<?xml version="1.0" encoding="utf-8"?>
<!-- =================================================================================== -->
<!-- |    This document was autogenerated by xacro from arbie_sim.urdf.xacro           | -->
<!-- |    EDITING THIS FILE BY HAND IS NOT RECOMMENDED                                 | -->
<!-- =================================================================================== -->
<robot name="arbie">
  <material name="body">
    <color rgba="0 0 1 1"/>
  </material>
  <material name="flipper">
    <color rgba="0 0.8 1 1"/>
  </material>
  <material name="tracks">
    <color rgba="0 0 0 0.5"/>
  </material>
  <material name="wheel">
    <color rgba="1 1 1 0.8"/>
  </material>
  <material name="arm">
    <color rgba="0 1 0 1"/>
  </material>
  <material name="wrist">
    <color rgba="1 1 0 1"/>
  </material>
  <material name="gripper">
    <color rgba="1 1 1 1"/>
  </material>
  <material name="camera">
    <color rgba="1 0.4 0 1"/>
  </material>
  <!-- CAMERA FRAMES AND PLUGINS PLUGINS -->
  <gazebo reference="camera_t265_link">
    <sensor name="t265_camera" type="multicamera">
      <update_rate>30.0</update_rate>
      <camera name="left">
        <pose>0 0.035 0 0 0 0</pose>
        <horizontal_fov>1.3962634</horizontal_fov>
        <image>
          <width>800</width>
          <height>800</height>
          <format>R8G8B8</format>
        </image>
        <clip>
          <near>0.02</near>
          <far>300</far>
        </clip>
        <noise>
          <type>gaussian</type>
          <mean>0.0</mean>
          <stddev>0.007</stddev>
        </noise>
      </camera>
      <camera name="right">
        <pose>0 -0.035 0 0 0 0</pose>
        <horizontal_fov>1.3962634</horizontal_fov>
        <image>
          <width>800</width>
          <height>800</height>
          <format>R8G8B8</format>
        </image>
        <clip>
          <near>0.02</near>
          <far>300</far>
        </clip>
        <noise>
          <type>gaussian</type>
          <mean>0.0</mean>
          <stddev>0.007</stddev>
        </noise>
      </camera>
      <plugin filename="libgazebo_ros_multicamera.so" name="t265_camera_controller">
        <alwaysOn>true</alwaysOn>
        <updateRate>0.0</updateRate>
        <cameraName>t265</cameraName>
        <imageTopicName>image_raw</imageTopicName>
        <cameraInfoTopicName>camera_info</cameraInfoTopicName>
        <frameName>camera_t265_link</frameName>
        <hackBaseline>0.07</hackBaseline>
        <distortionK1>0.0</distortionK1>
        <distortionK2>0.0</distortionK2>
        <distortionK3>0.0</distortionK3>
        <distortionT1>0.0</distortionT1>
        <distortionT2>0.0</distortionT2>
      </plugin>
    </sensor>
  </gazebo>
  <gazebo reference="camera_t265_link">
    <gravity>true</gravity>
    <sensor name="t265_imu" type="imu">
      <always_on>true</always_on>
      <update_rate>30.0</update_rate>
      <visualize>true</visualize>
      <topic>/t265/imu</topic>
      <plugin filename="libgazebo_ros_imu_sensor.so" name="t265_imu_controller">
        <topicName>/t265/imu</topicName>
        <bodyName>camera_t265_link</bodyName>
        <updateRateHZ>10.0</updateRateHZ>
        <gaussianNoise>0.0</gaussianNoise>
        <xyzOffset>0 0 0</xyzOffset>
        <rpyOffset>0 0 0</rpyOffset>
        <frameName>camera_t265_link</frameName>
        <initialOrientationAsReference>false</initialOrientationAsReference>
      </plugin>
      <pose>0 0 0 0 0 0</pose>
    </sensor>
  </gazebo>
  <gazebo reference="camera_d435_link">
    <sensor name="d435_camera" type="depth">
      <update_rate>30.0</update_rate>
      <camera>
        <horizontal_fov>1.047198</horizontal_fov>
        <image>
          <width>640</width>
          <height>480</height>
          <format>R8G8B8</format>
        </image>
        <clip>
          <near>0.05</near>
          <far>300</far>
        </clip>
      </camera>
      <plugin filename="libgazebo_ros_openni_kinect.so" name="d435_camera_controller">
        <baseline>0.2</baseline>
        <alwaysOn>true</alwaysOn>
        <updateRate>1.0</updateRate>
        <cameraName>d435</cameraName>
        <imageTopicName>/d435/color/image_raw</imageTopicName>
        <cameraInfoTopicName>/d435/color/camera_info</cameraInfoTopicName>
        <depthImageTopicName>/d435/depth/image_raw</depthImageTopicName>
        <depthImageInfoTopicName>/d435/depth/camera_info</depthImageInfoTopicName>
        <pointCloudTopicName>/d435/depth/points</pointCloudTopicName>
        <frameName>camera_d435_link</frameName>
        <pointCloudCutoff>0.5</pointCloudCutoff>
        <pointCloudCutoffMax>3.0</pointCloudCutoffMax>
        <distortionK1>0.00000001</distortionK1>
        <distortionK2>0.00000001</distortionK2>
        <distortionK3>0.00000001</distortionK3>
        <distortionT1>0.00000001</distortionT1>
        <distortionT2>0.00000001</distortionT2>
        <CxPrime>0</CxPrime>
        <Cx>0</Cx>
        <Cy>0</Cy>
        <focalLength>0</focalLength>
        <hackBaseline>0</hackBaseline>
      </plugin>
    </sensor>
  </gazebo>
  <gazebo reference="camera_d435_link">
    <gravity>true</gravity>
    <sensor name="d435_imu" type="imu">
      <always_on>true</always_on>
      <update_rate>30.0</update_rate>
      <visualize>true</visualize>
      <topic>/d435/imu</topic>
      <plugin filename="libgazebo_ros_imu_sensor.so" name="d435_imu_controller">
        <topicName>/d435/imu</topicName>
        <bodyName>camera_d435_link</bodyName>
        <updateRateHZ>10.0</updateRateHZ>
        <gaussianNoise>0.0</gaussianNoise>
        <xyzOffset>0 0 0</xyzOffset>
        <rpyOffset>0 0 0</rpyOffset>
        <frameName>camera_d435_link</frameName>
        <initialOrientationAsReference>false</initialOrientationAsReference>
      </plugin>
      <pose>0 0 0 0 0 0</pose>
    </sensor>
  </gazebo>
  <!-- BASE LINK -->
  <link name="base_link">
</link>
  <joint name="base_joint" type="fixed">
    <origin rpy="1.5708 0 1.5708" xyz="0.01 0 0.075"/>
    <parent link="base_link"/>
    <child link="body_link"/>
  </joint>
  <!-- BODY LINK -->
  <link name="body_link">
    <inertial>
      <origin rpy="0 0 0" xyz="-0.0007103904794560104 0.04685539726506198 -0.03652499028281223"/>
      <mass value="132.38352048208554"/>
      <inertia ixx="3.87908" ixy="-0.00108" ixz="-0.002599" iyy="4.409886" iyz="0.163573" izz="0.920138"/>
    </inertial>
    <visual>
      <origin rpy="0 0 0" xyz="0 0 0"/>
      <geometry>
        <mesh filename="package://arbie_description/meshes/body.stl"/>
      </geometry>
      <material name="body"/>
    </visual>
    <collision>
      <origin rpy="0 0 0" xyz="0 0 0"/>
      <geometry>
        <mesh filename="package://arbie_description/meshes/body.stl"/>
      </geometry>
    </collision>
  </link>
  <!-- CAMERA LINKS -->
  <link name="camera_mount_leg_1_link">
    <inertial>
      <origin rpy="0 0 0" xyz="-0.003687719231986318 0.005710165082249932 -1.3429420225863353e-07"/>
      <mass value="0.011972469965960587"/>
      <inertia ixx="1e-06" ixy="0.0" ixz="-0.0" iyy="0.0" iyz="0.0" izz="1e-06"/>
    </inertial>
    <visual>
      <origin rpy="0 0 0" xyz="-0.037807 -0.048101 -0.262572"/>
      <geometry>
        <mesh filename="package://arbie_description/meshes/camera_mount_leg_1.stl"/>
      </geometry>
      <material name="camera"/>
    </visual>
    <collision>
      <origin rpy="0 0 0" xyz="-0.037807 -0.048101 -0.262572"/>
      <geometry>
        <mesh filename="package://arbie_description/meshes/camera_mount_leg_1.stl"/>
      </geometry>
    </collision>
  </link>
  <link name="camera_mount_leg_2_link">
    <inertial>
      <origin rpy="0 0 0" xyz="0.0036876320544024996 0.005710165082249995 -1.3429420259170044e-07"/>
      <mass value="0.011972469965960601"/>
      <inertia ixx="1e-06" ixy="-0.0" ixz="0.0" iyy="0.0" iyz="-0.0" izz="1e-06"/>
    </inertial>
    <visual>
      <origin rpy="0 0 0" xyz="0.039194 -0.048101 -0.262572"/>
      <geometry>
        <mesh filename="package://arbie_description/meshes/camera_mount_leg_2.stl"/>
      </geometry>
      <material name="camera"/>
    </visual>
    <collision>
      <origin rpy="0 0 0" xyz="0.039194 -0.048101 -0.262572"/>
      <geometry>
        <mesh filename="package://arbie_description/meshes/camera_mount_leg_2.stl"/>
      </geometry>
    </collision>
  </link>
  <link name="camera_mount_link">
    <inertial>
      <origin rpy="0 0 0" xyz="-0.03446385172095636 0.0015631569649731947 0.008958079682170272"/>
      <mass value="0.10512980225278633"/>
      <inertia ixx="1.6e-05" ixy="-2e-06" ixz="1e-06" iyy="5.6e-05" iyz="3e-06" izz="5.4e-05"/>
    </inertial>
    <visual>
      <origin rpy="0 0 0" xyz="-0.033807 -0.073851 -0.262572"/>
      <geometry>
        <mesh filename="package://arbie_description/meshes/camera_mount.stl"/>
      </geometry>
      <material name="camera"/>
    </visual>
    <collision>
      <origin rpy="0 0 0" xyz="-0.033807 -0.073851 -0.262572"/>
      <geometry>
        <mesh filename="package://arbie_description/meshes/camera_mount.stl"/>
      </geometry>
    </collision>
  </link>
  <link name="camera_d435_link">
    <inertial>
      <origin rpy="-1.57079632679 -3.14159265359 -1.57079632679" xyz="-0.00997485340212 -0.000489026194926 0.000287807668346"/>
      <mass value="0.3380578483539848"/>
      <inertia ixx="3.1e-05" ixy="-0.0" ixz="2e-06" iyy="0.000212" iyz="-0.0" izz="0.000211"/>
    </inertial>
    <visual>
      <origin rpy="-1.57079632679 -3.14159265359 -1.57079632679" xyz="-0.285 0.00125 -0.09"/>
      <geometry>
        <mesh filename="package://arbie_description/meshes/camera_d435.stl"/>
      </geometry>
      <material name="camera"/>
    </visual>
    <collision>
      <origin rpy="-1.57079632679 -3.14159265359 -1.57079632679" xyz="-0.285 0.00125 -0.09"/>
      <geometry>
        <mesh filename="package://arbie_description/meshes/camera_d435.stl"/>
      </geometry>
    </collision>
  </link>
  <joint name="rigid_camera_mount_to_camera_d435_joint" type="fixed">
    <origin rpy="-1.57079632679 -1.57079632679 0" xyz="-0.032557 0.016149 0.022428"/>
    <parent link="camera_mount_link"/>
    <child link="camera_d435_link"/>
  </joint>
  <link name="camera_t265_link">
    <inertial>
      <origin rpy="-1.57079632679 -3.14159265359 -1.57079632679" xyz="-0.0051159762466 0.00725377525549 0"/>
      <mass value="0.11087104010777465"/>
      <inertia ixx="7e-06" ixy="0.0" ixz="-1e-06" iyy="0.000103" iyz="-0.0" izz="0.000108"/>
    </inertial>
    <visual>
      <origin rpy="-1.57079632679 -3.14159265359 -1.57079632679" xyz="-0.286572 -0.000323 -0.060351 "/>
      <geometry>
        <mesh filename="package://arbie_description/meshes/camera_t265.stl"/>
      </geometry>
      <material name="camera"/>
    </visual>
    <collision>
      <origin rpy="-1.57079632679 -3.14159265359 -1.57079632679" xyz="-0.286572 -0.000323 -0.060351 "/>
      <geometry>
        <mesh filename="package://arbie_description/meshes/camera_t265.stl"/>
      </geometry>
    </collision>
  </link>
  <joint name="rigid_camera_mount_to_camera_t265_joint" type="fixed">
    <origin rpy="-1.57079632679 -1.57079632679 0" xyz="-0.03413 -0.0135 0.024"/>
    <parent link="camera_mount_link"/>
    <child link="camera_t265_link"/>
  </joint>
  <!-- BOUNDING MESH FOR TRACKS -->
  <link name="tracks_right_link">
    <inertial>
      <origin rpy="0 0 0" xyz="-0.02499954358879042 0.002120489076708521 -0.0007430080149572974"/>
      <mass value="44.76242127990538"/>
      <inertia ixx="1.472289" ixy="-0.0" ixz="-0.0" iyy="1.350001" iyz="0.000109" izz="0.140939"/>
    </inertial>
    <visual>
      <origin rpy="0 0 0" xyz="0.124694 -0.019326 0.010978"/>
      <geometry>
        <mesh filename="package://arbie_description/meshes/tracks_right.stl"/>
      </geometry>
      <material name="tracks"/>
    </visual>
    <collision>
      <origin rpy="0 0 0" xyz="0.124694 -0.019326 0.010978"/>
      <geometry>
        <mesh filename="package://arbie_description/meshes/tracks_right.stl"/>
      </geometry>
    </collision>
  </link>
  <link name="tracks_left_link">
    <inertial>
      <origin rpy="0 0 0" xyz="0.02500045641121243 0.00212048907670849 -0.000743015955378042"/>
      <mass value="44.76242127990538"/>
      <inertia ixx="1.472289" ixy="-0.0" ixz="-0.0" iyy="1.350001" iyz="0.000109" izz="0.140939"/>
    </inertial>
    <visual>
      <origin rpy="0 0 0" xyz="-0.123306 -0.019326 0.010978"/>
      <geometry>
        <mesh filename="package://arbie_description/meshes/tracks_left.stl"/>
      </geometry>
      <material name="tracks"/>
    </visual>
    <collision>
      <origin rpy="0 0 0" xyz="-0.123306 -0.019326 0.010978"/>
      <geometry>
        <mesh filename="package://arbie_description/meshes/tracks_left.stl"/>
      </geometry>
    </collision>
  </link>
  <!-- RIGID JOINTS -->
  <joint name="rigid_body_to_tracks_right_joint" type="fixed">
    <origin rpy="0 0 0" xyz="-0.124694 0.019326 -0.010978"/>
    <parent link="body_link"/>
    <child link="tracks_right_link"/>
  </joint>
  <joint name="rigid_body_to_tracks_left_joint" type="fixed">
    <origin rpy="0 0 0" xyz="0.123306 0.019326 -0.010978"/>
    <parent link="body_link"/>
    <child link="tracks_left_link"/>
  </joint>
  <joint name="rigid_body_to_camera_mount_leg_1_joint" type="fixed">
    <origin rpy="0 0 0" xyz="0.037807 0.048101 0.262572"/>
    <parent link="body_link"/>
    <child link="camera_mount_leg_1_link"/>
  </joint>
  <joint name="rigid_body_to_camera_mount_leg_2_joint" type="fixed">
    <origin rpy="0 0 0" xyz="-0.039194 0.048101 0.262572"/>
    <parent link="body_link"/>
    <child link="camera_mount_leg_2_link"/>
  </joint>
  <!-- CAMERA MOUNT JOINT -->
  <joint name="camera_tilt_joint" type="continuous">
    <origin rpy="0 0 0" xyz="-0.004 0.02575 0.0"/>
    <parent link="camera_mount_leg_1_link"/>
    <child link="camera_mount_link"/>
    <axis xyz="1 0 0"/>
  </joint>
  <transmission name="camera_mount_transmission">
    <type>transmission_interface/SimpleTransmission</type>
    <joint name="camera_tilt_joint">
      <hardwareInterface>hardware_interface/PositionJointInterface</hardwareInterface>
    </joint>
    <actuator name="camera_mount_actuator">
      <hardwareInterface>PositionJointInterface</hardwareInterface>
      <mechanicalReduction>1</mechanicalReduction>
    </actuator>
  </transmission>
  <!-- EQUIVALENT WHEELS FOR TRACKS - USED TO CALCULATE VELOCITY COMMANDS -->
  <link name="tracks_right_wheel_link">
    <visual>
      <origin rpy="0 1.57079632679 0" xyz="0 0 0"/>
      <geometry>
        <cylinder length="0.04" radius="0.12"/>
      </geometry>
      <material name="wheel"/>
    </visual>
    <collision>
      <origin rpy="0 1.57079632679 0" xyz="0 0 0"/>
      <geometry>
        <cylinder length="0.04" radius="0.12"/>
      </geometry>
    </collision>
    <inertial>
      <origin rpy="0 1.57079632679 0" xyz="0 0 0"/>
      <mass value="0.5"/>
      <inertia ixx="0.00186666666667" ixy="0" ixz="0" iyy="0.00186666666667" iyz="0" izz="0.0036"/>
    </inertial>
  </link>
  <link name="tracks_left_wheel_link">
    <visual>
      <origin rpy="0 1.57079632679 0" xyz="0 0 0"/>
      <geometry>
        <cylinder length="0.04" radius="0.12"/>
      </geometry>
      <material name="wheel"/>
    </visual>
    <collision>
      <origin rpy="0 1.57079632679 0" xyz="0 0 0"/>
      <geometry>
        <cylinder length="0.04" radius="0.12"/>
      </geometry>
    </collision>
    <inertial>
      <origin rpy="0 1.57079632679 0" xyz="0 0 0"/>
      <mass value="0.5"/>
      <inertia ixx="0.00186666666667" ixy="0" ixz="0" iyy="0.00186666666667" iyz="0" izz="0.0036"/>
    </inertial>
  </link>
  <!-- TRACK WHEEL JOINTS -->
  <joint name="tracks_right_joint" type="continuous">
    <origin rpy="0 0 0" xyz="-0.025 0.005 0.1"/>
    <parent link="tracks_right_link"/>
    <child link="tracks_right_wheel_link"/>
    <axis xyz="1 0 0"/>
  </joint>
  <joint name="tracks_left_joint" type="continuous">
    <origin rpy="0 0 0" xyz="0.025 0.005 0.1"/>
    <parent link="tracks_left_link"/>
    <child link="tracks_left_wheel_link"/>
    <axis xyz="1 0 0"/>
  </joint>
  <transmission name="tracks_right_transmission">
    <type>transmission_interface/SimpleTransmission</type>
    <joint name="tracks_right_joint">
      <hardwareInterface>hardware_interface/VelocityJointInterface</hardwareInterface>
    </joint>
    <actuator name="tracks_right_actuator">
      <hardwareInterface>VelocityJointInterface</hardwareInterface>
      <mechanicalReduction>1</mechanicalReduction>
    </actuator>
  </transmission>
  <transmission name="tracks_left_transmission">
    <type>transmission_interface/SimpleTransmission</type>
    <joint name="tracks_left_joint">
      <hardwareInterface>hardware_interface/VelocityJointInterface</hardwareInterface>
    </joint>
    <actuator name="tracks_left_actuator">
      <hardwareInterface>VelocityJointInterface</hardwareInterface>
      <mechanicalReduction>1</mechanicalReduction>
    </actuator>
  </transmission>
  <!-- BALL -->
  <link name="ball_link">
    <visual>
      <geometry>
        <sphere radius="0.05"/>
      </geometry>
      <material name="wheel"/>
    </visual>
    <collision>
      <geometry>
        <sphere radius="0.05"/>
      </geometry>
    </collision>
    <inertial>
      <mass value="1"/>
      <inertia ixx="0.001" ixy="0" ixz="0" iyy="0.001" iyz="0" izz="0.001"/>
    </inertial>
  </link>
  <gazebo reference="ball_link">
    <mu1>0</mu1>
    <mu2>0</mu2>
  </gazebo>
  <joint name="rigid_body_to_ball_joint" type="fixed">
    <origin rpy="0 0 0" xyz="0 -0.05 -0.25"/>
    <parent link="body_link"/>
    <child link="ball_link"/>
  </joint>
  <gazebo>
    <plugin filename="libgazebo_ros_control.so" name="gazebo_ros_control"/>
  </gazebo>
  <!-- FLIPPER LINKS -->
  <link name="flipper_front_right_link">
    <inertial>
      <origin rpy="0 0 0" xyz="0.019795020283170317 0.16537558379618636 -1.3146244423611897e-07"/>
      <mass value="13.868020437393694"/>
      <inertia ixx="0.085351" ixy="-0.004876" ixz="0.0" iyy="0.028555" iyz="-0.0" izz="0.07162"/>
    </inertial>
    <visual>
      <origin rpy="0 0 0" xyz="0.174694 -0.024729 -0.219022"/>
      <geometry>
        <mesh filename="package://arbie_description/meshes/flipper_front_right.stl"/>
      </geometry>
      <material name="flipper"/>
    </visual>
    <collision>
      <origin rpy="0 0 0" xyz="0.174694 -0.024729 -0.219022"/>
      <geometry>
        <mesh filename="package://arbie_description/meshes/flipper_front_right.stl"/>
      </geometry>
    </collision>
  </link>
  <link name="flipper_front_left_link">
    <inertial>
      <origin rpy="0 0 0" xyz="-0.019794107460748195 0.16537558379618633 -1.394028636692024e-07"/>
      <mass value="13.868020437393678"/>
      <inertia ixx="0.085351" ixy="0.004876" ixz="-0.0" iyy="0.028555" iyz="-0.0" izz="0.07162"/>
    </inertial>
    <visual>
      <origin rpy="0 0 0" xyz="-0.173306 -0.024729 -0.219022"/>
      <geometry>
        <mesh filename="package://arbie_description/meshes/flipper_front_left.stl"/>
      </geometry>
      <material name="flipper"/>
    </visual>
    <collision>
      <origin rpy="0 0 0" xyz="-0.173306 -0.024729 -0.219022"/>
      <geometry>
        <mesh filename="package://arbie_description/meshes/flipper_front_left.stl"/>
      </geometry>
    </collision>
  </link>
  <link name="flipper_rear_right_link">
    <inertial>
      <origin rpy="0 0 0" xyz="0.01979502028317115 0.16537558379618683 -1.3146242511252737e-07"/>
      <mass value="13.868020437393698"/>
      <inertia ixx="0.085351" ixy="-0.004876" ixz="0.0" iyy="0.028555" iyz="-0.0" izz="0.07162"/>
    </inertial>
    <visual>
      <origin rpy="0 0 0" xyz="0.174694 -0.024729 0.240978"/>
      <geometry>
        <mesh filename="package://arbie_description/meshes/flipper_rear_right.stl"/>
      </geometry>
      <material name="flipper"/>
    </visual>
    <collision>
      <origin rpy="0 0 0" xyz="0.174694 -0.024729 0.240978"/>
      <geometry>
        <mesh filename="package://arbie_description/meshes/flipper_rear_right.stl"/>
      </geometry>
    </collision>
  </link>
  <link name="flipper_rear_left_link">
    <inertial>
      <origin rpy="0 0 0" xyz="-0.019794107460749416 0.16537558379618675 -1.394028462664565e-07"/>
      <mass value="13.868020437393671"/>
      <inertia ixx="0.085351" ixy="0.004876" ixz="-0.0" iyy="0.028555" iyz="-0.0" izz="0.07162"/>
    </inertial>
    <visual>
      <origin rpy="0 0 0" xyz="-0.173306 -0.024729 0.240978"/>
      <geometry>
        <mesh filename="package://arbie_description/meshes/flipper_rear_left.stl"/>
      </geometry>
      <material name="flipper"/>
    </visual>
    <collision>
      <origin rpy="0 0 0" xyz="-0.173306 -0.024729 0.240978"/>
      <geometry>
        <mesh filename="package://arbie_description/meshes/flipper_rear_left.stl"/>
      </geometry>
    </collision>
  </link>
  <!-- RIGID LINKS BETWEEN OPPOSITE FLIPPERS -->
  <joint name="rigid_flipper_front_right_to_flipper_front_left" type="fixed">
    <origin rpy="0 0 0" xyz="0.347996 0 0"/>
    <parent link="flipper_front_right_link"/>
    <child link="flipper_front_left_link"/>
  </joint>
  <joint name="rigid_flipper_rear_right_to_flipper_rear_left" type="fixed">
    <origin rpy="0 0 0" xyz="0.347996 0 0"/>
    <parent link="flipper_rear_right_link"/>
    <child link="flipper_rear_left_link"/>
  </joint>
  <!-- FLIPPER JOINTS -->
  <joint name="flippers_front_joint" type="continuous">
    <origin rpy="0 0 0" xyz="-0.05 0.005403 0.23"/>
    <parent link="tracks_right_link"/>
    <child link="flipper_front_right_link"/>
    <axis xyz="1 0 0"/>
  </joint>
  <transmission name="flippers_front_transmission">
    <type>transmission_interface/SimpleTransmission</type>
    <joint name="flippers_front_joint">
      <hardwareInterface>hardware_interface/EffortJointInterface</hardwareInterface>
    </joint>
    <actuator name="flippers_front_actuator">
      <hardwareInterface>EffortJointInterface</hardwareInterface>
      <mechanicalReduction>1</mechanicalReduction>
    </actuator>
  </transmission>
  <joint name="flippers_rear_joint" type="continuous">
    <origin rpy="0 0 0" xyz="-0.05 0.005403 -0.23"/>
    <parent link="tracks_right_link"/>
    <child link="flipper_rear_right_link"/>
    <axis xyz="1 0 0"/>
  </joint>
  <transmission name="flippers_rear_transmission">
    <type>transmission_interface/SimpleTransmission</type>
    <joint name="flippers_rear_joint">
      <hardwareInterface>hardware_interface/EffortJointInterface</hardwareInterface>
    </joint>
    <actuator name="flippers_rear_actuator">
      <hardwareInterface>EffortJointInterface</hardwareInterface>
      <mechanicalReduction>1</mechanicalReduction>
    </actuator>
  </transmission>
  <!-- ARM LINKS -->
  <link name="arm_base_link">
    <inertial>
      <origin rpy="0 0 0" xyz="-0.0016420049931783305 0.023135022831294483 -7.480052882286037e-06"/>
      <mass value="3.3465093478653403"/>
      <inertia ixx="0.005075" ixy="0.000176" ixz="-0.0" iyy="0.010632" iyz="1e-06" izz="0.009087"/>
    </inertial>
    <visual>
      <origin rpy="0 0 0" xyz="0.000694 -0.107101 -0.186272"/>
      <geometry>
        <mesh filename="package://arbie_description/meshes/arm_base.stl"/>
      </geometry>
      <material name="arm"/>
    </visual>
    <collision>
      <origin rpy="0 0 0" xyz="0.000694 -0.107101 -0.186272"/>
      <geometry>
        <mesh filename="package://arbie_description/meshes/arm_base.stl"/>
      </geometry>
    </collision>
  </link>
  <link name="arm_lower_link">
    <inertial>
      <origin rpy="0 0 0" xyz="-0.053878611230066 0.007243666919340863 -0.13003163766238773"/>
      <mass value="9.290217371436244"/>
      <inertia ixx="0.285483" ixy="0.000938" ixz="-0.009995" iyy="0.285913" iyz="0.0181" izz="0.011485"/>
    </inertial>
    <visual>
      <origin rpy="0 0 0" xyz="-0.052806 -0.174101 -0.186495"/>
      <geometry>
        <mesh filename="package://arbie_description/meshes/arm_lower.stl"/>
      </geometry>
      <material name="arm"/>
    </visual>
    <collision>
      <origin rpy="0 0 0" xyz="-0.052806 -0.174101 -0.186495"/>
      <geometry>
        <mesh filename="package://arbie_description/meshes/arm_lower.stl"/>
      </geometry>
    </collision>
  </link>
  <link name="arm_upper_link">
    <inertial>
      <origin rpy="0 0 0" xyz="-0.016999544747906395 0.013376208584352511 0.039239753662060034"/>
      <mass value="3.0631873001334227"/>
      <inertia ixx="0.015235" ixy="0.0" ixz="0.0" iyy="0.013273" iyz="-0.002633" izz="0.002494"/>
    </inertial>
    <visual>
      <origin rpy="0 0 0" xyz="-0.019806 -0.209101 0.263505"/>
      <geometry>
        <mesh filename="package://arbie_description/meshes/arm_upper.stl"/>
      </geometry>
      <material name="arm"/>
    </visual>
    <collision>
      <origin rpy="0 0 0" xyz="-0.019806 -0.209101 0.263505"/>
      <geometry>
        <mesh filename="package://arbie_description/meshes/arm_upper.stl"/>
      </geometry>
    </collision>
  </link>
  <!-- WRIST LINKS -->
  <link name="wrist_base_link">
    <inertial>
      <origin rpy="0 0 0" xyz="4.57436623640603e-07 0.00012475245793225342 0.025292868333247724"/>
      <mass value="0.9490572232520995"/>
      <inertia ixx="0.000757" ixy="1e-06" ixz="-0.0" iyy="0.001107" iyz="2e-06" izz="0.000496"/>
    </inertial>
    <visual>
      <origin rpy="0 0 0" xyz="-0.002806 -0.244101 0.038505"/>
      <geometry>
        <mesh filename="package://arbie_description/meshes/wrist_base.stl"/>
      </geometry>
      <material name="wrist"/>
    </visual>
    <collision>
      <origin rpy="0 0 0" xyz="-0.002806 -0.244101 0.038505"/>
      <geometry>
        <mesh filename="package://arbie_description/meshes/wrist_base.stl"/>
      </geometry>
    </collision>
  </link>
  <link name="wrist_pitch_link">
    <inertial>
      <origin rpy="0 0 0" xyz="-0.0332984740595477 0.0020671950198172806 0.02282064850736746"/>
      <mass value="0.08039663104912372"/>
      <inertia ixx="5.5e-05" ixy="0.0" ixz="0.0" iyy="9.5e-05" iyz="-7e-06" izz="8e-05"/>
    </inertial>
    <visual>
      <origin rpy="0 0 0" xyz="-0.036206 -0.244101 -0.014995"/>
      <geometry>
        <mesh filename="package://arbie_description/meshes/wrist_pitch.stl"/>
      </geometry>
      <material name="wrist"/>
    </visual>
    <collision>
      <origin rpy="0 0 0" xyz="-0.036206 -0.244101 -0.014995"/>
      <geometry>
        <mesh filename="package://arbie_description/meshes/wrist_pitch.stl"/>
      </geometry>
    </collision>
  </link>
  <link name="wrist_yaw_link">
    <inertial>
      <origin rpy="0 0 0" xyz="-0.013267784777998575 0.01927575393175185 0.016285676232992735"/>
      <mass value="0.6469480906726006"/>
      <inertia ixx="0.000275" ixy="2e-06" ixz="2e-06" iyy="0.000342" iyz="3e-06" izz="0.000171"/>
    </inertial>
    <visual>
      <origin rpy="0 0 0" xyz="-0.002906 -0.225651 -0.078119"/>
      <geometry>
        <mesh filename="package://arbie_description/meshes/wrist_yaw.stl"/>
      </geometry>
      <material name="wrist"/>
    </visual>
    <collision>
      <origin rpy="0 0 0" xyz="-0.002906 -0.225651 -0.078119"/>
      <geometry>
        <mesh filename="package://arbie_description/meshes/wrist_yaw.stl"/>
      </geometry>
    </collision>
  </link>
  <!-- GRIPPER LINKS -->
  <link name="gripper_base_link">
    <inertial>
      <origin rpy="0 0 0" xyz="-4.607760189011137e-05 -0.0006917471996047975 0.03460710409065769"/>
      <mass value="0.6706735500880907"/>
      <inertia ixx="0.000199" ixy="0.0" ixz="0.0" iyy="0.000353" iyz="-3e-06" izz="0.000284"/>
    </inertial>
    <visual>
      <origin rpy="0 0 0" xyz="-0.002906 -0.244651 -0.123519"/>
      <geometry>
        <mesh filename="package://arbie_description/meshes/gripper_base.stl"/>
      </geometry>
      <material name="gripper"/>
    </visual>
    <collision>
      <origin rpy="0 0 0" xyz="-0.002906 -0.244651 -0.123519"/>
      <geometry>
        <mesh filename="package://arbie_description/meshes/gripper_base.stl"/>
      </geometry>
    </collision>
  </link>
  <link name="gripper_right_driver_link">
    <inertial>
      <origin rpy="0 0 0" xyz="4.537220775792383e-07 -0.03094002747411953 0.004350576193156569"/>
      <mass value="0.01374798583124482"/>
      <inertia ixx="5e-06" ixy="-0.0" ixz="0.0" iyy="2e-06" iyz="-1e-06" izz="4e-06"/>
    </inertial>
    <visual>
      <origin rpy="0 0 0" xyz="-0.018906 -0.263651 -0.172219"/>
      <geometry>
        <mesh filename="package://arbie_description/meshes/gripper_right_driver.stl"/>
      </geometry>
      <material name="gripper"/>
    </visual>
    <collision>
      <origin rpy="0 0 0" xyz="-0.018906 -0.263651 -0.172219"/>
      <geometry>
        <mesh filename="package://arbie_description/meshes/gripper_right_driver.stl"/>
      </geometry>
    </collision>
  </link>
  <link name="gripper_right_linkage_link">
    <inertial>
      <origin rpy="0 0 0" xyz="0.005348977862044579 0.00500022075444323 -0.01750042810563407"/>
      <mass value="0.00386409068463368"/>
      <inertia ixx="1e-06" ixy="0.0" ixz="0.0" iyy="1e-06" iyz="-0.0" izz="0.0"/>
    </inertial>
    <visual>
      <origin rpy="0 0 0" xyz="0.015 -0.485 -0.09"/>
      <geometry>
        <mesh filename="package://arbie_description/meshes/gripper_right_linkage.stl"/>
      </geometry>
      <material name="gripper"/>
    </visual>
    <collision>
      <origin rpy="0 0 0" xyz="-0.03671 -0.238651 0.153719"/>
      <geometry>
        <mesh filename="package://arbie_description/meshes/gripper_right_linkage.stl"/>
      </geometry>
    </collision>
  </link>
  <link name="gripper_right_contact_link">
    <inertial>
      <origin rpy="0 0 0" xyz="0.004967829686739981 -0.01899661466926142 0.016466890477460472"/>
      <mass value="0.023712538812289255"/>
      <inertia ixx="7e-06" ixy="1e-06" ixz="2e-06" iyy="7e-06" iyz="-1e-06" izz="4e-06"/>
    </inertial>
    <visual>
      <origin rpy="0 0 0" xyz="-0.018906 -0.261251 -0.207219"/>
      <geometry>
        <mesh filename="package://arbie_description/meshes/gripper_right_contact.stl"/>
      </geometry>
      <material name="gripper"/>
    </visual>
    <collision>
      <origin rpy="0 0 0" xyz="-0.018906 -0.261251 -0.207219"/>
      <geometry>
        <mesh filename="package://arbie_description/meshes/gripper_right_contact.stl"/>
      </geometry>
    </collision>
  </link>
  
--&gt;


  <link name="gripper_left_driver_link">
    <inertial>
      <origin rpy="0 0 0" xyz="4.552690735497994e-07 -0.030940033304886344 0.004350583148282683"/>
      <mass value="0.013747989643093032"/>
      <inertia ixx="5e-06" ixy="0.0" ixz="0.0" iyy="2e-06" iyz="-1e-06" izz="4e-06"/>
    </inertial>
    <visual>
      <origin rpy="0 0 0" xyz="0.013094 -0.263651 -0.172219"/>
      <geometry>
        <mesh filename="package://arbie_description/meshes/gripper_left_driver.stl"/>
      </geometry>
      <material name="gripper"/>
    </visual>
    <collision>
      <origin rpy="0 0 0" xyz="0.013094 -0.263651 -0.172219"/>
      <geometry>
        <mesh filename="package://arbie_description/meshes/gripper_left_driver.stl"/>
      </geometry>
    </collision>
  </link>
  <link name="gripper_left_contact_link">
    <inertial>
      <origin rpy="0 0 0" xyz="-0.0049669191825520796 -0.01899661466926142 0.016466890477460527"/>
      <mass value="0.023712538812289255"/>
      <inertia ixx="7e-06" ixy="-1e-06" ixz="-2e-06" iyy="7e-06" iyz="-1e-06" izz="4e-06"/>
    </inertial>
    <visual>
      <origin rpy="0 0 0" xyz="0.013094 -0.261251 -0.207219"/>
      <geometry>
        <mesh filename="package://arbie_description/meshes/gripper_left_contact.stl"/>
      </geometry>
      <material name="gripper"/>
    </visual>
    <collision>
      <origin rpy="0 0 0" xyz="0.013094 -0.261251 -0.207219"/>
      <geometry>
        <mesh filename="package://arbie_description/meshes/gripper_left_contact.stl"/>
      </geometry>
    </collision>
  </link>
  <link name="gripper_left_linkage_link">
    <inertial>
      <origin rpy="0 0 0" xyz="-0.005348977862044579 0.00500022075444323 0.01750042810563407"/>
      <mass value="0.00386409068463368"/>
      <inertia ixx="1e-06" ixy="0.0" ixz="0.0" iyy="1e-06" iyz="-0.0" izz="0.0"/>
    </inertial>
    <visual>
      <origin rpy="0 0 0" xyz="0.03671 -0.238651 -0.153719"/>
      <geometry>
        <mesh filename="package://arbie_description/meshes/gripper_left_linkage.stl"/>
      </geometry>
      <material name="gripper"/>
    </visual>
    <collision>
      <origin rpy="0 0 0" xyz="0.03671 -0.238651 -0.153719"/>
      <geometry>
        <mesh filename="package://arbie_description/meshes/gripper_left_linkage.stl"/>
      </geometry>
    </collision>
  </link>
  <!-- RIGID JOINTS -->
  <joint name="rigid_arm_upper_to_wrist_base_joint" type="fixed">
    <origin rpy="0 0 0" xyz="-0.017 0.035 0.27"/>
    <parent link="arm_upper_link"/>
    <child link="wrist_base_link"/>
  </joint>
  <!-- ARM JOINTS -->
  <joint name="arm_1_joint" type="continuous">
    <origin rpy="0 0 0" xyz="-0.000694 0.107101 0.186272"/>
    <parent link="body_link"/>
    <child link="arm_base_link"/>
    <axis xyz="0 1 0"/>
  </joint>
  <transmission name="arm_1_tran">
    <type>transmission_interface/SimpleTransmission</type>
    <joint name="arm_1_joint">
      <hardwareInterface>hardware_interface/EffortJointInterface</hardwareInterface>
    </joint>
    <actuator name="arm_1_actuator">
      <hardwareInterface>EffortJointInterface</hardwareInterface>
      <mechanicalReduction>1</mechanicalReduction>
    </actuator>
  </transmission>
  <joint name="arm_2_joint" type="continuous">
    <origin rpy="0 0 0" xyz="0.0535 0.067 0.000223"/>
    <parent link="arm_base_link"/>
    <child link="arm_lower_link"/>
    <axis xyz="1 0 0"/>
  </joint>
  <transmission name="arm_2_transmission">
    <type>transmission_interface/SimpleTransmission</type>
    <joint name="arm_2_joint">
      <hardwareInterface>EffortJointInterface</hardwareInterface>
    </joint>
    <actuator name="arm_2_actuator">
      <hardwareInterface>EffortJointInterface</hardwareInterface>
      <mechanicalReduction>1</mechanicalReduction>
    </actuator>
  </transmission>
  <joint name="arm_3_joint" type="continuous">
    <origin rpy="0 0 0" xyz="-0.033 0.035 -0.45"/>
    <parent link="arm_lower_link"/>
    <child link="arm_upper_link"/>
    <axis xyz="-1 0 0"/>
  </joint>
  <transmission name="arm_3_transmission">
    <type>transmission_interface/SimpleTransmission</type>
    <joint name="arm_3_joint">
      <hardwareInterface>hardware_interface/EffortJointInterface</hardwareInterface>
    </joint>
    <actuator name="arm_3_actuator">
      <hardwareInterface>EffortJointInterface</hardwareInterface>
      <mechanicalReduction>1</mechanicalReduction>
    </actuator>
  </transmission>
  <!-- WRIST JOINTS -->
  <joint name="wrist_pitch_joint" type="continuous">
    <origin rpy="0 0 0" xyz="0.0334 0.0 0.0535"/>
    <parent link="wrist_base_link"/>
    <child link="wrist_pitch_link"/>
    <axis xyz="1 0 0"/>
  </joint>
  <transmission name="wrist_pitch_transmission">
    <type>transmission_interface/SimpleTransmission</type>
    <joint name="wrist_pitch_joint">
      <hardwareInterface>hardware_interface/EffortJointInterface</hardwareInterface>
    </joint>
    <actuator name="wrist_pitch_actuator">
      <hardwareInterface>EffortJointInterface</hardwareInterface>
      <mechanicalReduction>1</mechanicalReduction>
    </actuator>
  </transmission>
  <joint name="wrist_yaw_joint" type="continuous">
    <origin rpy="0 0 0" xyz="-0.0333 -0.01845 0.063124"/>
    <parent link="wrist_pitch_link"/>
    <child link="wrist_yaw_link"/>
    <axis xyz="0 -1 0"/>
  </joint>
  <transmission name="wrist_yaw_transmsission">
    <type>transmission_interface/SimpleTransmission</type>
    <joint name="wrist_yaw_joint">
      <hardwareInterface>hardware_interface/EffortJointInterface</hardwareInterface>
    </joint>
    <actuator name="wrist_yaw_actuator">
      <hardwareInterface>EffortJointInterface</hardwareInterface>
      <mechanicalReduction>1</mechanicalReduction>
    </actuator>
  </transmission>
  <joint name="wrist_roll_joint" type="continuous">
    <origin rpy="0 0 -1.5708" xyz="0.0 0.019 0.0454"/>
    <parent link="wrist_yaw_link"/>
    <child link="gripper_base_link"/>
    <axis xyz="0 0 1"/>
  </joint>
  <transmission name="wrist_roll_transmission">
    <type>transmission_interface/SimpleTransmission</type>
    <joint name="wrist_roll_joint">
      <hardwareInterface>hardware_interface/EffortJointInterface</hardwareInterface>
    </joint>
    <actuator name="wrist_roll_actuator">
      <hardwareInterface>EffortJointInterface</hardwareInterface>
      <mechanicalReduction>1</mechanicalReduction>
    </actuator>
  </transmission>
  <!-- GRIPPER DRIVEN JOINTS -->
  <joint name="gripper_right_joint" type="continuous">
    <origin rpy="0 -0.348 0" xyz="0.016 0.019 0.0487"/>
    <parent link="gripper_base_link"/>
    <child link="gripper_right_driver_link"/>
    <axis xyz="0 1 0"/>
  </joint>
  <transmission name="gripper_right_driver_transmission">
    <type>transmission_interface/SimpleTransmission</type>
    <joint name="gripper_right_joint">
      <hardwareInterface>hardware_interface/EffortJointInterface</hardwareInterface>
    </joint>
    <actuator name="gripper_right_driver_actuator">
      <hardwareInterface>EffortJointInterface</hardwareInterface>
      <mechanicalReduction>1</mechanicalReduction>
    </actuator>
  </transmission>
  <joint name="gripper_left_joint" type="continuous">
    <origin rpy="0 0.348 0" xyz="-0.016 0.019 0.0487"/>
    <parent link="gripper_base_link"/>
    <child link="gripper_left_driver_link"/>
    <axis xyz="0 1 0"/>
  </joint>
  <transmission name="gripper_left_driver_transmission">
    <type>transmission_interface/SimpleTransmission</type>
    <joint name="gripper_left_joint">
      <hardwareInterface>hardware_interface/EffortJointInterface</hardwareInterface>
    </joint>
    <actuator name="gripper_left_driver_actuator">
      <hardwareInterface>EffortJointInterface</hardwareInterface>
      <mechanicalReduction>1</mechanicalReduction>
    </actuator>
  </transmission>
  <!-- GRIPPER DEPENDENT JOINTS -->
  <joint name="gripper_right_contact_dependent_joint" type="continuous">
    <origin rpy="0 0.348 0" xyz="0.0 -0.0024 0.035"/>
    <parent link="gripper_right_driver_link"/>
    <child link="gripper_right_contact_link"/>
    <axis xyz="0 1 0"/>
    <mimic joint="gripper_right_joint" multiplier="-1"/>
  </joint>
  <joint name="gripper_left_contact_dependent_joint" type="continuous">
    <origin rpy="0 -0.348 0" xyz="0.0 -0.0024 0.035"/>
    <parent link="gripper_left_driver_link"/>
    <child link="gripper_left_contact_link"/>
    <axis xyz="0 1 0"/>
    <mimic joint="gripper_left_joint" multiplier="-1"/>
  </joint>
  <joint name="gripper_right_linkage_dependent_joint" type="continuous">
    <origin rpy="0 -0.348 0" xyz="0.039616 -0.006 0.0302"/>
    <parent link="gripper_base_link"/>
    <child link="gripper_right_linkage_link"/>
    <axis xyz="0 1 0"/>
    <mimic joint="gripper_right_joint"/>
  </joint>
  <joint name="gripper_left_linkage_dependent_joint" type="continuous">
    <origin rpy="0 0.348 0" xyz="-0.039616 -0.006 0.0302"/>
    <parent link="gripper_base_link"/>
    <child link="gripper_left_linkage_link"/>
    <axis xyz="0 1 0"/>
    <mimic joint="gripper_left_joint"/>
  </joint>
  <!-- GAZEBO ONLY JOINTS - CLOSE LOOP -->
  <gazebo>
    <joint name="gripper_right_linkage_dependent_2_joint" type="revolute">
      <pose>0 0 0 0 0 0</pose>
      <parent>gripper_right_linkage_link</parent>
      <child>gripper_right_contact_link&quot;</child>
      <axis>
        <xyz>0 1 0</xyz>
      </axis>
    </joint>
    <joint name="gripper_left_linkage_dependent_2_joint" type="revolute">
      <pose>0 0 0 0 0 0</pose>
      <parent>gripper_left_linkage_link</parent>
      <child>gripper_left_contact_link&quot;</child>
      <axis>
        <xyz>0 1 0</xyz>
      </axis>
    </joint>
  </gazebo>
</robot>

