<sdf version='1.6'>
  <model name='arbie'>
    <link name='base_link'>
      <pose frame=''>0 0 0 0 -0 0</pose>
      <inertial>
        <pose frame=''>-0.01749 -0.000701 0.111218 0 -0 0</pose>
        <mass>222.932</mass>
        <inertia>
          <ixx>3.23254</ixx>
          <ixy>-0.00247844</ixy>
          <ixz>0.178083</ixz>
          <iyy>6.95121</iyy>
          <iyz>-0.000995817</iyz>
          <izz>9.18305</izz>
        </inertia>
      </inertial>
      <collision name='base_link_fixed_joint_lump__body_link_collision'>
        <pose frame=''>0.01 0 0.075 1.5708 -0 1.5708</pose>
        <geometry>
          <mesh>
            <scale>1 1 1</scale>
            <uri>model://arbie_description/meshes/body.stl</uri>
          </mesh>
        </geometry>
      </collision>
      <collision name='base_link_fixed_joint_lump__ball_link_collision_1'>
        <pose frame=''>-0.24 -1e-06 0.025001 1.5708 -0 1.5708</pose>
        <geometry>
          <sphere>
            <radius>0.05</radius>
          </sphere>
        </geometry>
        <surface>
          <contact>
            <ode/>
          </contact>
          <friction>
            <ode>
              <mu>0</mu>
              <mu2>0</mu2>
            </ode>
          </friction>
        </surface>
      </collision>
      <collision name='base_link_fixed_joint_lump__camera_mount_leg_1_link_collision_2'>
        <pose frame=''>0.01 0 0.075 1.5708 -0 1.5708</pose>
        <geometry>
          <mesh>
            <scale>1 1 1</scale>
            <uri>model://arbie_description/meshes/camera_mount_leg_1.stl</uri>
          </mesh>
        </geometry>
      </collision>
      <collision name='base_link_fixed_joint_lump__camera_mount_leg_2_link_collision_3'>
        <pose frame=''>0.01 0 0.075 1.5708 -0 1.5708</pose>
        <geometry>
          <mesh>
            <scale>1 1 1</scale>
            <uri>model://arbie_description/meshes/camera_mount_leg_2.stl</uri>
          </mesh>
        </geometry>
      </collision>
      <collision name='base_link_fixed_joint_lump__tracks_left_link_collision_4'>
        <pose frame=''>0.01 0 0.075 1.5708 -0 1.5708</pose>
        <geometry>
          <mesh>
            <scale>1 1 1</scale>
            <uri>model://arbie_description/meshes/tracks_left.stl</uri>
          </mesh>
        </geometry>
      </collision>
      <collision name='base_link_fixed_joint_lump__tracks_right_link_collision_5'>
        <pose frame=''>0.01 0 0.075 1.5708 -0 1.5708</pose>
        <geometry>
          <mesh>
            <scale>1 1 1</scale>
            <uri>model://arbie_description/meshes/tracks_right.stl</uri>
          </mesh>
        </geometry>
      </collision>
      <visual name='base_link_fixed_joint_lump__body_link_visual'>
        <pose frame=''>0.01 0 0.075 1.5708 -0 1.5708</pose>
        <geometry>
          <mesh>
            <scale>1 1 1</scale>
            <uri>model://arbie_description/meshes/body.stl</uri>
          </mesh>
        </geometry>
      </visual>
      <visual name='base_link_fixed_joint_lump__ball_link_visual_1'>
        <pose frame=''>-0.24 -1e-06 0.025001 1.5708 -0 1.5708</pose>
        <geometry>
          <sphere>
            <radius>0.05</radius>
          </sphere>
        </geometry>
        <material>
          <script>
            <uri>__default__</uri>
            <name>__default__</name>
          </script>
        </material>
      </visual>
      <visual name='base_link_fixed_joint_lump__camera_mount_leg_1_link_visual_2'>
        <pose frame=''>0.01 0 0.075 1.5708 -0 1.5708</pose>
        <geometry>
          <mesh>
            <scale>1 1 1</scale>
            <uri>model://arbie_description/meshes/camera_mount_leg_1.stl</uri>
          </mesh>
        </geometry>
      </visual>
      <visual name='base_link_fixed_joint_lump__camera_mount_leg_2_link_visual_3'>
        <pose frame=''>0.01 0 0.075 1.5708 -0 1.5708</pose>
        <geometry>
          <mesh>
            <scale>1 1 1</scale>
            <uri>model://arbie_description/meshes/camera_mount_leg_2.stl</uri>
          </mesh>
        </geometry>
      </visual>
      <visual name='base_link_fixed_joint_lump__tracks_left_link_visual_4'>
        <pose frame=''>0.01 0 0.075 1.5708 -0 1.5708</pose>
        <geometry>
          <mesh>
            <scale>1 1 1</scale>
            <uri>model://arbie_description/meshes/tracks_left.stl</uri>
          </mesh>
        </geometry>
      </visual>
      <visual name='base_link_fixed_joint_lump__tracks_right_link_visual_5'>
        <pose frame=''>0.01 0 0.075 1.5708 -0 1.5708</pose>
        <geometry>
          <mesh>
            <scale>1 1 1</scale>
            <uri>model://arbie_description/meshes/tracks_right.stl</uri>
          </mesh>
        </geometry>
      </visual>
      <gravity>1</gravity>
      <velocity_decay/>
    </link>
    <link name='arm_base_link'>
      <pose frame=''>0.196272 -0.000693 0.1821 1.5708 -0 1.5708</pose>
      <inertial>
        <pose frame=''>-0.001642 0.023135 -7e-06 0 -0 0</pose>
        <mass>3.34651</mass>
        <inertia>
          <ixx>0.005075</ixx>
          <ixy>0.000176</ixy>
          <ixz>-0</ixz>
          <iyy>0.010632</iyy>
          <iyz>1e-06</iyz>
          <izz>0.009087</izz>
        </inertia>
      </inertial>
      <collision name='arm_base_link_collision'>
        <pose frame=''>0.000694 -0.107101 -0.186272 0 -0 0</pose>
        <geometry>
          <mesh>
            <scale>1 1 1</scale>
            <uri>model://arbie_description/meshes/arm_base.stl</uri>
          </mesh>
        </geometry>
      </collision>
      <visual name='arm_base_link_visual'>
        <pose frame=''>0.000694 -0.107101 -0.186272 0 -0 0</pose>
        <geometry>
          <mesh>
            <scale>1 1 1</scale>
            <uri>model://arbie_description/meshes/arm_base.stl</uri>
          </mesh>
        </geometry>
      </visual>
    </link>
    <joint name='arm_1_joint' type='revolute'>
      <child>arm_base_link</child>
      <parent>base_link</parent>
      <axis>
        <xyz>4e-06 0 1</xyz>
        <limit>
          <lower>-1e+16</lower>
          <upper>1e+16</upper>
        </limit>
        <dynamics>
          <spring_reference>0</spring_reference>
          <spring_stiffness>0</spring_stiffness>
        </dynamics>
        <use_parent_model_frame>1</use_parent_model_frame>
      </axis>
    </joint>
    <link name='arm_lower_link'>
      <pose frame=''>0.196495 0.052807 0.2491 1.5708 -0 1.5708</pose>
      <inertial>
        <pose frame=''>-0.053879 0.007244 -0.130032 0 -0 0</pose>
        <mass>9.29022</mass>
        <inertia>
          <ixx>0.285483</ixx>
          <ixy>0.000938</ixy>
          <ixz>-0.009995</ixz>
          <iyy>0.285913</iyy>
          <iyz>0.0181</iyz>
          <izz>0.011485</izz>
        </inertia>
      </inertial>
      <collision name='arm_lower_link_collision'>
        <pose frame=''>-0.052806 -0.174101 -0.186495 0 -0 0</pose>
        <geometry>
          <mesh>
            <scale>1 1 1</scale>
            <uri>model://arbie_description/meshes/arm_lower.stl</uri>
          </mesh>
        </geometry>
      </collision>
      <visual name='arm_lower_link_visual'>
        <pose frame=''>-0.052806 -0.174101 -0.186495 0 -0 0</pose>
        <geometry>
          <mesh>
            <scale>1 1 1</scale>
            <uri>model://arbie_description/meshes/arm_lower.stl</uri>
          </mesh>
        </geometry>
      </visual>
    </link>
    <joint name='arm_2_joint' type='revolute'>
      <child>arm_lower_link</child>
      <parent>arm_base_link</parent>
      <axis>
        <xyz>-4e-06 1 0</xyz>
        <limit>
          <lower>-1e+16</lower>
          <upper>1e+16</upper>
        </limit>
        <dynamics>
          <spring_reference>0</spring_reference>
          <spring_stiffness>0</spring_stiffness>
        </dynamics>
        <use_parent_model_frame>1</use_parent_model_frame>
      </axis>
    </joint>
    <link name='arm_upper_link'>
      <pose frame=''>-0.253504 0.019805 0.284102 1.5708 -0 1.5708</pose>
      <inertial>
        <pose frame=''>-0.017 0.018521 0.099807 0 -0 0</pose>
        <mass>4.01224</mass>
        <inertia>
          <ixx>0.0638396</ixx>
          <ixy>9.99966e-07</ixy>
          <ixz>-4.05291e-10</ixz>
          <iyy>0.0618849</iyy>
          <iyz>-0.00666596</iyz>
          <izz>0.00333272</izz>
        </inertia>
      </inertial>
      <collision name='arm_upper_link_collision'>
        <pose frame=''>-0.019806 -0.209101 0.263505 0 -0 0</pose>
        <geometry>
          <mesh>
            <scale>1 1 1</scale>
            <uri>model://arbie_description/meshes/arm_upper.stl</uri>
          </mesh>
        </geometry>
      </collision>
      <collision name='arm_upper_link_fixed_joint_lump__wrist_base_link_collision_1'>
        <pose frame=''>-0.019806 -0.209101 0.308505 0 -0 0</pose>
        <geometry>
          <mesh>
            <scale>1 1 1</scale>
            <uri>model://arbie_description/meshes/wrist_base.stl</uri>
          </mesh>
        </geometry>
      </collision>
      <visual name='arm_upper_link_visual'>
        <pose frame=''>-0.019806 -0.209101 0.263505 0 -0 0</pose>
        <geometry>
          <mesh>
            <scale>1 1 1</scale>
            <uri>model://arbie_description/meshes/arm_upper.stl</uri>
          </mesh>
        </geometry>
      </visual>
      <visual name='arm_upper_link_fixed_joint_lump__wrist_base_link_visual_1'>
        <pose frame=''>-0.019806 -0.209101 0.308505 0 -0 0</pose>
        <geometry>
          <mesh>
            <scale>1 1 1</scale>
            <uri>model://arbie_description/meshes/wrist_base.stl</uri>
          </mesh>
        </geometry>
      </visual>
    </link>
    <joint name='arm_3_joint' type='revolute'>
      <child>arm_upper_link</child>
      <parent>arm_lower_link</parent>
      <axis>
        <xyz>4e-06 -1 0</xyz>
        <limit>
          <lower>-1e+16</lower>
          <upper>1e+16</upper>
        </limit>
        <dynamics>
          <spring_reference>0</spring_reference>
          <spring_stiffness>0</spring_stiffness>
        </dynamics>
        <use_parent_model_frame>1</use_parent_model_frame>
      </axis>
    </joint>
    <link name='wrist_pitch_link'>
      <pose frame=''>0.069996 0.036206 0.319101 1.5708 -0 1.5708</pose>
      <inertial>
        <pose frame=''>-0.033299 0.002067 0.022821 0 -0 0</pose>
        <mass>0.0803966</mass>
        <inertia>
          <ixx>5.5e-05</ixx>
          <ixy>0</ixy>
          <ixz>0</ixz>
          <iyy>9.5e-05</iyy>
          <iyz>-7e-06</iyz>
          <izz>8e-05</izz>
        </inertia>
      </inertial>
      <collision name='wrist_pitch_link_collision'>
        <pose frame=''>-0.036206 -0.244101 -0.014995 0 -0 0</pose>
        <geometry>
          <mesh>
            <scale>1 1 1</scale>
            <uri>model://arbie_description/meshes/wrist_pitch.stl</uri>
          </mesh>
        </geometry>
      </collision>
      <visual name='wrist_pitch_link_visual'>
        <pose frame=''>-0.036206 -0.244101 -0.014995 0 -0 0</pose>
        <geometry>
          <mesh>
            <scale>1 1 1</scale>
            <uri>model://arbie_description/meshes/wrist_pitch.stl</uri>
          </mesh>
        </geometry>
      </visual>
    </link>
    <joint name='wrist_pitch_joint' type='revolute'>
      <child>wrist_pitch_link</child>
      <parent>arm_upper_link</parent>
      <axis>
        <xyz>-4e-06 1 0</xyz>
        <limit>
          <lower>-1e+16</lower>
          <upper>1e+16</upper>
        </limit>
        <dynamics>
          <spring_reference>0</spring_reference>
          <spring_stiffness>0</spring_stiffness>
        </dynamics>
        <use_parent_model_frame>1</use_parent_model_frame>
      </axis>
    </joint>
    <link name='wrist_yaw_link'>
      <pose frame=''>0.13312 0.002906 0.300651 1.5708 -0 1.5708</pose>
      <inertial>
        <pose frame=''>-0.013268 0.019276 0.016286 0 -0 0</pose>
        <mass>0.646948</mass>
        <inertia>
          <ixx>0.000275</ixx>
          <ixy>2e-06</ixy>
          <ixz>2e-06</ixz>
          <iyy>0.000342</iyy>
          <iyz>3e-06</iyz>
          <izz>0.000171</izz>
        </inertia>
      </inertial>
      <collision name='wrist_yaw_link_collision'>
        <pose frame=''>-0.002906 -0.225651 -0.078119 0 -0 0</pose>
        <geometry>
          <mesh>
            <scale>1 1 1</scale>
            <uri>model://arbie_description/meshes/wrist_yaw.stl</uri>
          </mesh>
        </geometry>
      </collision>
      <visual name='wrist_yaw_link_visual'>
        <pose frame=''>-0.002906 -0.225651 -0.078119 0 -0 0</pose>
        <geometry>
          <mesh>
            <scale>1 1 1</scale>
            <uri>model://arbie_description/meshes/wrist_yaw.stl</uri>
          </mesh>
        </geometry>
      </visual>
    </link>
    <joint name='wrist_yaw_joint' type='revolute'>
      <child>wrist_yaw_link</child>
      <parent>wrist_pitch_link</parent>
      <axis>
        <xyz>-4e-06 -0 -1</xyz>
        <limit>
          <lower>-1e+16</lower>
          <upper>1e+16</upper>
        </limit>
        <dynamics>
          <spring_reference>0</spring_reference>
          <spring_stiffness>0</spring_stiffness>
        </dynamics>
        <use_parent_model_frame>1</use_parent_model_frame>
      </axis>
    </joint>
    <link name='gripper_base_link'>
      <pose frame=''>0.17852 0.002907 0.31965 -2.35619 1.57079 -2.35619</pose>
      <inertial>
        <pose frame=''>-4.6e-05 -0.000692 0.034607 0 -0 0</pose>
        <mass>0.670674</mass>
        <inertia>
          <ixx>0.000199</ixx>
          <ixy>0</ixy>
          <ixz>0</ixz>
          <iyy>0.000353</iyy>
          <iyz>-3e-06</iyz>
          <izz>0.000284</izz>
        </inertia>
      </inertial>
      <collision name='gripper_base_link_collision'>
        <pose frame=''>-0.002906 -0.244651 -0.123519 0 -0 0</pose>
        <geometry>
          <mesh>
            <scale>1 1 1</scale>
            <uri>model://arbie_description/meshes/gripper_base.stl</uri>
          </mesh>
        </geometry>
      </collision>
      <visual name='gripper_base_link_visual'>
        <pose frame=''>-0.002906 -0.244651 -0.123519 0 -0 0</pose>
        <geometry>
          <mesh>
            <scale>1 1 1</scale>
            <uri>model://arbie_description/meshes/gripper_base.stl</uri>
          </mesh>
        </geometry>
      </visual>
    </link>
    <joint name='wrist_roll_joint' type='revolute'>
      <child>gripper_base_link</child>
      <parent>wrist_yaw_link</parent>
      <axis>
        <xyz>1 4e-06 -4e-06</xyz>
        <limit>
          <lower>-1e+16</lower>
          <upper>1e+16</upper>
        </limit>
        <dynamics>
          <spring_reference>0</spring_reference>
          <spring_stiffness>0</spring_stiffness>
        </dynamics>
        <use_parent_model_frame>1</use_parent_model_frame>
      </axis>
    </joint>
    <link name='gripper_left_driver_link'>
      <pose frame=''>0.22722 0.021907 0.33565 -3.14158 1.22279 -3.14158</pose>
      <inertial>
        <pose frame=''>0 -0.03094 0.004351 0 -0 0</pose>
        <mass>0.013748</mass>
        <inertia>
          <ixx>5e-06</ixx>
          <ixy>0</ixy>
          <ixz>0</ixz>
          <iyy>2e-06</iyy>
          <iyz>-1e-06</iyz>
          <izz>4e-06</izz>
        </inertia>
      </inertial>
      <collision name='gripper_left_driver_link_collision'>
        <pose frame=''>0.013094 -0.263651 -0.172219 0 -0 0</pose>
        <geometry>
          <mesh>
            <scale>1 1 1</scale>
            <uri>model://arbie_description/meshes/gripper_left_driver.stl</uri>
          </mesh>
        </geometry>
      </collision>
      <visual name='gripper_left_driver_link_visual'>
        <pose frame=''>0.013094 -0.263651 -0.172219 0 -0 0</pose>
        <geometry>
          <mesh>
            <scale>1 1 1</scale>
            <uri>model://arbie_description/meshes/gripper_left_driver.stl</uri>
          </mesh>
        </geometry>
      </visual>
    </link>
    <joint name='gripper_left_joint' type='revolute'>
      <child>gripper_left_driver_link</child>
      <parent>gripper_base_link</parent>
      <axis>
        <xyz>-4e-06 1 -4e-06</xyz>
        <limit>
          <lower>-1e+16</lower>
          <upper>1e+16</upper>
        </limit>
        <dynamics>
          <spring_reference>0</spring_reference>
          <spring_stiffness>0</spring_stiffness>
        </dynamics>
        <use_parent_model_frame>1</use_parent_model_frame>
      </axis>
    </joint>
    <link name='gripper_left_contact_link'>
      <pose frame=''>0.260122 0.019507 0.323714 -2.35619 1.57079 -2.35619</pose>
      <inertial>
        <pose frame=''>-0.004967 -0.018997 0.016467 0 -0 0</pose>
        <mass>0.0237125</mass>
        <inertia>
          <ixx>7e-06</ixx>
          <ixy>-1e-06</ixy>
          <ixz>-2e-06</ixz>
          <iyy>7e-06</iyy>
          <iyz>-1e-06</iyz>
          <izz>4e-06</izz>
        </inertia>
      </inertial>
      <collision name='gripper_left_contact_link_collision'>
        <pose frame=''>0.013094 -0.261251 -0.207219 0 -0 0</pose>
        <geometry>
          <mesh>
            <scale>1 1 1</scale>
            <uri>model://arbie_description/meshes/gripper_left_contact.stl</uri>
          </mesh>
        </geometry>
      </collision>
      <visual name='gripper_left_contact_link_visual'>
        <pose frame=''>0.013094 -0.261251 -0.207219 0 -0 0</pose>
        <geometry>
          <mesh>
            <scale>1 1 1</scale>
            <uri>model://arbie_description/meshes/gripper_left_contact.stl</uri>
          </mesh>
        </geometry>
      </visual>
    </link>
    <joint name='gripper_left_contact_dependent_joint' type='revolute'>
      <child>gripper_left_contact_link</child>
      <parent>gripper_left_driver_link</parent>
      <axis>
        <xyz>-4e-06 1 -4e-06</xyz>
        <limit>
          <lower>-1e+16</lower>
          <upper>1e+16</upper>
        </limit>
        <dynamics>
          <spring_reference>0</spring_reference>
          <spring_stiffness>0</spring_stiffness>
        </dynamics>
        <use_parent_model_frame>1</use_parent_model_frame>
      </axis>
    </joint>
    <link name='gripper_left_linkage_link'>
      <pose frame=''>0.20872 -0.003093 0.359266 -3.14158 1.22279 -3.14158</pose>
      <inertial>
        <pose frame=''>-0.005349 0.005 0.0175 0 -0 0</pose>
        <mass>0.00386409</mass>
        <inertia>
          <ixx>1e-06</ixx>
          <ixy>0</ixy>
          <ixz>0</ixz>
          <iyy>1e-06</iyy>
          <iyz>-0</iyz>
          <izz>0</izz>
        </inertia>
      </inertial>
      <collision name='gripper_left_linkage_link_collision'>
        <pose frame=''>0.03671 -0.238651 -0.153719 0 -0 0</pose>
        <geometry>
          <mesh>
            <scale>1 1 1</scale>
            <uri>model://arbie_description/meshes/gripper_left_linkage.stl</uri>
          </mesh>
        </geometry>
      </collision>
      <visual name='gripper_left_linkage_link_visual'>
        <pose frame=''>0.03671 -0.238651 -0.153719 0 -0 0</pose>
        <geometry>
          <mesh>
            <scale>1 1 1</scale>
            <uri>model://arbie_description/meshes/gripper_left_linkage.stl</uri>
          </mesh>
        </geometry>
      </visual>
    </link>
    <joint name='gripper_left_linkage_dependent_joint' type='revolute'>
      <child>gripper_left_linkage_link</child>
      <parent>gripper_base_link</parent>
      <axis>
        <xyz>-4e-06 1 -4e-06</xyz>
        <limit>
          <lower>-1e+16</lower>
          <upper>1e+16</upper>
        </limit>
        <dynamics>
          <spring_reference>0</spring_reference>
          <spring_stiffness>0</spring_stiffness>
        </dynamics>
        <use_parent_model_frame>1</use_parent_model_frame>
      </axis>
    </joint>
    <link name='gripper_right_driver_link'>
      <pose frame=''>0.22722 0.021907 0.30365 -1.1e-05 1.2228 -6e-06</pose>
      <inertial>
        <pose frame=''>0 -0.03094 0.004351 0 -0 0</pose>
        <mass>0.013748</mass>
        <inertia>
          <ixx>5e-06</ixx>
          <ixy>-0</ixy>
          <ixz>0</ixz>
          <iyy>2e-06</iyy>
          <iyz>-1e-06</iyz>
          <izz>4e-06</izz>
        </inertia>
      </inertial>
      <collision name='gripper_right_driver_link_collision'>
        <pose frame=''>-0.018906 -0.263651 -0.172219 0 -0 0</pose>
        <geometry>
          <mesh>
            <scale>1 1 1</scale>
            <uri>model://arbie_description/meshes/gripper_right_driver.stl</uri>
          </mesh>
        </geometry>
      </collision>
      <visual name='gripper_right_driver_link_visual'>
        <pose frame=''>-0.018906 -0.263651 -0.172219 0 -0 0</pose>
        <geometry>
          <mesh>
            <scale>1 1 1</scale>
            <uri>model://arbie_description/meshes/gripper_right_driver.stl</uri>
          </mesh>
        </geometry>
      </visual>
    </link>
    <joint name='gripper_right_joint' type='revolute'>
      <child>gripper_right_driver_link</child>
      <parent>gripper_base_link</parent>
      <axis>
        <xyz>-4e-06 1 -4e-06</xyz>
        <limit>
          <lower>-1e+16</lower>
          <upper>1e+16</upper>
        </limit>
        <dynamics>
          <spring_reference>0</spring_reference>
          <spring_stiffness>0</spring_stiffness>
        </dynamics>
        <use_parent_model_frame>1</use_parent_model_frame>
      </axis>
    </joint>
    <link name='gripper_right_contact_link'>
      <pose frame=''>0.260122 0.019507 0.315586 -2.35619 1.57079 -2.35619</pose>
      <inertial>
        <pose frame=''>0.004968 -0.018997 0.016467 0 -0 0</pose>
        <mass>0.0237125</mass>
        <inertia>
          <ixx>7e-06</ixx>
          <ixy>1e-06</ixy>
          <ixz>2e-06</ixz>
          <iyy>7e-06</iyy>
          <iyz>-1e-06</iyz>
          <izz>4e-06</izz>
        </inertia>
      </inertial>
      <collision name='gripper_right_contact_link_collision'>
        <pose frame=''>-0.018906 -0.261251 -0.207219 0 -0 0</pose>
        <geometry>
          <mesh>
            <scale>1 1 1</scale>
            <uri>model://arbie_description/meshes/gripper_right_contact.stl</uri>
          </mesh>
        </geometry>
      </collision>
      <visual name='gripper_right_contact_link_visual'>
        <pose frame=''>-0.018906 -0.261251 -0.207219 0 -0 0</pose>
        <geometry>
          <mesh>
            <scale>1 1 1</scale>
            <uri>model://arbie_description/meshes/gripper_right_contact.stl</uri>
          </mesh>
        </geometry>
      </visual>
    </link>
    <joint name='gripper_right_contact_dependent_joint' type='revolute'>
      <child>gripper_right_contact_link</child>
      <parent>gripper_right_driver_link</parent>
      <axis>
        <xyz>-4e-06 1 -4e-06</xyz>
        <limit>
          <lower>-1e+16</lower>
          <upper>1e+16</upper>
        </limit>
        <dynamics>
          <spring_reference>0</spring_reference>
          <spring_stiffness>0</spring_stiffness>
        </dynamics>
        <use_parent_model_frame>1</use_parent_model_frame>
      </axis>
    </joint>
    <link name='gripper_right_linkage_link'>
      <pose frame=''>0.20872 -0.003093 0.280034 -1.1e-05 1.2228 -6e-06</pose>
      <inertial>
        <pose frame=''>0.005349 0.005 -0.0175 0 -0 0</pose>
        <mass>0.00386409</mass>
        <inertia>
          <ixx>1e-06</ixx>
          <ixy>0</ixy>
          <ixz>0</ixz>
          <iyy>1e-06</iyy>
          <iyz>-0</iyz>
          <izz>0</izz>
        </inertia>
      </inertial>
      <collision name='gripper_right_linkage_link_collision'>
        <pose frame=''>-0.03671 -0.238651 0.153719 0 -0 0</pose>
        <geometry>
          <mesh>
            <scale>1 1 1</scale>
            <uri>model://arbie_description/meshes/gripper_right_linkage.stl</uri>
          </mesh>
        </geometry>
      </collision>
      <visual name='gripper_right_linkage_link_visual'>
        <pose frame=''>0.015 -0.485 -0.09 0 -0 0</pose>
        <geometry>
          <mesh>
            <scale>1 1 1</scale>
            <uri>model://arbie_description/meshes/gripper_right_linkage.stl</uri>
          </mesh>
        </geometry>
      </visual>
    </link>
    <joint name='gripper_right_linkage_dependent_joint' type='revolute'>
      <child>gripper_right_linkage_link</child>
      <parent>gripper_base_link</parent>
      <axis>
        <xyz>-4e-06 1 -4e-06</xyz>
        <limit>
          <lower>-1e+16</lower>
          <upper>1e+16</upper>
        </limit>
        <dynamics>
          <spring_reference>0</spring_reference>
          <spring_stiffness>0</spring_stiffness>
        </dynamics>
        <use_parent_model_frame>1</use_parent_model_frame>
      </axis>
    </joint>
    <link name='camera_mount_link'>
      <pose frame=''>0.272572 0.033808 0.14885 1.5708 -0 1.5708</pose>
      <inertial>
        <pose frame=''>-0.03208 0.007624 0.013077 0 -0 0</pose>
        <mass>0.554059</mass>
        <inertia>
          <ixx>0.000139244</ixx>
          <ixy>1.15465e-05</ixy>
          <ixz>-2.58634e-06</ixz>
          <iyy>0.000380569</iyy>
          <iyz>1.58344e-05</iyz>
          <izz>0.000456506</izz>
        </inertia>
      </inertial>
      <collision name='camera_mount_link_collision'>
        <pose frame=''>-0.033807 -0.073851 -0.262572 0 -0 0</pose>
        <geometry>
          <mesh>
            <scale>1 1 1</scale>
            <uri>model://arbie_description/meshes/camera_mount.stl</uri>
          </mesh>
        </geometry>
      </collision>
      <collision name='camera_mount_link_fixed_joint_lump__camera_d435_link_collision_1'>
        <pose frame=''>-0.031307 -0.073851 -0.262572 0 0 0</pose>
        <geometry>
          <mesh>
            <scale>1 1 1</scale>
            <uri>model://arbie_description/meshes/camera_d435.stl</uri>
          </mesh>
        </geometry>
        <surface>
          <contact>
            <ode/>
          </contact>
          <friction>
            <ode/>
          </friction>
        </surface>
      </collision>
      <collision name='camera_mount_link_fixed_joint_lump__camera_t265_link_collision_2'>
        <pose frame=''>-0.034453 -0.073851 -0.262572 0 0 0</pose>
        <geometry>
          <mesh>
            <scale>1 1 1</scale>
            <uri>model://arbie_description/meshes/camera_t265.stl</uri>
          </mesh>
        </geometry>
        <surface>
          <contact>
            <ode/>
          </contact>
          <friction>
            <ode/>
          </friction>
        </surface>
      </collision>
      <visual name='camera_mount_link_visual'>
        <pose frame=''>-0.033807 -0.073851 -0.262572 0 -0 0</pose>
        <geometry>
          <mesh>
            <scale>1 1 1</scale>
            <uri>model://arbie_description/meshes/camera_mount.stl</uri>
          </mesh>
        </geometry>
      </visual>
      <visual name='camera_mount_link_fixed_joint_lump__camera_d435_link_visual_1'>
        <pose frame=''>-0.031307 -0.073851 -0.262572 0 0 0</pose>
        <geometry>
          <mesh>
            <scale>1 1 1</scale>
            <uri>model://arbie_description/meshes/camera_d435.stl</uri>
          </mesh>
        </geometry>
        <material>
          <script>
            <uri>__default__</uri>
            <name>__default__</name>
          </script>
        </material>
      </visual>
      <visual name='camera_mount_link_fixed_joint_lump__camera_t265_link_visual_2'>
        <pose frame=''>-0.034453 -0.073851 -0.262572 0 0 0</pose>
        <geometry>
          <mesh>
            <scale>1 1 1</scale>
            <uri>model://arbie_description/meshes/camera_t265.stl</uri>
          </mesh>
        </geometry>
        <material>
          <script>
            <uri>__default__</uri>
            <name>__default__</name>
          </script>
        </material>
      </visual>
      <velocity_decay/>
      <sensor name='d435_camera' type='depth'>
        <update_rate>30</update_rate>
        <camera name='__default__'>
          <horizontal_fov>1.0472</horizontal_fov>
          <image>
            <width>640</width>
            <height>480</height>
            <format>R8G8B8</format>
          </image>
          <clip>
            <near>0.05</near>
            <far>300</far>
          </clip>
        </camera>
        <plugin name='d435_camera_controller' filename='libgazebo_ros_openni_kinect.so'>
          <baseline>0.2</baseline>
          <alwaysOn>1</alwaysOn>
          <updateRate>1.0</updateRate>
          <cameraName>d435</cameraName>
          <imageTopicName>/d435/color/image_raw</imageTopicName>
          <cameraInfoTopicName>/d435/color/camera_info</cameraInfoTopicName>
          <depthImageTopicName>/d435/depth/image_raw</depthImageTopicName>
          <depthImageInfoTopicName>/d435/depth/camera_info</depthImageInfoTopicName>
          <pointCloudTopicName>/d435/depth/points</pointCloudTopicName>
          <frameName>camera_d435_link</frameName>
          <pointCloudCutoff>0.5</pointCloudCutoff>
          <pointCloudCutoffMax>3.0</pointCloudCutoffMax>
          <distortionK1>0.00000001</distortionK1>
          <distortionK2>0.00000001</distortionK2>
          <distortionK3>0.00000001</distortionK3>
          <distortionT1>0.00000001</distortionT1>
          <distortionT2>0.00000001</distortionT2>
          <CxPrime>0</CxPrime>
          <Cx>0</Cx>
          <Cy>0</Cy>
          <focalLength>0</focalLength>
          <hackBaseline>0</hackBaseline>
        </plugin>
        <pose frame=''>-0.032557 0.016149 0.022428 3.14159 -1.57079 1.57079</pose>
      </sensor>
      <velocity_decay/>
      <sensor name='d435_imu' type='imu'>
        <always_on>1</always_on>
        <update_rate>30</update_rate>
        <visualize>1</visualize>
        <topic>/d435/imu</topic>
        <plugin name='d435_imu_controller' filename='libgazebo_ros_imu_sensor.so'>
          <topicName>/d435/imu</topicName>
          <bodyName>camera_d435_link</bodyName>
          <updateRateHZ>10.0</updateRateHZ>
          <gaussianNoise>0.0</gaussianNoise>
          <xyzOffset>0 0 0</xyzOffset>
          <rpyOffset>0 0 0</rpyOffset>
          <frameName>camera_d435_link</frameName>
          <initialOrientationAsReference>0</initialOrientationAsReference>
        </plugin>
        <pose frame=''>-0.032557 0.016149 0.022428 3.14159 -1.57079 1.57079</pose>
      </sensor>
      <gravity>1</gravity>
      <velocity_decay/>
      <sensor name='t265_camera' type='multicamera'>
        <update_rate>30</update_rate>
        <camera name='left'>
          <pose frame=''>0 0.035 0 0 -0 0</pose>
          <horizontal_fov>1.39626</horizontal_fov>
          <image>
            <width>800</width>
            <height>800</height>
            <format>R8G8B8</format>
          </image>
          <clip>
            <near>0.02</near>
            <far>300</far>
          </clip>
          <noise>
            <type>gaussian</type>
            <mean>0</mean>
            <stddev>0.007</stddev>
          </noise>
        </camera>
        <camera name='right'>
          <pose frame=''>0 -0.035 0 0 -0 0</pose>
          <horizontal_fov>1.39626</horizontal_fov>
          <image>
            <width>800</width>
            <height>800</height>
            <format>R8G8B8</format>
          </image>
          <clip>
            <near>0.02</near>
            <far>300</far>
          </clip>
          <noise>
            <type>gaussian</type>
            <mean>0</mean>
            <stddev>0.007</stddev>
          </noise>
        </camera>
        <plugin name='t265_camera_controller' filename='libgazebo_ros_multicamera.so'>
          <alwaysOn>1</alwaysOn>
          <updateRate>0.0</updateRate>
          <cameraName>t265</cameraName>
          <imageTopicName>image_raw</imageTopicName>
          <cameraInfoTopicName>camera_info</cameraInfoTopicName>
          <frameName>camera_t265_link</frameName>
          <hackBaseline>0.07</hackBaseline>
          <distortionK1>0.0</distortionK1>
          <distortionK2>0.0</distortionK2>
          <distortionK3>0.0</distortionK3>
          <distortionT1>0.0</distortionT1>
          <distortionT2>0.0</distortionT2>
        </plugin>
        <pose frame=''>-0.03413 -0.0135 0.024 3.14159 -1.57079 1.57079</pose>
      </sensor>
      <gravity>1</gravity>
      <velocity_decay/>
      <gravity>1</gravity>
      <sensor name='t265_imu' type='imu'>
        <always_on>1</always_on>
        <update_rate>30</update_rate>
        <visualize>1</visualize>
        <topic>/t265/imu</topic>
        <plugin name='t265_imu_controller' filename='libgazebo_ros_imu_sensor.so'>
          <topicName>/t265/imu</topicName>
          <bodyName>camera_t265_link</bodyName>
          <updateRateHZ>10.0</updateRateHZ>
          <gaussianNoise>0.0</gaussianNoise>
          <xyzOffset>0 0 0</xyzOffset>
          <rpyOffset>0 0 0</rpyOffset>
          <frameName>camera_t265_link</frameName>
          <initialOrientationAsReference>0</initialOrientationAsReference>
        </plugin>
        <pose frame=''>-0.03413 -0.0135 0.024 3.14159 -1.57079 1.57079</pose>
      </sensor>
    </link>
    <joint name='camera_tilt_joint' type='revolute'>
      <child>camera_mount_link</child>
      <parent>base_link</parent>
      <axis>
        <xyz>-4e-06 1 0</xyz>
        <limit>
          <lower>-1e+16</lower>
          <upper>1e+16</upper>
        </limit>
        <dynamics>
          <spring_reference>0</spring_reference>
          <spring_stiffness>0</spring_stiffness>
        </dynamics>
        <use_parent_model_frame>1</use_parent_model_frame>
      </axis>
    </joint>
    <link name='tracks_left_wheel_link'>
      <pose frame=''>0.099022 0.148306 0.099326 1.5708 -0 1.5708</pose>
      <inertial>
        <pose frame=''>0 0 0 3.14159 1.57079 3.14159</pose>
        <mass>0.5</mass>
        <inertia>
          <ixx>0.00186667</ixx>
          <ixy>0</ixy>
          <ixz>0</ixz>
          <iyy>0.00186667</iyy>
          <iyz>0</iyz>
          <izz>0.0036</izz>
        </inertia>
      </inertial>
      <collision name='tracks_left_wheel_link_collision'>
        <pose frame=''>0 0 0 3.14159 1.57079 3.14159</pose>
        <geometry>
          <cylinder>
            <length>0.04</length>
            <radius>0.12</radius>
          </cylinder>
        </geometry>
      </collision>
      <visual name='tracks_left_wheel_link_visual'>
        <pose frame=''>0 0 0 3.14159 1.57079 3.14159</pose>
        <geometry>
          <cylinder>
            <length>0.04</length>
            <radius>0.12</radius>
          </cylinder>
        </geometry>
      </visual>
    </link>
    <joint name='tracks_left_joint' type='revolute'>
      <child>tracks_left_wheel_link</child>
      <parent>base_link</parent>
      <axis>
        <xyz>-4e-06 1 0</xyz>
        <limit>
          <lower>-1e+16</lower>
          <upper>1e+16</upper>
        </limit>
        <dynamics>
          <spring_reference>0</spring_reference>
          <spring_stiffness>0</spring_stiffness>
        </dynamics>
        <use_parent_model_frame>1</use_parent_model_frame>
      </axis>
    </joint>
    <link name='flipper_front_right_link'>
      <pose frame=''>0.229023 -0.174693 0.099728 1.5708 -0 1.5708</pose>
      <inertial>
        <pose frame=''>0.173998 0.165376 -0 0 -0 0</pose>
        <mass>27.736</mass>
        <inertia>
          <ixx>0.170702</ixx>
          <ixy>-1.11022e-16</ixy>
          <ixz>1.69806e-08</ixz>
          <iyy>0.716637</iyy>
          <iyz>0</iyz>
          <izz>0.802767</izz>
        </inertia>
      </inertial>
      <collision name='flipper_front_right_link_collision'>
        <pose frame=''>0.174694 -0.024729 -0.219022 0 -0 0</pose>
        <geometry>
          <mesh>
            <scale>1 1 1</scale>
            <uri>model://arbie_description/meshes/flipper_front_right.stl</uri>
          </mesh>
        </geometry>
      </collision>
      <collision name='flipper_front_right_link_fixed_joint_lump__flipper_front_left_link_collision_1'>
        <pose frame=''>0.17469 -0.024729 -0.219022 0 -0 0</pose>
        <geometry>
          <mesh>
            <scale>1 1 1</scale>
            <uri>model://arbie_description/meshes/flipper_front_left.stl</uri>
          </mesh>
        </geometry>
      </collision>
      <visual name='flipper_front_right_link_visual'>
        <pose frame=''>0.174694 -0.024729 -0.219022 0 -0 0</pose>
        <geometry>
          <mesh>
            <scale>1 1 1</scale>
            <uri>model://arbie_description/meshes/flipper_front_right.stl</uri>
          </mesh>
        </geometry>
      </visual>
      <visual name='flipper_front_right_link_fixed_joint_lump__flipper_front_left_link_visual_1'>
        <pose frame=''>0.17469 -0.024729 -0.219022 0 -0 0</pose>
        <geometry>
          <mesh>
            <scale>1 1 1</scale>
            <uri>model://arbie_description/meshes/flipper_front_left.stl</uri>
          </mesh>
        </geometry>
      </visual>
    </link>
    <joint name='flippers_front_joint' type='revolute'>
      <child>flipper_front_right_link</child>
      <parent>base_link</parent>
      <axis>
        <xyz>-4e-06 1 0</xyz>
        <limit>
          <lower>-1e+16</lower>
          <upper>1e+16</upper>
        </limit>
        <dynamics>
          <spring_reference>0</spring_reference>
          <spring_stiffness>0</spring_stiffness>
        </dynamics>
        <use_parent_model_frame>1</use_parent_model_frame>
      </axis>
    </joint>
    <link name='flipper_rear_right_link'>
      <pose frame=''>-0.230977 -0.174695 0.09973 1.5708 -0 1.5708</pose>
      <inertial>
        <pose frame=''>0.173998 0.165376 -0 0 -0 0</pose>
        <mass>27.736</mass>
        <inertia>
          <ixx>0.170702</ixx>
          <ixy>-2.22045e-16</ixy>
          <ixz>1.69806e-08</ixz>
          <iyy>0.716637</iyy>
          <iyz>0</iyz>
          <izz>0.802767</izz>
        </inertia>
      </inertial>
      <collision name='flipper_rear_right_link_collision'>
        <pose frame=''>0.174694 -0.024729 0.240978 0 -0 0</pose>
        <geometry>
          <mesh>
            <scale>1 1 1</scale>
            <uri>model://arbie_description/meshes/flipper_rear_right.stl</uri>
          </mesh>
        </geometry>
      </collision>
      <collision name='flipper_rear_right_link_fixed_joint_lump__flipper_rear_left_link_collision_1'>
        <pose frame=''>0.17469 -0.024729 0.240978 0 -0 0</pose>
        <geometry>
          <mesh>
            <scale>1 1 1</scale>
            <uri>model://arbie_description/meshes/flipper_rear_left.stl</uri>
          </mesh>
        </geometry>
      </collision>
      <visual name='flipper_rear_right_link_visual'>
        <pose frame=''>0.174694 -0.024729 0.240978 0 -0 0</pose>
        <geometry>
          <mesh>
            <scale>1 1 1</scale>
            <uri>model://arbie_description/meshes/flipper_rear_right.stl</uri>
          </mesh>
        </geometry>
      </visual>
      <visual name='flipper_rear_right_link_fixed_joint_lump__flipper_rear_left_link_visual_1'>
        <pose frame=''>0.17469 -0.024729 0.240978 0 -0 0</pose>
        <geometry>
          <mesh>
            <scale>1 1 1</scale>
            <uri>model://arbie_description/meshes/flipper_rear_left.stl</uri>
          </mesh>
        </geometry>
      </visual>
    </link>
    <joint name='flippers_rear_joint' type='revolute'>
      <child>flipper_rear_right_link</child>
      <parent>base_link</parent>
      <axis>
        <xyz>-4e-06 1 0</xyz>
        <limit>
          <lower>-1e+16</lower>
          <upper>1e+16</upper>
        </limit>
        <dynamics>
          <spring_reference>0</spring_reference>
          <spring_stiffness>0</spring_stiffness>
        </dynamics>
        <use_parent_model_frame>1</use_parent_model_frame>
      </axis>
    </joint>
    <link name='tracks_right_wheel_link'>
      <pose frame=''>0.099023 -0.149694 0.099326 1.5708 -0 1.5708</pose>
      <inertial>
        <pose frame=''>0 0 0 3.14159 1.57079 3.14159</pose>
        <mass>0.5</mass>
        <inertia>
          <ixx>0.00186667</ixx>
          <ixy>0</ixy>
          <ixz>0</ixz>
          <iyy>0.00186667</iyy>
          <iyz>0</iyz>
          <izz>0.0036</izz>
        </inertia>
      </inertial>
      <collision name='tracks_right_wheel_link_collision'>
        <pose frame=''>0 0 0 3.14159 1.57079 3.14159</pose>
        <geometry>
          <cylinder>
            <length>0.04</length>
            <radius>0.12</radius>
          </cylinder>
        </geometry>
      </collision>
      <visual name='tracks_right_wheel_link_visual'>
        <pose frame=''>0 0 0 3.14159 1.57079 3.14159</pose>
        <geometry>
          <cylinder>
            <length>0.04</length>
            <radius>0.12</radius>
          </cylinder>
        </geometry>
      </visual>
    </link>
    <joint name='tracks_right_joint' type='revolute'>
      <child>tracks_right_wheel_link</child>
      <parent>base_link</parent>
      <axis>
        <xyz>-4e-06 1 0</xyz>
        <limit>
          <lower>-1e+16</lower>
          <upper>1e+16</upper>
        </limit>
        <dynamics>
          <spring_reference>0</spring_reference>
          <spring_stiffness>0</spring_stiffness>
        </dynamics>
        <use_parent_model_frame>1</use_parent_model_frame>
      </axis>
    </joint>
    <plugin name='gazebo_ros_control' filename='libgazebo_ros_control.so'/>
    <static>0</static>
    <joint name='gripper_right_linkage_dependent_2_joint' type='revolute'>
      <pose frame=''>0.0235 -0.0225 -0.0185 0 -0 0</pose>
      <parent>gripper_right_linkage_link</parent>
      <child>gripper_right_contact_link"</child>
      <axis>
        <xyz>0 1 0</xyz>
        <use_parent_model_frame>1</use_parent_model_frame>
        <limit>
          <lower>-1e+16</lower>
          <upper>1e+16</upper>
        </limit>
      </axis>
    </joint>
    <joint name='gripper_left_linkage_dependent_2_joint' type='revolute'>
      <pose frame=''>0.0235 -0.0225 -0.0185 0 -0 0</pose>
      <parent>gripper_left_linkage_link</parent>
      <child>gripper_left_contact_link"</child>
      <axis>
        <xyz>0 1 0</xyz>
        <use_parent_model_frame>1</use_parent_model_frame>
        <limit>
          <lower>-1e+16</lower>
          <upper>1e+16</upper>
        </limit>
      </axis>
    </joint>
  </model>
</sdf>
