<?xml version='1.0'?>
<to_include xmlns:xacro="https://www.ros.org/wiki/xacro">

<!-- ARM LINKS -->

<link name="arm_base_link">
  <inertial>
    <origin rpy="0 0 0" xyz="-0.0016420049931783305 0.023135022831294483 -7.480052882286037e-06"/>
    <mass value="3.3465093478653403"/>
    <inertia ixx="0.005075" ixy="0.000176" ixz="-0.0" iyy="0.010632" iyz="1e-06" izz="0.009087"/>
  </inertial>
  <visual>
    <origin rpy="0 0 0" xyz="0.000694 -0.107101 -0.186272"/>
    <geometry>
      <mesh filename="package://arbie_description/meshes/arm_base.stl"/>
    </geometry>
    <material name="arm"/>
  </visual>
  <collision>
    <origin rpy="0 0 0" xyz="0.000694 -0.107101 -0.186272"/>
    <geometry>
      <mesh filename="package://arbie_description/meshes/arm_base.stl"/>
    </geometry>
  </collision>
</link>

<link name="arm_lower_link">
  <inertial>
    <origin rpy="0 0 0" xyz="-0.053878611230066 0.007243666919340863 -0.13003163766238773"/>
    <mass value="9.290217371436244"/>
    <inertia ixx="0.285483" ixy="0.000938" ixz="-0.009995" iyy="0.285913" iyz="0.0181" izz="0.011485"/>
  </inertial>
  <visual>
    <origin rpy="0 0 0" xyz="-0.052806 -0.174101 -0.186495"/>
    <geometry>
      <mesh filename="package://arbie_description/meshes/arm_lower.stl"/>
    </geometry>
    <material name="arm"/>
  </visual>
  <collision>
    <origin rpy="0 0 0" xyz="-0.052806 -0.174101 -0.186495"/>
    <geometry>
      <mesh filename="package://arbie_description/meshes/arm_lower.stl"/>
    </geometry>
  </collision>
</link>

<link name="arm_upper_link">
  <inertial>
    <origin rpy="0 0 0" xyz="-0.016999544747906395 0.013376208584352511 0.039239753662060034"/>
    <mass value="3.0631873001334227"/>
    <inertia ixx="0.015235" ixy="0.0" ixz="0.0" iyy="0.013273" iyz="-0.002633" izz="0.002494"/>
  </inertial>
  <visual>
    <origin rpy="0 0 0" xyz="-0.019806 -0.209101 0.263505"/>
    <geometry>
      <mesh filename="package://arbie_description/meshes/arm_upper.stl"/>
    </geometry>
    <material name="arm"/>
  </visual>
  <collision>
    <origin rpy="0 0 0" xyz="-0.019806 -0.209101 0.263505"/>
    <geometry>
      <mesh filename="package://arbie_description/meshes/arm_upper.stl"/>
    </geometry>
  </collision>
</link>


<!-- WRIST LINKS -->

<link name="wrist_base_link">
  <inertial>
    <origin rpy="0 0 0" xyz="4.57436623640603e-07 0.00012475245793225342 0.025292868333247724"/>
    <mass value="0.9490572232520995"/>
    <inertia ixx="0.000757" ixy="1e-06" ixz="-0.0" iyy="0.001107" iyz="2e-06" izz="0.000496"/>
  </inertial>
  <visual>
    <origin rpy="0 0 0" xyz="-0.002806 -0.244101 0.038505"/>
    <geometry>
      <mesh filename="package://arbie_description/meshes/wrist_base.stl"/>
    </geometry>
    <material name="wrist"/>
  </visual>
  <collision>
    <origin rpy="0 0 0" xyz="-0.002806 -0.244101 0.038505"/>
    <geometry>
      <mesh filename="package://arbie_description/meshes/wrist_base.stl"/>
    </geometry>
  </collision>
</link>

<link name="wrist_pitch_link">
  <inertial>
    <origin rpy="0 0 0" xyz="-0.0332984740595477 0.0020671950198172806 0.02282064850736746"/>
    <mass value="0.08039663104912372"/>
    <inertia ixx="5.5e-05" ixy="0.0" ixz="0.0" iyy="9.5e-05" iyz="-7e-06" izz="8e-05"/>
  </inertial>
  <visual>
    <origin rpy="0 0 0" xyz="-0.036206 -0.244101 -0.014995"/>
    <geometry>
      <mesh filename="package://arbie_description/meshes/wrist_pitch.stl"/>
    </geometry>
    <material name="wrist"/>
  </visual>
  <collision>
    <origin rpy="0 0 0" xyz="-0.036206 -0.244101 -0.014995"/>
    <geometry>
      <mesh filename="package://arbie_description/meshes/wrist_pitch.stl"/>
    </geometry>
  </collision>
</link>

<link name="wrist_yaw_link">
  <inertial>
    <origin rpy="0 0 0" xyz="-0.013267784777998575 0.01927575393175185 0.016285676232992735"/>
    <mass value="0.6469480906726006"/>
    <inertia ixx="0.000275" ixy="2e-06" ixz="2e-06" iyy="0.000342" iyz="3e-06" izz="0.000171"/>
  </inertial>
  <visual>
    <origin rpy="0 0 0" xyz="-0.002906 -0.225651 -0.078119"/>
    <geometry>
      <mesh filename="package://arbie_description/meshes/wrist_yaw.stl"/>
    </geometry>
    <material name="wrist"/>
  </visual>
  <collision>
    <origin rpy="0 0 0" xyz="-0.002906 -0.225651 -0.078119"/>
    <geometry>
      <mesh filename="package://arbie_description/meshes/wrist_yaw.stl"/>
    </geometry>
  </collision>
</link>


<!-- GRIPPER LINKS
<inertial> for gripper contact and linkage links are commented out.
Only the driver link of the gripper is included. It is possible to add in the
whole parallel linkage, but it is difficult to get right and is unstable,
so am just omitting it for now. It's not that important to simulate this.
-->

<link name="gripper_base_link">
  <inertial>
    <origin rpy="0 0 0" xyz="-4.607760189011137e-05 -0.0006917471996047975 0.03460710409065769"/>
    <mass value="0.6706735500880907"/>
    <inertia ixx="0.000199" ixy="0.0" ixz="0.0" iyy="0.000353" iyz="-3e-06" izz="0.000284"/>
  </inertial>
  <visual>
    <origin rpy="0 0 0" xyz="-0.002906 -0.244651 -0.123519"/>
    <geometry>
      <mesh filename="package://arbie_description/meshes/gripper_base.stl"/>
    </geometry>
    <material name="gripper"/>
  </visual>
  <collision>
    <origin rpy="0 0 0" xyz="-0.002906 -0.244651 -0.123519"/>
    <geometry>
      <mesh filename="package://arbie_description/meshes/gripper_base.stl"/>
    </geometry>
  </collision>
</link>

<link name="gripper_right_driver_link">
  <inertial>
    <origin rpy="0 0 0" xyz="4.537220775792383e-07 -0.03094002747411953 0.004350576193156569"/>
    <mass value="0.01374798583124482"/>
    <inertia ixx="5e-06" ixy="-0.0" ixz="0.0" iyy="2e-06" iyz="-1e-06" izz="4e-06"/>
  </inertial>
  <visual>
    <origin rpy="0 0 0" xyz="-0.018906 -0.263651 -0.172219"/>
    <geometry>
      <mesh filename="package://arbie_description/meshes/gripper_right_driver.stl"/>
    </geometry>
    <material name="gripper"/>
  </visual>
  <collision>
    <origin rpy="0 0 0" xyz="-0.018906 -0.263651 -0.172219"/>
    <geometry>
      <mesh filename="package://arbie_description/meshes/gripper_right_driver.stl"/>
    </geometry>
  </collision>
</link>

<link name="gripper_right_linkage_link">
  <!--<inertial>
    <origin rpy="0 0 0" xyz="0.005348977862044579 0.00500022075444323 -0.01750042810563407"/>
    <mass value="0.00386409068463368"/>
    <inertia ixx="1e-06" ixy="0.0" ixz="0.0" iyy="1e-06" iyz="-0.0" izz="0.0"/>
  </inertial>-->
  <visual>
    <origin rpy="0 0 0" xyz="0.015 -0.485 -0.09"/>
    <geometry>
      <mesh filename="package://arbie_description/meshes/gripper_right_linkage.stl"/>
    </geometry>
    <material name="gripper"/>
  </visual>
  <collision>
    <origin rpy="0 0 0" xyz="0.015 -0.485 -0.09"/>
    <geometry>
      <mesh filename="package://arbie_description/meshes/gripper_right_linkage.stl"/>
    </geometry>
  </collision>
</link>

<link name="gripper_right_contact_link">
  <!--<inertial>
    <origin rpy="0 0 0" xyz="0.004967829686739981 -0.01899661466926142 0.016466890477460472"/>
    <mass value="0.023712538812289255"/>
    <inertia ixx="7e-06" ixy="1e-06" ixz="2e-06" iyy="7e-06" iyz="-1e-06" izz="4e-06"/>
  </inertial>-->
  <visual>
    <origin rpy="0 0 0" xyz="-0.018906 -0.261251 -0.207219"/>
    <geometry>
      <mesh filename="package://arbie_description/meshes/gripper_right_contact.stl"/>
    </geometry>
    <material name="gripper"/>
  </visual>
  <collision>
    <origin rpy="0 0 0" xyz="-0.018906 -0.261251 -0.207219"/>
    <geometry>
      <mesh filename="package://arbie_description/meshes/gripper_right_contact.stl"/>
    </geometry>
  </collision>
</link>
-->

<link name="gripper_left_driver_link">
  <inertial>
    <origin rpy="0 0 0" xyz="4.552690735497994e-07 -0.030940033304886344 0.004350583148282683"/>
    <mass value="0.013747989643093032"/>
    <inertia ixx="5e-06" ixy="0.0" ixz="0.0" iyy="2e-06" iyz="-1e-06" izz="4e-06"/>
  </inertial>
  <visual>
    <origin rpy="0 0 0" xyz="0.013094 -0.263651 -0.172219"/>
    <geometry>
      <mesh filename="package://arbie_description/meshes/gripper_left_driver.stl"/>
    </geometry>
    <material name="gripper"/>
  </visual>
  <collision>
    <origin rpy="0 0 0" xyz="0.013094 -0.263651 -0.172219"/>
    <geometry>
      <mesh filename="package://arbie_description/meshes/gripper_left_driver.stl"/>
    </geometry>
  </collision>
</link>

<link name="gripper_left_contact_link">
  <!--<inertial>
    <origin rpy="0 0 0" xyz="-0.0049669191825520796 -0.01899661466926142 0.016466890477460527"/>
    <mass value="0.023712538812289255"/>
    <inertia ixx="7e-06" ixy="-1e-06" ixz="-2e-06" iyy="7e-06" iyz="-1e-06" izz="4e-06"/>
  </inertial>-->
  <visual>
    <origin rpy="0 0 0" xyz="0.013094 -0.261251 -0.207219"/>
    <geometry>
      <mesh filename="package://arbie_description/meshes/gripper_left_contact.stl"/>
    </geometry>
    <material name="gripper"/>
  </visual>
  <collision>
    <origin rpy="0 0 0" xyz="0.013094 -0.261251 -0.207219"/>
    <geometry>
      <mesh filename="package://arbie_description/meshes/gripper_left_contact.stl"/>
    </geometry>
  </collision>
</link>

<link name="gripper_left_linkage_link">
  <!--<inertial>
    <origin rpy="0 0 0" xyz="-0.005348977862044579 0.00500022075444323 0.01750042810563407"/>
    <mass value="0.00386409068463368"/>
    <inertia ixx="1e-06" ixy="0.0" ixz="0.0" iyy="1e-06" iyz="-0.0" izz="0.0"/>
  </inertial>-->
  <visual>
    <origin rpy="0 0 0" xyz="0.03671 -0.238651 -0.153719"/>
    <geometry>
      <mesh filename="package://arbie_description/meshes/gripper_left_linkage.stl"/>
    </geometry>
    <material name="gripper"/>
  </visual>
  <collision>
    <origin rpy="0 0 0" xyz="0.03671 -0.238651 -0.153719"/>
    <geometry>
      <mesh filename="package://arbie_description/meshes/gripper_left_linkage.stl"/>
    </geometry>
  </collision>
</link>

<!-- RIGID JOINTS -->

<joint name="rigid_arm_upper_to_wrist_base_joint" type="fixed">
  <origin rpy="0 0 0" xyz="-0.017 0.035 0.27"/>
  <parent link="arm_upper_link"/>
  <child link="wrist_base_link"/>
</joint>

<!-- ARM JOINTS -->

<joint name="arm_1_joint" type="continuous">
  <origin rpy="0 0 0" xyz="-0.000694 0.107101 0.186272"/>
  <parent link="body_link"/>
  <child link="arm_base_link"/>
  <axis xyz="0 1 0"/>
</joint>

<transmission name="arm_1_tran">
  <type>transmission_interface/SimpleTransmission</type>
  <joint name="arm_1_joint">
    <hardwareInterface>hardware_interface/PositionJointInterface</hardwareInterface>
  </joint>
  <actuator name="arm_1_actuator">
    <hardwareInterface>PositionJointInterface</hardwareInterface>
    <mechanicalReduction>1</mechanicalReduction>
  </actuator>
</transmission>

<joint name="arm_2_joint" type="revolute">
  <origin rpy="0 0 0" xyz="0.0535 0.067 0.000223"/>
  <parent link="arm_base_link"/>
  <child link="arm_lower_link"/>
  <axis xyz="1 0 0"/>
  <limit effort="1000.0" lower="0.0" upper="${pi}" velocity="1"/>
</joint>

<transmission name="arm_2_transmission">
  <type>transmission_interface/SimpleTransmission</type>
  <joint name="arm_2_joint">
    <hardwareInterface>hardware_interface/PositionJointInterface</hardwareInterface>
  </joint>
  <actuator name="arm_2_actuator">
    <hardwareInterface>PositionJointInterface</hardwareInterface>
    <mechanicalReduction>1</mechanicalReduction>
  </actuator>
</transmission>

<joint name="arm_3_joint" type="revolute">
  <origin rpy="0 0 0" xyz="-0.033 0.035 -0.45"/>
  <parent link="arm_lower_link"/>
  <child link="arm_upper_link"/>
  <axis xyz="-1 0 0"/>
  <limit effort="1000.0" lower="0.0" upper="${pi}" velocity="1"/>
</joint>

<transmission name="arm_3_transmission">
  <type>transmission_interface/SimpleTransmission</type>
  <joint name="arm_3_joint">
    <hardwareInterface>hardware_interface/PositionJointInterface</hardwareInterface>
  </joint>
  <actuator name="arm_3_actuator">
    <hardwareInterface>PositionJointInterface</hardwareInterface>
    <mechanicalReduction>1</mechanicalReduction>
  </actuator>
</transmission>


<!-- WRIST JOINTS -->

<joint name="wrist_pitch_joint" type="revolute">
  <origin rpy="0 0 0" xyz="0.0334 0.0 0.0535"/>
  <parent link="wrist_base_link"/>
  <child link="wrist_pitch_link"/>
  <axis xyz="1 0 0"/>
  <limit effort="1000.0" lower="${-pi/2}" upper="${pi/2}" velocity="1"/>
</joint>

<transmission name="wrist_pitch_transmission">
  <type>transmission_interface/SimpleTransmission</type>
  <joint name="wrist_pitch_joint">
    <hardwareInterface>hardware_interface/PositionJointInterface</hardwareInterface>
  </joint>
  <actuator name="wrist_pitch_actuator">
    <hardwareInterface>PositionJointInterface</hardwareInterface>
    <mechanicalReduction>1</mechanicalReduction>
  </actuator>
</transmission>

<joint name="wrist_yaw_joint" type="revolute">
  <origin rpy="0 0 0" xyz="-0.0333 -0.01845 0.063124"/>
  <parent link="wrist_pitch_link"/>
  <child link="wrist_yaw_link"/>
  <axis xyz="0 -1 0"/>
  <limit effort="1000.0" lower="${-pi/2}" upper="${pi/2}" velocity="1"/>
</joint>

<transmission name="wrist_yaw_transmsission">
  <type>transmission_interface/SimpleTransmission</type>
  <joint name="wrist_yaw_joint">
    <hardwareInterface>hardware_interface/PositionJointInterface</hardwareInterface>
  </joint>
  <actuator name="wrist_yaw_actuator">
    <hardwareInterface>PositionJointInterface</hardwareInterface>
    <mechanicalReduction>1</mechanicalReduction>
  </actuator>
</transmission>

<joint name="wrist_roll_joint" type="continuous">
  <origin rpy="0 0 -1.5708" xyz="0.0 0.019 0.0454"/>
  <parent link="wrist_yaw_link"/>
  <child link="gripper_base_link"/>
  <axis xyz="0 0 1"/>
</joint>

<transmission name="wrist_roll_transmission">
  <type>transmission_interface/SimpleTransmission</type>
  <joint name="wrist_roll_joint">
    <hardwareInterface>hardware_interface/PositionJointInterface</hardwareInterface>
  </joint>
  <actuator name="wrist_roll_actuator">
    <hardwareInterface>PositionJointInterface</hardwareInterface>
    <mechanicalReduction>1</mechanicalReduction>
  </actuator>
</transmission>


<!-- GRIPPER DRIVEN JOINTS -->

<!-- Use the right gripper joint as the "driven" joint -->
<joint name="gripper_joint" type="continuous">
  <origin rpy="0 -0.348 0" xyz="0.016 0.019 0.0487"/>
  <parent link="gripper_base_link"/>
  <child link="gripper_right_driver_link"/>
  <axis xyz="0 1 0"/>
</joint>

<transmission name="gripper_right_driver_transmission">
  <type>transmission_interface/SimpleTransmission</type>
  <joint name="gripper_joint">
    <hardwareInterface>hardware_interface/PositionJointInterface</hardwareInterface>
  </joint>
  <actuator name="gripper_right_driver_actuator">
    <hardwareInterface>PositionJointInterface</hardwareInterface>
    <mechanicalReduction>1</mechanicalReduction>
  </actuator>
</transmission>

<!-- Mimic gripper_joint to gripper_left_joint -->
<joint name="gripper_left_joint" type="continuous">
  <origin rpy="0 0.348 0" xyz="-0.016 0.019 0.0487"/>
  <parent link="gripper_base_link"/>
  <child link="gripper_left_driver_link"/>
  <axis xyz="0 1 0"/>
  <mimic joint="gripper_joint" multiplier="-1"/>
</joint>

<transmission name="gripper_left_driver_transmission">
  <type>transmission_interface/SimpleTransmission</type>
  <joint name="gripper_left_joint">
    <hardwareInterface>hardware_interface/PositionJointInterface</hardwareInterface>
  </joint>
  <actuator name="gripper_left_driver_actuator">
    <hardwareInterface>PositionJointInterface</hardwareInterface>
    <mechanicalReduction>1</mechanicalReduction>
  </actuator>
</transmission>

<!-- Use gazebo mimic joint plugin to drive the left joint too -->
<gazebo>
<plugin name="gripper_mimic_joint_plugin" filename="libroboticsgroup_gazebo_mimic_joint_plugin.so">
  <joint>gripper_joint</joint>
  <mimicJoint>gripper_left_joint</mimicJoint>
  <multiplier>-1</multiplier>
</plugin>
</gazebo>


<!-- GRIPPER DEPENDENT JOINTS
Links aren't driven. Set by the gripper parallel linkage.
The <mimic> elements tell ROS how to set the joint values, used for setting the
robot state.
-->

<joint name="gripper_left_contact_dependent_joint" type="continuous">
  <origin rpy="0 -0.348 0" xyz="0.0 -0.0024 0.035"/>
  <parent link="gripper_left_driver_link"/>
  <child link="gripper_left_contact_link"/>
  <axis xyz="0 1 0"/>
  <mimic joint="gripper_joint"/>
</joint>

<joint name="gripper_right_contact_dependent_joint" type="continuous">
  <origin rpy="0 0.348 0" xyz="0.0 -0.0024 0.035"/>
  <parent link="gripper_right_driver_link"/>
  <child link="gripper_right_contact_link"/>
  <axis xyz="0 1 0"/>
  <mimic joint="gripper_joint" multiplier="-1"/>
</joint>

<joint name="gripper_left_linkage_dependent_joint" type="continuous">
  <origin rpy="0 0.348 0" xyz="-0.039616 -0.006 0.0302"/>
  <parent link="gripper_base_link"/>
  <child link="gripper_left_linkage_link"/>
  <axis xyz="0 1 0"/>
  <mimic joint="gripper_joint" multiplier="-1"/>
</joint>

<joint name="gripper_right_linkage_dependent_joint" type="continuous">
  <origin rpy="0 -0.348 0" xyz="0.039616 -0.006 0.0302"/>
  <parent link="gripper_base_link"/>
  <child link="gripper_right_linkage_link"/>
  <axis xyz="0 1 0"/>
  <mimic joint="gripper_joint"/>
</joint>


<!-- GAZEBO GRIPPER LINKAGE
Currently not used, since neither option works particularly well
-->

<!-- OPTION 1: Use mimic joints plugin
Will drive the dependent angles with the correct angles.
Problem: The contact links seem to drift for some reason.
-->

<xacro:macro name="mimic_joint_plugin_gazebo" params="parent_joint mimic_joint multiplier:=1.0">
<plugin name="${mimic_joint}_mimic_joint_plugin" filename="libroboticsgroup_gazebo_mimic_joint_plugin.so">
  <joint>${parent_joint}</joint>
  <mimicJoint>${mimic_joint}</mimicJoint>
  <multiplier>${multiplier}</multiplier>
</plugin>
</xacro:macro>


<!--
<gazebo>
<xacro:mimic_joint_plugin_gazebo
    parent_joint="gripper_left_joint" mimic_joint="gripper_left_contact_dependent_joint"
    multiplier="-1.0"/>

<xacro:mimic_joint_plugin_gazebo
    parent_joint="gripper_right_joint" mimic_joint="gripper_right_contact_dependent_joint"
    multiplier="-1.0"/>

<xacro:mimic_joint_plugin_gazebo
    parent_joint="gripper_left_joint" mimic_joint="gripper_left_linkage_dependent_joint"
    multiplier="1.0"/>

<xacro:mimic_joint_plugin_gazebo
    parent_joint="gripper_right_joint" mimic_joint="gripper_right_linkage_dependent_joint"
    multiplier="1.0"/>
</gazebo>
-->


<!-- OPTION 2: Add joints to close the parallel linkages
Can't include these in the standard model, since ROS doesn't support parallel linkages.
However, Gazebo implements joints as a list of constraints that must be satisfied,
so you can add whatever joints you want.
Problem: Can close the parallel linkage, but doesn't respond to angle
commands and just stays stuck or becomes unstable.
-->

<!--
<gazebo>

<joint name='gripper_left_linkage_dependent_joint2' type='revolute'>
  <pose>-0.0235 -0.0225 -0.0185 0 0 0</pose>
  <child>gripper_left_contact_link</child>
  <parent>gripper_left_linkage_link</parent>
  <axis>
    <xyz>-4e-06 1 -4e-06</xyz>
    <limit>
      <lower>-1e+16</lower>
      <upper>1e+16</upper>
    </limit>
    <dynamics>
      <spring_reference>0</spring_reference>
      <spring_stiffness>0</spring_stiffness>
    </dynamics>
    <use_parent_model_frame>1</use_parent_model_frame>
  </axis>
</joint>

<joint name='gripper_right_linkage_dependent_joint2' type='revolute'>
  <pose>0.0235 -0.0225 -0.0185 0 0 0</pose>
  <child>gripper_right_contact_link</child>
  <parent>gripper_right_linkage_link</parent>
  <axis>
    <xyz>-4e-06 1 -4e-06</xyz>
    <limit>
      <lower>-1e+16</lower>
      <upper>1e+16</upper>
    </limit>
    <dynamics>
      <spring_reference>0</spring_reference>
      <spring_stiffness>0</spring_stiffness>
    </dynamics>
    <use_parent_model_frame>1</use_parent_model_frame>
  </axis>
</joint>

</gazebo>
-->

</to_include>
