<?xml version='1.0'?>
<to_include xmlns:xacro="https://www.ros.org/wiki/xacro">

<!-- CAMERA LINKS -->

<link name="camera_mount_leg_1_link">
  <inertial>
    <origin rpy="0 0 0" xyz="-0.003687719231986318 0.005710165082249932 -1.3429420225863353e-07"/>
    <mass value="0.011972469965960587"/>
    <inertia ixx="1e-06" ixy="0.0" ixz="-0.0" iyy="0.0" iyz="0.0" izz="1e-06"/>
  </inertial>
  <visual>
    <origin rpy="0 0 0" xyz="-0.037807 -0.048101 -0.262572"/>
    <geometry>
      <mesh filename="package://arbie_description/meshes/camera_mount_leg_1.stl"/>
    </geometry>
    <material name="camera"/>
  </visual>
  <collision>
    <origin rpy="0 0 0" xyz="-0.037807 -0.048101 -0.262572"/>
    <geometry>
      <mesh filename="package://arbie_description/meshes/camera_mount_leg_1.stl"/>
    </geometry>
  </collision>
</link>

<link name="camera_mount_leg_2_link">
  <inertial>
    <origin rpy="0 0 0" xyz="0.0036876320544024996 0.005710165082249995 -1.3429420259170044e-07"/>
    <mass value="0.011972469965960601"/>
    <inertia ixx="1e-06" ixy="-0.0" ixz="0.0" iyy="0.0" iyz="-0.0" izz="1e-06"/>
  </inertial>
  <visual>
    <origin rpy="0 0 0" xyz="0.039194 -0.048101 -0.262572"/>
    <geometry>
      <mesh filename="package://arbie_description/meshes/camera_mount_leg_2.stl"/>
    </geometry>
    <material name="camera"/>
  </visual>
  <collision>
    <origin rpy="0 0 0" xyz="0.039194 -0.048101 -0.262572"/>
    <geometry>
      <mesh filename="package://arbie_description/meshes/camera_mount_leg_2.stl"/>
    </geometry>
  </collision>
</link>

<link name="camera_mount_link">
  <inertial>
    <origin rpy="0 0 0" xyz="-0.03446385172095636 0.0015631569649731947 0.008958079682170272"/>
    <mass value="0.10512980225278633"/>
    <inertia ixx="1.6e-05" ixy="-2e-06" ixz="1e-06" iyy="5.6e-05" iyz="3e-06" izz="5.4e-05"/>
  </inertial>
  <visual>
    <origin rpy="0 0 0" xyz="-0.033807 -0.073851 -0.262572"/>
    <geometry>
      <mesh filename="package://arbie_description/meshes/camera_mount.stl"/>
    </geometry>
    <material name="camera"/>
  </visual>
  <collision>
    <origin rpy="0 0 0" xyz="-0.033807 -0.073851 -0.262572"/>
    <geometry>
      <mesh filename="package://arbie_description/meshes/camera_mount.stl"/>
    </geometry>
  </collision>
</link>

<!-- RIGID JOINTS -->

<joint name="rigid_body_to_camera_mount_leg_1_joint" type="fixed">
  <origin rpy="0 0 0" xyz="0.037807 0.048101 0.262572"/>
  <parent link="body_link"/>
  <child link="camera_mount_leg_1_link"/>
</joint>

<joint name="rigid_body_to_camera_mount_leg_2_joint" type="fixed">
  <origin rpy="0 0 0" xyz="-0.039194 0.048101 0.262572"/>
  <parent link="body_link"/>
  <child link="camera_mount_leg_2_link"/>
</joint>


<!-- CAMERA MOUNT JOINT -->

<joint name="camera_tilt_joint" type="continuous">
  <origin rpy="0 0 0" xyz="0 -0.01 0"/>
  <parent link="camera_mount_link"/>
  <child link="camera_mount_aligned_frame"/>
  <axis xyz="1 0 0"/>
</joint>

<link name="camera_mount_aligned_frame"/>
<joint name="camera_mount_aligned_frame_to_base_joint" type="fixed">
  <origin rpy="${-pi/2} ${-pi/2} 0" xyz="-0.034 -0.139 -0.2725"/>
  <parent link="camera_mount_aligned_frame"/>
  <child link="base_link"/>
</joint>

<transmission name="camera_mount_transmission">
  <type>transmission_interface/SimpleTransmission</type>
  <joint name="camera_tilt_joint">
    <hardwareInterface>hardware_interface/PositionJointInterface</hardwareInterface>
  </joint>
  <actuator name="camera_mount_actuator">
    <hardwareInterface>PositionJointInterface</hardwareInterface>
    <mechanicalReduction>1</mechanicalReduction>
  </actuator>
</transmission>

<!-- CAMERA SENSORS AND PLUGINS  -->

<xacro:include filename="$(find realsense_ros_gazebo)/xacro/depthcam.xacro"/>
<xacro:realsense_d435 sensor_name="d400" parent_link="camera_mount_link" rate="50">
  <origin rpy="${-pi/2} ${-pi/2} 0" xyz="-0.0345 0.004 0.011"/>
</xacro:realsense_d435>

<xacro:include filename="$(find realsense_ros_gazebo)/xacro/tracker.xacro"/>
<xacro:realsense_T265 sensor_name="t265" rate="50">
  <origin rpy="${-pi/2} ${-pi/2} 0" xyz="-0.044 -0.0135 0.02"/>
</xacro:realsense_T265>

<joint name="t265_to_camera_mount_fixed_joint" type="fixed">
  <parent link="t265_link"/>
  <child link="camera_mount_link"/>
  <origin rpy="${pi/2} 0 ${pi/2}" xyz="-0.02 0.044 0.0135"/>
</joint>

</to_include>
