<?xml version="1.0"?>
<to_include xmlns:xacro="http://www.ros.org/wiki/xacro">

<!-- EQUIVALENT WHEELS FOR TRACKS - USED TO CALCULATE VELOCITY COMMANDS -->

<xacro:include filename="wheel.urdf.xacro"/>
<xacro:wheel name="tracks_right_wheel_link" radius="0.12" length="0.04" mass="0.5"/>
<xacro:wheel name="tracks_left_wheel_link" radius="0.12" length="0.04" mass="0.5"/>

<!-- TRACK WHEEL JOINTS -->

<joint name="tracks_right_joint" type="continuous">
  <origin rpy="0 0 0" xyz="-0.025 0.005 0.1"/>
  <parent link="tracks_right_link"/>
  <child link="tracks_right_wheel_link"/>
  <axis xyz="1 0 0"/>
</joint>

<joint name="tracks_left_joint" type="continuous">
  <origin rpy="0 0 0" xyz="0.025 0.005 0.1"/>
  <parent link="tracks_left_link"/>
  <child link="tracks_left_wheel_link"/>
  <axis xyz="1 0 0"/>
</joint>

<transmission name="tracks_right_transmission">
  <type>transmission_interface/SimpleTransmission</type>
  <joint name="tracks_right_joint">
    <hardwareInterface>hardware_interface/VelocityJointInterface</hardwareInterface>
  </joint>
  <actuator name="tracks_right_actuator">
    <hardwareInterface>VelocityJointInterface</hardwareInterface>
    <mechanicalReduction>1</mechanicalReduction>
  </actuator>
</transmission>

<transmission name="tracks_left_transmission">
  <type>transmission_interface/SimpleTransmission</type>
  <joint name="tracks_left_joint">
    <hardwareInterface>hardware_interface/VelocityJointInterface</hardwareInterface>
  </joint>
  <actuator name="tracks_left_actuator">
    <hardwareInterface>VelocityJointInterface</hardwareInterface>
    <mechanicalReduction>1</mechanicalReduction>
  </actuator>
</transmission>

<!-- BALL -->

<link name="ball_link">
<visual>
    <geometry>
        <sphere radius="0.05"/>
    </geometry>
    <material name="wheel"/>
</visual>
<collision>
    <geometry>
        <sphere radius="0.05"/>
    </geometry>
</collision>
<inertial>
    <mass value="1"/>
    <inertia
        ixx="0.001"
        iyy="0.001"
        izz="0.001"
        ixy="0" ixz="0" iyz="0"
    />
</inertial>
</link>
<gazebo reference="ball_link">
    <mu1>0</mu1>
    <mu2>0</mu2>
</gazebo>

<joint name="rigid_body_to_ball_joint" type="fixed">
  <origin rpy="0 0 0" xyz="0 -0.05 -0.25"/>
  <parent link="body_link"/>
  <child link="ball_link"/>
</joint>

</to_include>
