<?xml version="1.0"?>
<to_include xmlns:xacro="http://www.ros.org/wiki/xacro">

<!-- EQUIVALENT WHEELS FOR TRACKS - USED TO CALCULATE VELOCITY COMMANDS -->

<xacro:include filename="wheel.urdf.xacro"/>
<xacro:wheel name="tracks_right_wheel_link" radius="0.1" length="0.04" mass="0.5"/>
<xacro:wheel name="tracks_left_wheel_link" radius="0.1" length="0.04" mass="0.5"/>

<!-- TRACK WHEEL JOINTS -->

<joint name="tracks_right_joint" type="continuous">
  <origin rpy="0 0 0" xyz="-0.025 0.0 0.0"/>
  <parent link="tracks_right_link"/>
  <child link="tracks_right_wheel_link"/>
  <axis xyz="1 0 0"/>
</joint>

<joint name="tracks_left_joint" type="continuous">
  <origin rpy="0 0 0" xyz="0.025 0.0 0.0"/>
  <parent link="tracks_left_link"/>
  <child link="tracks_left_wheel_link"/>
  <axis xyz="1 0 0"/>
</joint>

<transmission name="tracks_right_transmission">
  <type>transmission_interface/SimpleTransmission</type>
  <joint name="tracks_right_joint">
    <hardwareInterface>hardware_interface/VelocityJointInterface</hardwareInterface>
  </joint>
  <actuator name="tracks_right_actuator">
    <hardwareInterface>VelocityJointInterface</hardwareInterface>
    <mechanicalReduction>1</mechanicalReduction>
  </actuator>
</transmission>

<transmission name="tracks_left_transmission">
  <type>transmission_interface/SimpleTransmission</type>
  <joint name="tracks_left_joint">
    <hardwareInterface>hardware_interface/VelocityJointInterface</hardwareInterface>
  </joint>
  <actuator name="tracks_left_actuator">
    <hardwareInterface>VelocityJointInterface</hardwareInterface>
    <mechanicalReduction>1</mechanicalReduction>
  </actuator>
</transmission>

</to_include>
