<sdf version='1.6'>
  <model name='arbie'>
    <link name='base_link'>
      <pose frame=''>0 0 0 0 -0 0</pose>
      <inertial>
        <pose frame=''>0.033063 -0.020422 0.122414 0 -0 0</pose>
        <mass>226.672</mass>
        <inertia>
          <ixx>2.94158</ixx>
          <ixy>0.000174509</ixy>
          <ixz>0.0307777</ixz>
          <iyy>6.58602</iyy>
          <iyz>-4.96569e-05</iyz>
          <izz>8.32208</izz>
        </inertia>
      </inertial>
      <collision name='base_link_fixed_joint_lump__main_body_collision'>
        <pose frame=''>-0.105 -0.17 0.15 1.57075 -0 0</pose>
        <geometry>
          <mesh>
            <scale>1 1 1</scale>
            <uri>file:/../arbie_description/meshes/base_link_m-binary.stl</uri>
          </mesh>
        </geometry>
      </collision>
      <collision name='base_link_fixed_joint_lump__right_belt_1_collision_1'>
        <pose frame=''>-0.105 -0.17 0.15 1.57075 -0 0</pose>
        <geometry>
          <mesh>
            <scale>1 1 1</scale>
            <uri>file:/../arbie_description/meshes/right_belt_1_m-binary.stl</uri>
          </mesh>
        </geometry>
      </collision>
      <collision name='base_link_fixed_joint_lump__left_belt_1_collision_2'>
        <pose frame=''>-0.105 -0.17 0.15 1.57075 -0 0</pose>
        <geometry>
          <mesh>
            <scale>1 1 1</scale>
            <uri>file:/../arbie_description/meshes/left_belt_1_m-binary.stl</uri>
          </mesh>
        </geometry>
      </collision>
      <visual name='base_link_fixed_joint_lump__main_body_visual'>
        <pose frame=''>-0.105 -0.17 0.15 1.57075 -0 0</pose>
        <geometry>
          <mesh>
            <scale>1 1 1</scale>
            <uri>file:/../arbie_description/meshes/base_link_m-binary.stl</uri>
          </mesh>
        </geometry>
      </visual>
      <visual name='base_link_fixed_joint_lump__right_belt_1_visual_1'>
        <pose frame=''>-0.105 -0.17 0.15 1.57075 -0 0</pose>
        <geometry>
          <mesh>
            <scale>1 1 1</scale>
            <uri>file:/../arbie_description/meshes/right_belt_1_m-binary.stl</uri>
          </mesh>
        </geometry>
      </visual>
      <visual name='base_link_fixed_joint_lump__left_belt_1_visual_2'>
        <pose frame=''>-0.105 -0.17 0.15 1.57075 -0 0</pose>
        <geometry>
          <mesh>
            <scale>1 1 1</scale>
            <uri>file:/../arbie_description/meshes/left_belt_1_m-binary.stl</uri>
          </mesh>
        </geometry>
      </visual>
    </link>
    <link name='flipper_front_right_1'>
      <pose frame=''>0.261824 -0.184178 0.117324 1.57075 -0 0</pose>
      <inertial>
        <pose frame=''>0 0.063279 -0.163751 0 -0 0</pose>
        <mass>23.2784</mass>
        <inertia>
          <ixx>0.928632</ixx>
          <ixy>-1.05879e-22</ixy>
          <ixz>2.57909e-15</ixz>
          <iyy>0.807634</iyy>
          <iyz>1.66533e-16</iyz>
          <izz>0.19851</izz>
        </inertia>
      </inertial>
      <collision name='flipper_front_right_1_collision'>
        <pose frame=''>-0.366824 0.032677 -0.014176 0 -0 0</pose>
        <geometry>
          <mesh>
            <scale>1 1 1</scale>
            <uri>file:/../arbie_description/meshes/flipper_front_right_1_m-binary.stl</uri>
          </mesh>
        </geometry>
      </collision>
      <collision name='flipper_front_right_1_fixed_joint_lump__flipper_front_left_1_collision_1'>
        <pose frame=''>-0.366824 0.032677 -0.014176 0 -0 0</pose>
        <geometry>
          <mesh>
            <scale>1 1 1</scale>
            <uri>file:/../arbie_description/meshes/flipper_front_left_1_m-binary.stl</uri>
          </mesh>
        </geometry>
      </collision>
      <visual name='flipper_front_right_1_visual'>
        <pose frame=''>-0.366824 0.032677 -0.014176 0 -0 0</pose>
        <geometry>
          <mesh>
            <scale>1 1 1</scale>
            <uri>file:/../arbie_description/meshes/flipper_front_right_1_m-binary.stl</uri>
          </mesh>
        </geometry>
      </visual>
      <visual name='flipper_front_right_1_fixed_joint_lump__flipper_front_left_1_visual_1'>
        <pose frame=''>-0.366824 0.032677 -0.014176 0 -0 0</pose>
        <geometry>
          <mesh>
            <scale>1 1 1</scale>
            <uri>file:/../arbie_description/meshes/flipper_front_left_1_m-binary.stl</uri>
          </mesh>
        </geometry>
      </visual>
    </link>
    <joint name='flippers_front' type='revolute'>
      <child>flipper_front_right_1</child>
      <parent>base_link</parent>
      <axis>
        <xyz>0 -0.01 0</xyz>
        <limit>
          <lower>-3.31613</lower>
          <upper>1.5708</upper>
          <effort>100</effort>
          <velocity>100</velocity>
        </limit>
        <dynamics>
          <spring_reference>0</spring_reference>
          <spring_stiffness>0</spring_stiffness>
        </dynamics>
        <use_parent_model_frame>1</use_parent_model_frame>
      </axis>
    </joint>
    <link name='flipper_rear_right_1'>
      <pose frame=''>-0.193054 -0.184178 0.117324 1.57075 -0 0</pose>
      <inertial>
        <pose frame=''>0 0.063279 -0.163751 0 -0 0</pose>
        <mass>23.2784</mass>
        <inertia>
          <ixx>0.928632</ixx>
          <ixy>-2.11758e-22</ixy>
          <ixz>1.90501e-15</ixz>
          <iyy>0.807634</iyy>
          <iyz>-5.55112e-17</iyz>
          <izz>0.19851</izz>
        </inertia>
      </inertial>
      <collision name='flipper_rear_right_1_collision'>
        <pose frame=''>0.088054 0.032677 -0.014176 0 -0 0</pose>
        <geometry>
          <mesh>
            <scale>1 1 1</scale>
            <uri>file:/../arbie_description/meshes/flipper_rear_right_1_m-binary.stl</uri>
          </mesh>
        </geometry>
      </collision>
      <collision name='flipper_rear_right_1_fixed_joint_lump__flipper_rear_left_1_collision_1'>
        <pose frame=''>0.088054 0.032677 -0.014176 0 -0 0</pose>
        <geometry>
          <mesh>
            <scale>1 1 1</scale>
            <uri>file:/../arbie_description/meshes/flipper_rear_left_1_m-binary.stl</uri>
          </mesh>
        </geometry>
      </collision>
      <visual name='flipper_rear_right_1_visual'>
        <pose frame=''>0.088054 0.032677 -0.014176 0 -0 0</pose>
        <geometry>
          <mesh>
            <scale>1 1 1</scale>
            <uri>file:/../arbie_description/meshes/flipper_rear_right_1_m-binary.stl</uri>
          </mesh>
        </geometry>
      </visual>
      <visual name='flipper_rear_right_1_fixed_joint_lump__flipper_rear_left_1_visual_1'>
        <pose frame=''>0.088054 0.032677 -0.014176 0 -0 0</pose>
        <geometry>
          <mesh>
            <scale>1 1 1</scale>
            <uri>file:/../arbie_description/meshes/flipper_rear_left_1_m-binary.stl</uri>
          </mesh>
        </geometry>
      </visual>
    </link>
    <joint name='flippers_rear' type='revolute'>
      <child>flipper_rear_right_1</child>
      <parent>base_link</parent>
      <axis>
        <xyz>0 -0.01 0</xyz>
        <limit>
          <lower>-1.5708</lower>
          <upper>3.31613</upper>
          <effort>100</effort>
          <velocity>100</velocity>
        </limit>
        <dynamics>
          <spring_reference>0</spring_reference>
          <spring_stiffness>0</spring_stiffness>
        </dynamics>
        <use_parent_model_frame>1</use_parent_model_frame>
      </axis>
    </joint>
    <link name='track_right'>
      <pose frame=''>0.026946 -0.189179 0.077324 1.57075 -0 0</pose>
      <inertial>
        <pose frame=''>0 0 0 0 -0 0</pose>
        <mass>1</mass>
        <inertia>
          <ixx>0.01</ixx>
          <ixy>0</ixy>
          <ixz>0</ixz>
          <iyy>0.01</iyy>
          <iyz>0</iyz>
          <izz>0.04</izz>
        </inertia>
      </inertial>
      <collision name='track_right_collision'>
        <pose frame=''>0 0 -0.04 0 -0 0</pose>
        <geometry>
          <cylinder>
            <length>0.08</length>
            <radius>0.1</radius>
          </cylinder>
        </geometry>
      </collision>
      <visual name='track_right_visual'>
        <pose frame=''>0 0 -0.04 0 -0 0</pose>
        <geometry>
          <cylinder>
            <length>0.08</length>
            <radius>0.1</radius>
          </cylinder>
        </geometry>
      </visual>
      <visual name='track_right_visual_1'>
        <pose frame=''>0 0.05 -0.04 0 -0 0</pose>
        <geometry>
          <cylinder>
            <length>0.09</length>
            <radius>0.025</radius>
          </cylinder>
        </geometry>
      </visual>
    </link>
    <joint name='track_right' type='revolute'>
      <child>track_right</child>
      <parent>base_link</parent>
      <axis>
        <xyz>0 1 -4.6e-05</xyz>
        <limit>
          <lower>-1.5708</lower>
          <upper>3.31613</upper>
          <effort>100</effort>
          <velocity>100</velocity>
        </limit>
        <dynamics>
          <spring_reference>0</spring_reference>
          <spring_stiffness>0</spring_stiffness>
        </dynamics>
        <use_parent_model_frame>1</use_parent_model_frame>
      </axis>
    </joint>
    <link name='track_left'>
      <pose frame=''>0.026946 0.148322 0.077308 1.57075 -0 0</pose>
      <inertial>
        <pose frame=''>0 0 0 0 -0 0</pose>
        <mass>1</mass>
        <inertia>
          <ixx>0.01</ixx>
          <ixy>0</ixy>
          <ixz>0</ixz>
          <iyy>0.01</iyy>
          <iyz>0</iyz>
          <izz>0.04</izz>
        </inertia>
      </inertial>
      <collision name='track_left_collision'>
        <pose frame=''>0 0 0.04 0 -0 0</pose>
        <geometry>
          <cylinder>
            <length>0.08</length>
            <radius>0.1</radius>
          </cylinder>
        </geometry>
      </collision>
      <visual name='track_left_visual'>
        <pose frame=''>0 0 0.04 0 -0 0</pose>
        <geometry>
          <cylinder>
            <length>0.08</length>
            <radius>0.1</radius>
          </cylinder>
        </geometry>
      </visual>
      <visual name='track_left_visual_1'>
        <pose frame=''>0 0.05 0.04 0 -0 0</pose>
        <geometry>
          <cylinder>
            <length>0.09</length>
            <radius>0.025</radius>
          </cylinder>
        </geometry>
      </visual>
    </link>
    <joint name='track_left' type='revolute'>
      <child>track_left</child>
      <parent>base_link</parent>
      <axis>
        <xyz>0 1 -4.6e-05</xyz>
        <limit>
          <lower>-1.5708</lower>
          <upper>3.31613</upper>
          <effort>100</effort>
          <velocity>100</velocity>
        </limit>
        <dynamics>
          <spring_reference>0</spring_reference>
          <spring_stiffness>0</spring_stiffness>
        </dynamics>
        <use_parent_model_frame>1</use_parent_model_frame>
      </axis>
    </joint>
    <link name='arm_base_1'>
      <pose frame=''>0.241824 -0.020423 0.194816 1.57075 -0 0</pose>
      <inertial>
        <pose frame=''>0.001525 0.036972 -0.009123 0 -0 0</pose>
        <mass>9.31867</mass>
        <inertia>
          <ixx>0.020384</ixx>
          <ixy>-0.000132</ixy>
          <ixz>-0.000105</ixz>
          <iyy>0.026478</iyy>
          <iyz>-4.7e-05</iyz>
          <izz>0.017031</izz>
        </inertia>
      </inertial>
      <collision name='arm_base_1_collision'>
        <pose frame=''>-0.346824 -0.044823 0.149575 0 -0 0</pose>
        <geometry>
          <mesh>
            <scale>1 1 1</scale>
            <uri>file:/../arbie_description/meshes/arm_base_1_m-binary.stl</uri>
          </mesh>
        </geometry>
      </collision>
      <visual name='arm_base_1_visual'>
        <pose frame=''>-0.346824 -0.044823 0.149575 0 -0 0</pose>
        <geometry>
          <mesh>
            <scale>1 1 1</scale>
            <uri>file:/../arbie_description/meshes/arm_base_1_m-binary.stl</uri>
          </mesh>
        </geometry>
      </visual>
    </link>
    <joint name='arm1' type='revolute'>
      <child>arm_base_1</child>
      <parent>base_link</parent>
      <axis>
        <xyz>0 -0 -0.01</xyz>
        <limit>
          <lower>-2.35619</lower>
          <upper>2.35619</upper>
          <effort>100</effort>
          <velocity>100</velocity>
        </limit>
        <dynamics>
          <spring_reference>0</spring_reference>
          <spring_stiffness>0</spring_stiffness>
        </dynamics>
        <use_parent_model_frame>1</use_parent_model_frame>
      </axis>
    </joint>
    <link name='arm_lower_1'>
      <pose frame=''>0.227393 -0.014419 0.283009 1.57075 -0 0</pose>
      <inertial>
        <pose frame=''>-0.33515 0.004913 0.01284 0 -0 0</pose>
        <mass>3.21199</mass>
        <inertia>
          <ixx>0.004374</ixx>
          <ixy>0.00084</ixy>
          <ixz>0.000477</ixz>
          <iyy>0.029637</iyy>
          <iyz>0.000198</iyz>
          <izz>0.026449</izz>
        </inertia>
      </inertial>
      <collision name='arm_lower_1_collision'>
        <pose frame=''>-0.332393 -0.133016 0.155575 0 -0 0</pose>
        <geometry>
          <mesh>
            <scale>1 1 1</scale>
            <uri>file:/../arbie_description/meshes/arm_lower_1_m-binary.stl</uri>
          </mesh>
        </geometry>
      </collision>
      <visual name='arm_lower_1_visual'>
        <pose frame=''>-0.332393 -0.133016 0.155575 0 -0 0</pose>
        <geometry>
          <mesh>
            <scale>1 1 1</scale>
            <uri>file:/../arbie_description/meshes/arm_lower_1_m-binary.stl</uri>
          </mesh>
        </geometry>
      </visual>
    </link>
    <joint name='arm2' type='revolute'>
      <child>arm_lower_1</child>
      <parent>arm_base_1</parent>
      <axis>
        <xyz>0 -0.01 0</xyz>
        <limit>
          <lower>-3.14159</lower>
          <upper>0</upper>
          <effort>100</effort>
          <velocity>100</velocity>
        </limit>
        <dynamics>
          <spring_reference>0</spring_reference>
          <spring_stiffness>0</spring_stiffness>
        </dynamics>
        <use_parent_model_frame>1</use_parent_model_frame>
      </axis>
    </joint>
    <link name='arm_upper_1'>
      <pose frame=''>-0.17063 -0.014417 0.322832 1.57075 -0 0</pose>
      <inertial>
        <pose frame=''>0.224512 1.3e-05 0.006 0 -0 0</pose>
        <mass>1.11702</mass>
        <inertia>
          <ixx>0.000146</ixx>
          <ixy>0</ixy>
          <ixz>-0</ixz>
          <iyy>0.010141</iyy>
          <iyz>0</iyz>
          <izz>0.01012</izz>
        </inertia>
      </inertial>
      <collision name='arm_upper_1_collision'>
        <pose frame=''>0.06563 -0.172839 0.155575 0 -0 0</pose>
        <geometry>
          <mesh>
            <scale>1 1 1</scale>
            <uri>file:/../arbie_description/meshes/arm_upper_1_m-binary.stl</uri>
          </mesh>
        </geometry>
      </collision>
      <visual name='arm_upper_1_visual'>
        <pose frame=''>0.06563 -0.172839 0.155575 0 -0 0</pose>
        <geometry>
          <mesh>
            <scale>1 1 1</scale>
            <uri>file:/../arbie_description/meshes/arm_upper_1_m-binary.stl</uri>
          </mesh>
        </geometry>
      </visual>
    </link>
    <joint name='arm3' type='revolute'>
      <child>arm_upper_1</child>
      <parent>arm_lower_1</parent>
      <axis>
        <xyz>0 -0.01 0</xyz>
        <limit>
          <lower>0</lower>
          <upper>3.14159</upper>
          <effort>100</effort>
          <velocity>100</velocity>
        </limit>
        <dynamics>
          <spring_reference>0</spring_reference>
          <spring_stiffness>0</spring_stiffness>
        </dynamics>
        <use_parent_model_frame>1</use_parent_model_frame>
      </axis>
    </joint>
    <link name='wrist_yaw_1'>
      <pose frame=''>0.14505 -0.001417 0.322873 1.57075 -0 0</pose>
      <inertial>
        <pose frame=''>0.044416 4.6e-05 0.019 0 -0 0</pose>
        <mass>0.509786</mass>
        <inertia>
          <ixx>0.000112</ixx>
          <ixy>-0</ixy>
          <ixz>-0</ixz>
          <iyy>0.000264</iyy>
          <iyz>0</iyz>
          <izz>0.000208</izz>
        </inertia>
      </inertial>
      <collision name='wrist_yaw_1_collision'>
        <pose frame=''>-0.25005 -0.172881 0.168575 0 -0 0</pose>
        <geometry>
          <mesh>
            <scale>1 1 1</scale>
            <uri>file:/../arbie_description/meshes/wrist_yaw_1_m-binary.stl</uri>
          </mesh>
        </geometry>
      </collision>
      <visual name='wrist_yaw_1_visual'>
        <pose frame=''>-0.25005 -0.172881 0.168575 0 -0 0</pose>
        <geometry>
          <mesh>
            <scale>1 1 1</scale>
            <uri>file:/../arbie_description/meshes/wrist_yaw_1_m-binary.stl</uri>
          </mesh>
        </geometry>
      </visual>
    </link>
    <joint name='wrist1' type='revolute'>
      <child>wrist_yaw_1</child>
      <parent>arm_upper_1</parent>
      <axis>
        <xyz>0 -0.01 0</xyz>
        <limit>
          <lower>-1e+16</lower>
          <upper>1e+16</upper>
        </limit>
        <dynamics>
          <spring_reference>0</spring_reference>
          <spring_stiffness>0</spring_stiffness>
        </dynamics>
        <use_parent_model_frame>1</use_parent_model_frame>
      </axis>
    </joint>
    <link name='wrist_pitch_1'>
      <pose frame=''>0.201585 -0.020416 0.337433 1.57075 -0 0</pose>
      <inertial>
        <pose frame=''>0.037374 -0.006111 0 0 -0 0</pose>
        <mass>0.393417</mass>
        <inertia>
          <ixx>0.000118</ixx>
          <ixy>-1.1e-05</ixy>
          <ixz>-0</ixz>
          <iyy>9.8e-05</iyy>
          <iyz>0</iyz>
          <izz>0.000176</izz>
        </inertia>
      </inertial>
      <collision name='wrist_pitch_1_collision'>
        <pose frame=''>-0.306585 -0.18744 0.149575 0 -0 0</pose>
        <geometry>
          <mesh>
            <scale>1 1 1</scale>
            <uri>file:/../arbie_description/meshes/wrist_pitch_1_m-binary.stl</uri>
          </mesh>
        </geometry>
      </collision>
      <visual name='wrist_pitch_1_visual'>
        <pose frame=''>-0.306585 -0.18744 0.149575 0 -0 0</pose>
        <geometry>
          <mesh>
            <scale>1 1 1</scale>
            <uri>file:/../arbie_description/meshes/wrist_pitch_1_m-binary.stl</uri>
          </mesh>
        </geometry>
      </visual>
    </link>
    <joint name='wrist2' type='revolute'>
      <child>wrist_pitch_1</child>
      <parent>wrist_yaw_1</parent>
      <axis>
        <xyz>1e-05 -0 -0.01</xyz>
        <limit>
          <lower>-1e+16</lower>
          <upper>1e+16</upper>
        </limit>
        <dynamics>
          <spring_reference>0</spring_reference>
          <spring_stiffness>0</spring_stiffness>
        </dynamics>
        <use_parent_model_frame>1</use_parent_model_frame>
      </axis>
    </joint>
    <link name='gripper_1'>
      <pose frame=''>0.2606 -0.020417 0.322995 1.57075 -0 0</pose>
      <inertial>
        <pose frame=''>0.025834 2.7e-05 0 0 -0 0</pose>
        <mass>1.70013</mass>
        <inertia>
          <ixx>0.004444</ixx>
          <ixy>-0</ixy>
          <ixz>-0</ixz>
          <iyy>0.004742</iyy>
          <iyz>-0</iyz>
          <izz>0.001496</izz>
        </inertia>
      </inertial>
      <collision name='gripper_1_collision'>
        <pose frame=''>-0.3656 -0.173002 0.149575 0 -0 0</pose>
        <geometry>
          <mesh>
            <scale>1 1 1</scale>
            <uri>file:/../arbie_description/meshes/gripper_1_m-binary.stl</uri>
          </mesh>
        </geometry>
      </collision>
      <visual name='gripper_1_visual'>
        <pose frame=''>-0.3656 -0.173002 0.149575 0 -0 0</pose>
        <geometry>
          <mesh>
            <scale>1 1 1</scale>
            <uri>file:/../arbie_description/meshes/gripper_1_m-binary.stl</uri>
          </mesh>
        </geometry>
      </visual>
    </link>
    <joint name='wrist3' type='revolute'>
      <child>gripper_1</child>
      <parent>wrist_pitch_1</parent>
      <axis>
        <xyz>0.01 0 1e-05</xyz>
        <limit>
          <lower>-1e+16</lower>
          <upper>1e+16</upper>
        </limit>
        <dynamics>
          <spring_reference>0</spring_reference>
          <spring_stiffness>0</spring_stiffness>
        </dynamics>
        <use_parent_model_frame>1</use_parent_model_frame>
      </axis>
    </joint>
    <static>0</static>
    <plugin name='control' filename='libgazebo_ros_control.so'/>
  </model>
</sdf>
