<?xml version="1.0" ?>
<robot name="Simple-model-Mk.III-v7">
<link name="base_link">
  <inertial>
    <origin rpy="0 0 0" xyz="-0.0007103904794560104 0.04685539726506198 -0.03652499028281223"/>
    <mass value="132.38352048208554"/>
    <inertia ixx="3.87908" ixy="-0.00108" ixz="-0.002599" iyy="4.409886" iyz="0.163573" izz="0.920138"/>
  </inertial>
  <visual>
    <origin rpy="0 0 0" xyz="0 0 0"/>
    <geometry>
      <mesh filename="package://arbie_description/meshes/base_link_m-binary.stl"/>
    </geometry>
    <material name="silver">
      <color rgba="1 0 0 1"/>
    </material>
  </visual>
  <collision>
    <origin rpy="0 0 0" xyz="0 0 0"/>
    <geometry>
      <mesh filename="package://arbie_description/meshes/base_link_m-binary.stl"/>
    </geometry>
  </collision>
</link>
<link name="Tracks_L_1">
  <inertial>
    <origin rpy="0 0 0" xyz="0.02500045641121243 0.00212048907670849 -0.000743015955378042"/>
    <mass value="44.76242127990538"/>
    <inertia ixx="1.472289" ixy="-0.0" ixz="-0.0" iyy="1.350001" iyz="0.000109" izz="0.140939"/>
  </inertial>
  <visual>
    <origin rpy="0 0 0" xyz="-0.123306 -0.019326 0.010978"/>
    <geometry>
      <mesh filename="package://arbie_description/meshes/Tracks_L_1_m-binary.stl"/>
    </geometry>
    <material name="silver">
      <color rgba="1 0 0 1"/>
    </material>
  </visual>
  <collision>
    <origin rpy="0 0 0" xyz="-0.123306 -0.019326 0.010978"/>
    <geometry>
      <mesh filename="package://arbie_description/meshes/Tracks_L_1_m-binary.stl"/>
    </geometry>
  </collision>
</link>
<link name="Tracks_R_1">
  <inertial>
    <origin rpy="0 0 0" xyz="-0.02499954358879042 0.002120489076708521 -0.0007430080149572974"/>
    <mass value="44.76242127990538"/>
    <inertia ixx="1.472289" ixy="-0.0" ixz="-0.0" iyy="1.350001" iyz="0.000109" izz="0.140939"/>
  </inertial>
  <visual>
    <origin rpy="0 0 0" xyz="0.124694 -0.019326 0.010978"/>
    <geometry>
      <mesh filename="package://arbie_description/meshes/Tracks_R_1_m-binary.stl"/>
    </geometry>
    <material name="silver">
      <color rgba="1 0 0 1"/>
    </material>
  </visual>
  <collision>
    <origin rpy="0 0 0" xyz="0.124694 -0.019326 0.010978"/>
    <geometry>
      <mesh filename="package://arbie_description/meshes/Tracks_R_1_m-binary.stl"/>
    </geometry>
  </collision>
</link>
<link name="equivalent_wheel_R_1">
  <inertial>
    <origin rpy="0 0 0" xyz="-0.004999543588790428 2.946488827579308e-07 -1.3146241448734608e-07"/>
    <mass value="1.3872095061007428"/>
    <inertia ixx="0.003902" ixy="-0.0" ixz="-0.0" iyy="0.001962" iyz="-0.0" izz="0.001962"/>
  </inertial>
  <visual>
    <origin rpy="0 0 0" xyz="0.144694 -0.019326 0.010978"/>
    <geometry>
      <mesh filename="package://arbie_description/meshes/equivalent_wheel_R_1_m-binary.stl"/>
    </geometry>
    <material name="silver">
      <color rgba="1 0 0 1"/>
    </material>
  </visual>
  <collision>
    <origin rpy="0 0 0" xyz="0.144694 -0.019326 0.010978"/>
    <geometry>
      <mesh filename="package://arbie_description/meshes/equivalent_wheel_R_1_m-binary.stl"/>
    </geometry>
  </collision>
</link>
<link name="equivalent_wheel_L_1">
  <inertial>
    <origin rpy="0 0 0" xyz="0.005000456411212495 2.9464888271282796e-07 -1.3940283523014574e-07"/>
    <mass value="1.3872095061007428"/>
    <inertia ixx="0.003902" ixy="0.0" ixz="0.0" iyy="0.001962" iyz="0.0" izz="0.001962"/>
  </inertial>
  <visual>
    <origin rpy="0 0 0" xyz="-0.143306 -0.019326 0.010978"/>
    <geometry>
      <mesh filename="package://arbie_description/meshes/equivalent_wheel_L_1_m-binary.stl"/>
    </geometry>
    <material name="silver">
      <color rgba="1 0 0 1"/>
    </material>
  </visual>
  <collision>
    <origin rpy="0 0 0" xyz="-0.143306 -0.019326 0.010978"/>
    <geometry>
      <mesh filename="package://arbie_description/meshes/equivalent_wheel_L_1_m-binary.stl"/>
    </geometry>
  </collision>
</link>
<link name="Leg_1_1">
  <inertial>
    <origin rpy="0 0 0" xyz="-0.003687719231986318 0.005710165082249932 -1.3429420225863353e-07"/>
    <mass value="0.011972469965960587"/>
    <inertia ixx="1e-06" ixy="0.0" ixz="-0.0" iyy="0.0" iyz="0.0" izz="1e-06"/>
  </inertial>
  <visual>
    <origin rpy="0 0 0" xyz="-0.037807 -0.048101 -0.262572"/>
    <geometry>
      <mesh filename="package://arbie_description/meshes/Leg_1_1_m-binary.stl"/>
    </geometry>
    <material name="silver">
      <color rgba="1 0 0 1"/>
    </material>
  </visual>
  <collision>
    <origin rpy="0 0 0" xyz="-0.037807 -0.048101 -0.262572"/>
    <geometry>
      <mesh filename="package://arbie_description/meshes/Leg_1_1_m-binary.stl"/>
    </geometry>
  </collision>
</link>
<link name="Leg_2_1">
  <inertial>
    <origin rpy="0 0 0" xyz="0.0036876320544024996 0.005710165082249995 -1.3429420259170044e-07"/>
    <mass value="0.011972469965960601"/>
    <inertia ixx="1e-06" ixy="-0.0" ixz="0.0" iyy="0.0" iyz="-0.0" izz="1e-06"/>
  </inertial>
  <visual>
    <origin rpy="0 0 0" xyz="0.039194 -0.048101 -0.262572"/>
    <geometry>
      <mesh filename="package://arbie_description/meshes/Leg_2_1_m-binary.stl"/>
    </geometry>
    <material name="silver">
      <color rgba="1 0 0 1"/>
    </material>
  </visual>
  <collision>
    <origin rpy="0 0 0" xyz="0.039194 -0.048101 -0.262572"/>
    <geometry>
      <mesh filename="package://arbie_description/meshes/Leg_2_1_m-binary.stl"/>
    </geometry>
  </collision>
</link>
<link name="Cam_mount_1">
  <inertial>
    <origin rpy="0 0 0" xyz="-0.03446385172095636 0.0015631569649731947 0.008958079682170272"/>
    <mass value="0.10512980225278633"/>
    <inertia ixx="1.6e-05" ixy="-2e-06" ixz="1e-06" iyy="5.6e-05" iyz="3e-06" izz="5.4e-05"/>
  </inertial>
  <visual>
    <origin rpy="0 0 0" xyz="-0.033807 -0.073851 -0.262572"/>
    <geometry>
      <mesh filename="package://arbie_description/meshes/Cam_mount_1_m-binary.stl"/>
    </geometry>
    <material name="silver">
      <color rgba="1 0 0 1"/>
    </material>
  </visual>
  <collision>
    <origin rpy="0 0 0" xyz="-0.033807 -0.073851 -0.262572"/>
    <geometry>
      <mesh filename="package://arbie_description/meshes/Cam_mount_1_m-binary.stl"/>
    </geometry>
  </collision>
</link>
<link name="D435_1">
  <inertial>
    <origin rpy="0 0 0" xyz="-0.019510973805073988 0.09028780766834578 0.300025146597877"/>
    <mass value="0.3380578483539848"/>
    <inertia ixx="3.1e-05" ixy="-0.0" ixz="2e-06" iyy="0.000212" iyz="-0.0" izz="0.000211"/>
  </inertial>
  <visual>
    <origin rpy="0 0 0" xyz="-0.02125 0.0 0.025"/>
    <geometry>
      <mesh filename="package://arbie_description/meshes/D435_1_m-binary.stl"/>
    </geometry>
    <material name="silver">
      <color rgba="1 0 0 1"/>
    </material>
  </visual>
  <collision>
    <origin rpy="0 0 0" xyz="-0.02125 0.0 0.025"/>
    <geometry>
      <mesh filename="package://arbie_description/meshes/D435_1_m-binary.stl"/>
    </geometry>
  </collision>
</link>
<link name="T265_1">
  <inertial>
    <origin rpy="0 0 0" xyz="-0.023753775255487577 1.0333193303339872e-05 0.0048840237534042985"/>
    <mass value="0.11087104010777465"/>
    <inertia ixx="7e-06" ixy="0.0" ixz="-1e-06" iyy="0.000103" iyz="-0.0" izz="0.000108"/>
  </inertial>
  <visual>
    <origin rpy="0 0 0" xyz="-0.016177 -0.060351 -0.276572"/>
    <geometry>
      <mesh filename="package://arbie_description/meshes/T265_1_m-binary.stl"/>
    </geometry>
    <material name="silver">
      <color rgba="1 0 0 1"/>
    </material>
  </visual>
  <collision>
    <origin rpy="0 0 0" xyz="-0.016177 -0.060351 -0.276572"/>
    <geometry>
      <mesh filename="package://arbie_description/meshes/T265_1_m-binary.stl"/>
    </geometry>
  </collision>
</link>
<link name="Flipper_FR_1">
  <inertial>
    <origin rpy="0 0 0" xyz="0.019795020283170317 0.16537558379618636 -1.3146244423611897e-07"/>
    <mass value="13.868020437393694"/>
    <inertia ixx="0.085351" ixy="-0.004876" ixz="0.0" iyy="0.028555" iyz="-0.0" izz="0.07162"/>
  </inertial>
  <visual>
    <origin rpy="0 0 0" xyz="0.174694 -0.024729 -0.219022"/>
    <geometry>
      <mesh filename="package://arbie_description/meshes/Flipper_FR_1_m-binary.stl"/>
    </geometry>
    <material name="silver">
      <color rgba="1 0 0 1"/>
    </material>
  </visual>
  <collision>
    <origin rpy="0 0 0" xyz="0.174694 -0.024729 -0.219022"/>
    <geometry>
      <mesh filename="package://arbie_description/meshes/Flipper_FR_1_m-binary.stl"/>
    </geometry>
  </collision>
</link>
<link name="Flipper_RR_1">
  <inertial>
    <origin rpy="0 0 0" xyz="0.01979502028317115 0.16537558379618683 -1.3146242511252737e-07"/>
    <mass value="13.868020437393698"/>
    <inertia ixx="0.085351" ixy="-0.004876" ixz="0.0" iyy="0.028555" iyz="-0.0" izz="0.07162"/>
  </inertial>
  <visual>
    <origin rpy="0 0 0" xyz="0.174694 -0.024729 0.240978"/>
    <geometry>
      <mesh filename="package://arbie_description/meshes/Flipper_RR_1_m-binary.stl"/>
    </geometry>
    <material name="silver">
      <color rgba="1 0 0 1"/>
    </material>
  </visual>
  <collision>
    <origin rpy="0 0 0" xyz="0.174694 -0.024729 0.240978"/>
    <geometry>
      <mesh filename="package://arbie_description/meshes/Flipper_RR_1_m-binary.stl"/>
    </geometry>
  </collision>
</link>
<link name="Flipper_FL_1">
  <inertial>
    <origin rpy="0 0 0" xyz="-0.019794107460748195 0.16537558379618633 -1.394028636692024e-07"/>
    <mass value="13.868020437393678"/>
    <inertia ixx="0.085351" ixy="0.004876" ixz="-0.0" iyy="0.028555" iyz="-0.0" izz="0.07162"/>
  </inertial>
  <visual>
    <origin rpy="0 0 0" xyz="-0.173306 -0.024729 -0.219022"/>
    <geometry>
      <mesh filename="package://arbie_description/meshes/Flipper_FL_1_m-binary.stl"/>
    </geometry>
    <material name="silver">
      <color rgba="1 0 0 1"/>
    </material>
  </visual>
  <collision>
    <origin rpy="0 0 0" xyz="-0.173306 -0.024729 -0.219022"/>
    <geometry>
      <mesh filename="package://arbie_description/meshes/Flipper_FL_1_m-binary.stl"/>
    </geometry>
  </collision>
</link>
<link name="Flipper_RL_1">
  <inertial>
    <origin rpy="0 0 0" xyz="-0.019794107460749416 0.16537558379618675 -1.394028462664565e-07"/>
    <mass value="13.868020437393671"/>
    <inertia ixx="0.085351" ixy="0.004876" ixz="-0.0" iyy="0.028555" iyz="-0.0" izz="0.07162"/>
  </inertial>
  <visual>
    <origin rpy="0 0 0" xyz="-0.173306 -0.024729 0.240978"/>
    <geometry>
      <mesh filename="package://arbie_description/meshes/Flipper_RL_1_m-binary.stl"/>
    </geometry>
    <material name="silver">
      <color rgba="1 0 0 1"/>
    </material>
  </visual>
  <collision>
    <origin rpy="0 0 0" xyz="-0.173306 -0.024729 0.240978"/>
    <geometry>
      <mesh filename="package://arbie_description/meshes/Flipper_RL_1_m-binary.stl"/>
    </geometry>
  </collision>
</link>
<link name="Arm_rotation_1">
  <inertial>
    <origin rpy="0 0 0" xyz="-0.0016420049931783305 0.023135022831294483 -7.480052882286037e-06"/>
    <mass value="3.3465093478653403"/>
    <inertia ixx="0.005075" ixy="0.000176" ixz="-0.0" iyy="0.010632" iyz="1e-06" izz="0.009087"/>
  </inertial>
  <visual>
    <origin rpy="0 0 0" xyz="0.000694 -0.107101 -0.186272"/>
    <geometry>
      <mesh filename="package://arbie_description/meshes/Arm_rotation_1_m-binary.stl"/>
    </geometry>
    <material name="silver">
      <color rgba="1 0 0 1"/>
    </material>
  </visual>
  <collision>
    <origin rpy="0 0 0" xyz="0.000694 -0.107101 -0.186272"/>
    <geometry>
      <mesh filename="package://arbie_description/meshes/Arm_rotation_1_m-binary.stl"/>
    </geometry>
  </collision>
</link>
<link name="Arm_link_1_1">
  <inertial>
    <origin rpy="0 0 0" xyz="-0.053878611230066 0.007243666919340863 -0.13003163766238773"/>
    <mass value="9.290217371436244"/>
    <inertia ixx="0.285483" ixy="0.000938" ixz="-0.009995" iyy="0.285913" iyz="0.0181" izz="0.011485"/>
  </inertial>
  <visual>
    <origin rpy="0 0 0" xyz="-0.052806 -0.174101 -0.186495"/>
    <geometry>
      <mesh filename="package://arbie_description/meshes/Arm_link_1_1_m-binary.stl"/>
    </geometry>
    <material name="silver">
      <color rgba="1 0 0 1"/>
    </material>
  </visual>
  <collision>
    <origin rpy="0 0 0" xyz="-0.052806 -0.174101 -0.186495"/>
    <geometry>
      <mesh filename="package://arbie_description/meshes/Arm_link_1_1_m-binary.stl"/>
    </geometry>
  </collision>
</link>
<link name="Arm_link_2_1">
  <inertial>
    <origin rpy="0 0 0" xyz="-0.016999544747906395 0.013376208584352511 0.039239753662060034"/>
    <mass value="3.0631873001334227"/>
    <inertia ixx="0.015235" ixy="0.0" ixz="0.0" iyy="0.013273" iyz="-0.002633" izz="0.002494"/>
  </inertial>
  <visual>
    <origin rpy="0 0 0" xyz="-0.019806 -0.209101 0.263505"/>
    <geometry>
      <mesh filename="package://arbie_description/meshes/Arm_link_2_1_m-binary.stl"/>
    </geometry>
    <material name="silver">
      <color rgba="1 0 0 1"/>
    </material>
  </visual>
  <collision>
    <origin rpy="0 0 0" xyz="-0.019806 -0.209101 0.263505"/>
    <geometry>
      <mesh filename="package://arbie_description/meshes/Arm_link_2_1_m-binary.stl"/>
    </geometry>
  </collision>
</link>
<link name="wrist_base_1">
  <inertial>
    <origin rpy="0 0 0" xyz="4.57436623640603e-07 0.00012475245793225342 0.025292868333247724"/>
    <mass value="0.9490572232520995"/>
    <inertia ixx="0.000757" ixy="1e-06" ixz="-0.0" iyy="0.001107" iyz="2e-06" izz="0.000496"/>
  </inertial>
  <visual>
    <origin rpy="0 0 0" xyz="-0.002806 -0.244101 0.038505"/>
    <geometry>
      <mesh filename="package://arbie_description/meshes/wrist_base_1_m-binary.stl"/>
    </geometry>
    <material name="silver">
      <color rgba="1 0 0 1"/>
    </material>
  </visual>
  <collision>
    <origin rpy="0 0 0" xyz="-0.002806 -0.244101 0.038505"/>
    <geometry>
      <mesh filename="package://arbie_description/meshes/wrist_base_1_m-binary.stl"/>
    </geometry>
  </collision>
</link>
<link name="pitch_mount_1">
  <inertial>
    <origin rpy="0 0 0" xyz="-0.0332984740595477 0.0020671950198172806 0.02282064850736746"/>
    <mass value="0.08039663104912372"/>
    <inertia ixx="5.5e-05" ixy="0.0" ixz="0.0" iyy="9.5e-05" iyz="-7e-06" izz="8e-05"/>
  </inertial>
  <visual>
    <origin rpy="0 0 0" xyz="-0.036206 -0.244101 -0.014995"/>
    <geometry>
      <mesh filename="package://arbie_description/meshes/pitch_mount_1_m-binary.stl"/>
    </geometry>
    <material name="silver">
      <color rgba="1 0 0 1"/>
    </material>
  </visual>
  <collision>
    <origin rpy="0 0 0" xyz="-0.036206 -0.244101 -0.014995"/>
    <geometry>
      <mesh filename="package://arbie_description/meshes/pitch_mount_1_m-binary.stl"/>
    </geometry>
  </collision>
</link>
<link name="roll_yaw_servo_1">
  <inertial>
    <origin rpy="0 0 0" xyz="-0.013267784777998575 0.01927575393175185 0.016285676232992735"/>
    <mass value="0.6469480906726006"/>
    <inertia ixx="0.000275" ixy="2e-06" ixz="2e-06" iyy="0.000342" iyz="3e-06" izz="0.000171"/>
  </inertial>
  <visual>
    <origin rpy="0 0 0" xyz="-0.002906 -0.225651 -0.078119"/>
    <geometry>
      <mesh filename="package://arbie_description/meshes/roll_yaw_servo_1_m-binary.stl"/>
    </geometry>
    <material name="silver">
      <color rgba="1 0 0 1"/>
    </material>
  </visual>
  <collision>
    <origin rpy="0 0 0" xyz="-0.002906 -0.225651 -0.078119"/>
    <geometry>
      <mesh filename="package://arbie_description/meshes/roll_yaw_servo_1_m-binary.stl"/>
    </geometry>
  </collision>
</link>
<link name="gripper_mount_1">
  <inertial>
    <origin rpy="0 0 0" xyz="-4.607760189011137e-05 -0.0006917471996047975 0.03460710409065769"/>
    <mass value="0.6706735500880907"/>
    <inertia ixx="0.000199" ixy="0.0" ixz="0.0" iyy="0.000353" iyz="-3e-06" izz="0.000284"/>
  </inertial>
  <visual>
    <origin rpy="0 0 0" xyz="-0.002906 -0.244651 -0.123519"/>
    <geometry>
      <mesh filename="package://arbie_description/meshes/gripper_mount_1_m-binary.stl"/>
    </geometry>
    <material name="silver">
      <color rgba="1 0 0 1"/>
    </material>
  </visual>
  <collision>
    <origin rpy="0 0 0" xyz="-0.002906 -0.244651 -0.123519"/>
    <geometry>
      <mesh filename="package://arbie_description/meshes/gripper_mount_1_m-binary.stl"/>
    </geometry>
  </collision>
</link>
<link name="r_link1_1">
  <inertial>
    <origin rpy="0 0 0" xyz="4.537220775792383e-07 -0.03094002747411953 0.004350576193156569"/>
    <mass value="0.01374798583124482"/>
    <inertia ixx="5e-06" ixy="-0.0" ixz="0.0" iyy="2e-06" iyz="-1e-06" izz="4e-06"/>
  </inertial>
  <visual>
    <origin rpy="0 0 0" xyz="-0.018906 -0.263651 -0.172219"/>
    <geometry>
      <mesh filename="package://arbie_description/meshes/r_link1_1_m-binary.stl"/>
    </geometry>
    <material name="silver">
      <color rgba="1 0 0 1"/>
    </material>
  </visual>
  <collision>
    <origin rpy="0 0 0" xyz="-0.018906 -0.263651 -0.172219"/>
    <geometry>
      <mesh filename="package://arbie_description/meshes/r_link1_1_m-binary.stl"/>
    </geometry>
  </collision>
</link>
<link name="l_link1_1">
  <inertial>
    <origin rpy="0 0 0" xyz="4.552690735497994e-07 -0.030940033304886344 0.004350583148282683"/>
    <mass value="0.013747989643093032"/>
    <inertia ixx="5e-06" ixy="0.0" ixz="0.0" iyy="2e-06" iyz="-1e-06" izz="4e-06"/>
  </inertial>
  <visual>
    <origin rpy="0 0 0" xyz="0.013094 -0.263651 -0.172219"/>
    <geometry>
      <mesh filename="package://arbie_description/meshes/l_link1_1_m-binary.stl"/>
    </geometry>
    <material name="silver">
      <color rgba="1 0 0 1"/>
    </material>
  </visual>
  <collision>
    <origin rpy="0 0 0" xyz="0.013094 -0.263651 -0.172219"/>
    <geometry>
      <mesh filename="package://arbie_description/meshes/l_link1_1_m-binary.stl"/>
    </geometry>
  </collision>
</link>
<link name="l_finger_1">
  <inertial>
    <origin rpy="0 0 0" xyz="-0.0049669191825520796 -0.01899661466926142 0.016466890477460527"/>
    <mass value="0.023712538812289255"/>
    <inertia ixx="7e-06" ixy="-1e-06" ixz="-2e-06" iyy="7e-06" iyz="-1e-06" izz="4e-06"/>
  </inertial>
  <visual>
    <origin rpy="0 0 0" xyz="0.013094 -0.261251 -0.207219"/>
    <geometry>
      <mesh filename="package://arbie_description/meshes/l_finger_1_m-binary.stl"/>
    </geometry>
    <material name="silver">
      <color rgba="1 0 0 1"/>
    </material>
  </visual>
  <collision>
    <origin rpy="0 0 0" xyz="0.013094 -0.261251 -0.207219"/>
    <geometry>
      <mesh filename="package://arbie_description/meshes/l_finger_1_m-binary.stl"/>
    </geometry>
  </collision>
</link>
<link name="r_finger_1">
  <inertial>
    <origin rpy="0 0 0" xyz="0.004967829686739981 -0.01899661466926142 0.016466890477460472"/>
    <mass value="0.023712538812289255"/>
    <inertia ixx="7e-06" ixy="1e-06" ixz="2e-06" iyy="7e-06" iyz="-1e-06" izz="4e-06"/>
  </inertial>
  <visual>
    <origin rpy="0 0 0" xyz="-0.018906 -0.261251 -0.207219"/>
    <geometry>
      <mesh filename="package://arbie_description/meshes/r_finger_1_m-binary.stl"/>
    </geometry>
    <material name="silver">
      <color rgba="1 0 0 1"/>
    </material>
  </visual>
  <collision>
    <origin rpy="0 0 0" xyz="-0.018906 -0.261251 -0.207219"/>
    <geometry>
      <mesh filename="package://arbie_description/meshes/r_finger_1_m-binary.stl"/>
    </geometry>
  </collision>
</link>
<link name="l_link2_1">
  <inertial>
    <origin rpy="0 0 0" xyz="-0.005348977862044579 0.00500022075444323 0.01750042810563407"/>
    <mass value="0.00386409068463368"/>
    <inertia ixx="1e-06" ixy="0.0" ixz="0.0" iyy="1e-06" iyz="-0.0" izz="0.0"/>
  </inertial>
  <visual>
    <origin rpy="0 0 0" xyz="0.03671 -0.238651 -0.153719"/>
    <geometry>
      <mesh filename="package://arbie_description/meshes/l_link2_1_m-binary.stl"/>
    </geometry>
    <material name="silver">
      <color rgba="1 0 0 1"/>
    </material>
  </visual>
  <collision>
    <origin rpy="0 0 0" xyz="0.03671 -0.238651 -0.153719"/>
    <geometry>
      <mesh filename="package://arbie_description/meshes/l_link2_1_m-binary.stl"/>
    </geometry>
  </collision>
</link>
<joint name="Rigid22" type="fixed">
  <origin rpy="0 0 0" xyz="0.123306 0.019326 -0.010978"/>
  <parent link="base_link"/>
  <child link="Tracks_L_1"/>
</joint>
<transmission name="Rigid22_tran">
  <type>transmission_interface/SimpleTransmission</type>
  <joint name="Rigid22">
    <hardwareInterface>PositionJointInterface</hardwareInterface>
  </joint>
  <actuator name="Rigid22_actr">
    <hardwareInterface>PositionJointInterface</hardwareInterface>
    <mechanicalReduction>1</mechanicalReduction>
  </actuator>
</transmission>
<joint name="Rigid23" type="fixed">
  <origin rpy="0 0 0" xyz="-0.124694 0.019326 -0.010978"/>
  <parent link="base_link"/>
  <child link="Tracks_R_1"/>
</joint>
<transmission name="Rigid23_tran">
  <type>transmission_interface/SimpleTransmission</type>
  <joint name="Rigid23">
    <hardwareInterface>PositionJointInterface</hardwareInterface>
  </joint>
  <actuator name="Rigid23_actr">
    <hardwareInterface>PositionJointInterface</hardwareInterface>
    <mechanicalReduction>1</mechanicalReduction>
  </actuator>
</transmission>
<joint name="Rigid24" type="fixed">
  <origin rpy="0 0 0" xyz="-0.02 0.0 0.0"/>
  <parent link="Tracks_R_1"/>
  <child link="equivalent_wheel_R_1"/>
</joint>
<transmission name="Rigid24_tran">
  <type>transmission_interface/SimpleTransmission</type>
  <joint name="Rigid24">
    <hardwareInterface>PositionJointInterface</hardwareInterface>
  </joint>
  <actuator name="Rigid24_actr">
    <hardwareInterface>PositionJointInterface</hardwareInterface>
    <mechanicalReduction>1</mechanicalReduction>
  </actuator>
</transmission>
<joint name="Rigid25" type="fixed">
  <origin rpy="0 0 0" xyz="0.02 0.0 0.0"/>
  <parent link="Tracks_L_1"/>
  <child link="equivalent_wheel_L_1"/>
</joint>
<transmission name="Rigid25_tran">
  <type>transmission_interface/SimpleTransmission</type>
  <joint name="Rigid25">
    <hardwareInterface>PositionJointInterface</hardwareInterface>
  </joint>
  <actuator name="Rigid25_actr">
    <hardwareInterface>PositionJointInterface</hardwareInterface>
    <mechanicalReduction>1</mechanicalReduction>
  </actuator>
</transmission>
<joint name="Rigid26" type="fixed">
  <origin rpy="0 0 0" xyz="0.037807 0.048101 0.262572"/>
  <parent link="base_link"/>
  <child link="Leg_1_1"/>
</joint>
<transmission name="Rigid26_tran">
  <type>transmission_interface/SimpleTransmission</type>
  <joint name="Rigid26">
    <hardwareInterface>PositionJointInterface</hardwareInterface>
  </joint>
  <actuator name="Rigid26_actr">
    <hardwareInterface>PositionJointInterface</hardwareInterface>
    <mechanicalReduction>1</mechanicalReduction>
  </actuator>
</transmission>
<joint name="Rigid27" type="fixed">
  <origin rpy="0 0 0" xyz="-0.039194 0.048101 0.262572"/>
  <parent link="base_link"/>
  <child link="Leg_2_1"/>
</joint>
<transmission name="Rigid27_tran">
  <type>transmission_interface/SimpleTransmission</type>
  <joint name="Rigid27">
    <hardwareInterface>PositionJointInterface</hardwareInterface>
  </joint>
  <actuator name="Rigid27_actr">
    <hardwareInterface>PositionJointInterface</hardwareInterface>
    <mechanicalReduction>1</mechanicalReduction>
  </actuator>
</transmission>
<joint name="Rev28" type="continuous">
  <origin rpy="0 0 0" xyz="-0.004 0.02575 0.0"/>
  <parent link="Leg_1_1"/>
  <child link="Cam_mount_1"/>
  <axis xyz="0.01 0.0 -0.0"/>
</joint>
<transmission name="Rev28_tran">
  <type>transmission_interface/SimpleTransmission</type>
  <joint name="Rev28">
    <hardwareInterface>PositionJointInterface</hardwareInterface>
  </joint>
  <actuator name="Rev28_actr">
    <hardwareInterface>PositionJointInterface</hardwareInterface>
    <mechanicalReduction>1</mechanicalReduction>
  </actuator>
</transmission>
<joint name="Rigid29" type="fixed">
  <origin rpy="0 0 0" xyz="-0.012557 -0.073851 -0.287572"/>
  <parent link="Cam_mount_1"/>
  <child link="D435_1"/>
</joint>
<transmission name="Rigid29_tran">
  <type>transmission_interface/SimpleTransmission</type>
  <joint name="Rigid29">
    <hardwareInterface>PositionJointInterface</hardwareInterface>
  </joint>
  <actuator name="Rigid29_actr">
    <hardwareInterface>PositionJointInterface</hardwareInterface>
    <mechanicalReduction>1</mechanicalReduction>
  </actuator>
</transmission>
<joint name="Rigid30" type="fixed">
  <origin rpy="0 0 0" xyz="-0.01763 -0.0135 0.014"/>
  <parent link="Cam_mount_1"/>
  <child link="T265_1"/>
</joint>
<transmission name="Rigid30_tran">
  <type>transmission_interface/SimpleTransmission</type>
  <joint name="Rigid30">
    <hardwareInterface>PositionJointInterface</hardwareInterface>
  </joint>
  <actuator name="Rigid30_actr">
    <hardwareInterface>PositionJointInterface</hardwareInterface>
    <mechanicalReduction>1</mechanicalReduction>
  </actuator>
</transmission>
<joint name="Rev31" type="continuous">
  <origin rpy="0 0 0" xyz="-0.05 0.005403 0.23"/>
  <parent link="Tracks_R_1"/>
  <child link="Flipper_FR_1"/>
  <axis xyz="0.01 -0.0 0.0"/>
</joint>
<transmission name="Rev31_tran">
  <type>transmission_interface/SimpleTransmission</type>
  <joint name="Rev31">
    <hardwareInterface>PositionJointInterface</hardwareInterface>
  </joint>
  <actuator name="Rev31_actr">
    <hardwareInterface>PositionJointInterface</hardwareInterface>
    <mechanicalReduction>1</mechanicalReduction>
  </actuator>
</transmission>
<joint name="Rev32" type="continuous">
  <origin rpy="0 0 0" xyz="-0.05 0.005403 -0.23"/>
  <parent link="Tracks_R_1"/>
  <child link="Flipper_RR_1"/>
  <axis xyz="0.01 -0.0 0.0"/>
</joint>
<transmission name="Rev32_tran">
  <type>transmission_interface/SimpleTransmission</type>
  <joint name="Rev32">
    <hardwareInterface>PositionJointInterface</hardwareInterface>
  </joint>
  <actuator name="Rev32_actr">
    <hardwareInterface>PositionJointInterface</hardwareInterface>
    <mechanicalReduction>1</mechanicalReduction>
  </actuator>
</transmission>
<joint name="Rev33" type="continuous">
  <origin rpy="0 0 0" xyz="0.05 0.005403 0.23"/>
  <parent link="Tracks_L_1"/>
  <child link="Flipper_FL_1"/>
  <axis xyz="0.01 0.0 -0.0"/>
</joint>
<transmission name="Rev33_tran">
  <type>transmission_interface/SimpleTransmission</type>
  <joint name="Rev33">
    <hardwareInterface>PositionJointInterface</hardwareInterface>
  </joint>
  <actuator name="Rev33_actr">
    <hardwareInterface>PositionJointInterface</hardwareInterface>
    <mechanicalReduction>1</mechanicalReduction>
  </actuator>
</transmission>
<joint name="Rev34" type="continuous">
  <origin rpy="0 0 0" xyz="0.05 0.005403 -0.23"/>
  <parent link="Tracks_L_1"/>
  <child link="Flipper_RL_1"/>
  <axis xyz="0.01 0.0 -0.0"/>
</joint>
<transmission name="Rev34_tran">
  <type>transmission_interface/SimpleTransmission</type>
  <joint name="Rev34">
    <hardwareInterface>PositionJointInterface</hardwareInterface>
  </joint>
  <actuator name="Rev34_actr">
    <hardwareInterface>PositionJointInterface</hardwareInterface>
    <mechanicalReduction>1</mechanicalReduction>
  </actuator>
</transmission>
<joint name="Rev35" type="continuous">
  <origin rpy="0 0 0" xyz="-0.000694 0.107101 0.186272"/>
  <parent link="base_link"/>
  <child link="Arm_rotation_1"/>
  <axis xyz="-0.0 -0.01 0.0"/>
</joint>
<transmission name="Rev35_tran">
  <type>transmission_interface/SimpleTransmission</type>
  <joint name="Rev35">
    <hardwareInterface>PositionJointInterface</hardwareInterface>
  </joint>
  <actuator name="Rev35_actr">
    <hardwareInterface>PositionJointInterface</hardwareInterface>
    <mechanicalReduction>1</mechanicalReduction>
  </actuator>
</transmission>
<joint name="Rev36" type="continuous">
  <origin rpy="0 0 0" xyz="0.0535 0.067 0.000223"/>
  <parent link="Arm_rotation_1"/>
  <child link="Arm_link_1_1"/>
  <axis xyz="0.01 0.0 -0.0"/>
</joint>
<transmission name="Rev36_tran">
  <type>transmission_interface/SimpleTransmission</type>
  <joint name="Rev36">
    <hardwareInterface>PositionJointInterface</hardwareInterface>
  </joint>
  <actuator name="Rev36_actr">
    <hardwareInterface>PositionJointInterface</hardwareInterface>
    <mechanicalReduction>1</mechanicalReduction>
  </actuator>
</transmission>
<joint name="Rev37" type="continuous">
  <origin rpy="0 0 0" xyz="-0.033 0.035 -0.45"/>
  <parent link="Arm_link_1_1"/>
  <child link="Arm_link_2_1"/>
  <axis xyz="-0.01 -0.0 0.0"/>
</joint>
<transmission name="Rev37_tran">
  <type>transmission_interface/SimpleTransmission</type>
  <joint name="Rev37">
    <hardwareInterface>PositionJointInterface</hardwareInterface>
  </joint>
  <actuator name="Rev37_actr">
    <hardwareInterface>PositionJointInterface</hardwareInterface>
    <mechanicalReduction>1</mechanicalReduction>
  </actuator>
</transmission>
<joint name="Rigid38" type="fixed">
  <origin rpy="0 0 0" xyz="-0.017 0.035 0.225"/>
  <parent link="Arm_link_2_1"/>
  <child link="wrist_base_1"/>
</joint>
<transmission name="Rigid38_tran">
  <type>transmission_interface/SimpleTransmission</type>
  <joint name="Rigid38">
    <hardwareInterface>PositionJointInterface</hardwareInterface>
  </joint>
  <actuator name="Rigid38_actr">
    <hardwareInterface>PositionJointInterface</hardwareInterface>
    <mechanicalReduction>1</mechanicalReduction>
  </actuator>
</transmission>
<joint name="Rev39" type="continuous">
  <origin rpy="0 0 0" xyz="0.0334 0.0 0.0535"/>
  <parent link="wrist_base_1"/>
  <child link="pitch_mount_1"/>
  <axis xyz="-0.01 -0.0 -0.0"/>
</joint>
<transmission name="Rev39_tran">
  <type>transmission_interface/SimpleTransmission</type>
  <joint name="Rev39">
    <hardwareInterface>PositionJointInterface</hardwareInterface>
  </joint>
  <actuator name="Rev39_actr">
    <hardwareInterface>PositionJointInterface</hardwareInterface>
    <mechanicalReduction>1</mechanicalReduction>
  </actuator>
</transmission>
<joint name="Rev40" type="continuous">
  <origin rpy="0 0 0" xyz="-0.0333 -0.01845 0.063124"/>
  <parent link="pitch_mount_1"/>
  <child link="roll_yaw_servo_1"/>
  <axis xyz="0.0 -0.01 -0.0"/>
</joint>
<transmission name="Rev40_tran">
  <type>transmission_interface/SimpleTransmission</type>
  <joint name="Rev40">
    <hardwareInterface>PositionJointInterface</hardwareInterface>
  </joint>
  <actuator name="Rev40_actr">
    <hardwareInterface>PositionJointInterface</hardwareInterface>
    <mechanicalReduction>1</mechanicalReduction>
  </actuator>
</transmission>
<joint name="Rev41" type="continuous">
  <origin rpy="0 0 0" xyz="0.0 0.019 0.0454"/>
  <parent link="roll_yaw_servo_1"/>
  <child link="gripper_mount_1"/>
  <axis xyz="-0.0 -0.0 0.01"/>
</joint>
<transmission name="Rev41_tran">
  <type>transmission_interface/SimpleTransmission</type>
  <joint name="Rev41">
    <hardwareInterface>PositionJointInterface</hardwareInterface>
  </joint>
  <actuator name="Rev41_actr">
    <hardwareInterface>PositionJointInterface</hardwareInterface>
    <mechanicalReduction>1</mechanicalReduction>
  </actuator>
</transmission>
<joint name="Rev42" type="continuous">
  <origin rpy="0 0 0" xyz="0.016 0.019 0.0487"/>
  <parent link="gripper_mount_1"/>
  <child link="r_link1_1"/>
  <axis xyz="-0.0 0.01 0.0"/>
</joint>
<transmission name="Rev42_tran">
  <type>transmission_interface/SimpleTransmission</type>
  <joint name="Rev42">
    <hardwareInterface>PositionJointInterface</hardwareInterface>
  </joint>
  <actuator name="Rev42_actr">
    <hardwareInterface>PositionJointInterface</hardwareInterface>
    <mechanicalReduction>1</mechanicalReduction>
  </actuator>
</transmission>
<joint name="Rev43" type="continuous">
  <origin rpy="0 0 0" xyz="-0.016 0.019 0.0487"/>
  <parent link="gripper_mount_1"/>
  <child link="l_link1_1"/>
  <axis xyz="-0.0 0.01 0.0"/>
</joint>
<transmission name="Rev43_tran">
  <type>transmission_interface/SimpleTransmission</type>
  <joint name="Rev43">
    <hardwareInterface>PositionJointInterface</hardwareInterface>
  </joint>
  <actuator name="Rev43_actr">
    <hardwareInterface>PositionJointInterface</hardwareInterface>
    <mechanicalReduction>1</mechanicalReduction>
  </actuator>
</transmission>
<joint name="Rev44" type="continuous">
  <origin rpy="0 0 0" xyz="0.0 -0.0024 0.035"/>
  <parent link="l_link1_1"/>
  <child link="l_finger_1"/>
  <axis xyz="0.0 -0.01 -0.0"/>
</joint>
<transmission name="Rev44_tran">
  <type>transmission_interface/SimpleTransmission</type>
  <joint name="Rev44">
    <hardwareInterface>PositionJointInterface</hardwareInterface>
  </joint>
  <actuator name="Rev44_actr">
    <hardwareInterface>PositionJointInterface</hardwareInterface>
    <mechanicalReduction>1</mechanicalReduction>
  </actuator>
</transmission>
<joint name="Rev45" type="continuous">
  <origin rpy="0 0 0" xyz="0.0 -0.0024 0.035"/>
  <parent link="r_link1_1"/>
  <child link="r_finger_1"/>
  <axis xyz="-0.0 0.01 0.0"/>
</joint>
<transmission name="Rev45_tran">
  <type>transmission_interface/SimpleTransmission</type>
  <joint name="Rev45">
    <hardwareInterface>PositionJointInterface</hardwareInterface>
  </joint>
  <actuator name="Rev45_actr">
    <hardwareInterface>PositionJointInterface</hardwareInterface>
    <mechanicalReduction>1</mechanicalReduction>
  </actuator>
</transmission>
<joint name="Rev46" type="continuous">
  <origin rpy="0 0 0" xyz="-0.039616 -0.006 0.0302"/>
  <parent link="gripper_mount_1"/>
  <child link="l_link2_1"/>
  <axis xyz="0.0 -0.01 -0.0"/>
</joint>
<transmission name="Rev46_tran">
  <type>transmission_interface/SimpleTransmission</type>
  <joint name="Rev46">
    <hardwareInterface>PositionJointInterface</hardwareInterface>
  </joint>
  <actuator name="Rev46_actr">
    <hardwareInterface>PositionJointInterface</hardwareInterface>
    <mechanicalReduction>1</mechanicalReduction>
  </actuator>
</transmission>
<gazebo>
  <plugin filename="libgazebo_ros_control.so" name="control"/>
</gazebo>
</robot>
