<?xml version="1.0"?>
<robot name="simple">

<link name="base_link"></link>
<joint name="base_joint" type="fixed">
    <parent link="base_link"/>
    <child link="body"/>
</joint>

<link name="body">
<visual>
    <geometry>
        <box size="0.6 0.4 0.1"/>
    </geometry>
    <origin xyz="-0.1 0 0"/>
</visual>
<collision>
    <geometry>
        <box size="0.6 0.4 0.1"/>
    </geometry>
    <origin xyz="-0.1 0 0"/>
</collision>
<inertial>
    <mass value="0.5"/>
    <inertia
        ixx="0.0071"
        iyy="0.0154"
        izz="0.0217"
        ixy="0" ixz="0" iyz="0"
    />
    <origin xyz="-0.1 0 0"/>
</inertial>

<visual>
    <geometry>
        <sphere radius="0.05"/>
    </geometry>
    <origin xyz="-0.35 0 -0.05"/>
</visual>
<collision>
    <geometry>
        <sphere radius="0.05"/>
    </geometry>
    <origin xyz="-0.35 0 -0.05"/>
</collision>
<inertial>
    <mass value="0.05"/>
    <inertia
        ixx="0.00005"
        iyy="0.00005"
        izz="0.00005"
        ixy="0" ixz="0" iyz="0"
    />
    <origin xyz="-0.35 0 -0.05"/>
</inertial>

</link>

<link name="wheel_right">
<visual>
    <geometry>
        <cylinder length="0.05" radius="0.1"/>
    </geometry>
    <origin xyz="0 0 0.025"/>
</visual>
<collision>
    <geometry>
        <cylinder length="0.05" radius="0.1"/>
    </geometry>
    <origin xyz="0 0 0.025"/>
</collision>
<inertial>
    <mass value="0.1"/>
    <inertia
        ixx="0.000146"
        iyy="0.000146"
        izz="0.0005"
        ixy="0" ixz="0" iyz="0"
    />
    <origin xyz="0 0 0.025"/>
</inertial>
</link>

<link name="wheel_left">
<visual>
    <geometry>
        <cylinder length="0.05" radius="0.1"/>
    </geometry>
    <origin xyz="0 0 0.025"/>
</visual>
<collision>
    <geometry>
        <cylinder length="0.05" radius="0.1"/>
    </geometry>
    <origin xyz="0 0 0.025"/>
</collision>
<inertial>
    <mass value="0.1"/>
    <inertia
        ixx="0.000146"
        iyy="0.000146"
        izz="0.0005"
        ixy="0" ixz="0" iyz="0"
    />
    <origin xyz="0 0 0.025"/>
</inertial>
</link>

<link name="T265">
<visual>
    <geometry>
        <box size="0.04 0.06 0.04"/>
    </geometry>
    <origin xyz="0 0 0.02"/>
</visual>
<collision>
    <geometry>
        <box size="0.04 0.06 0.04"/>
    </geometry>
    <origin xyz="0 0 0.02"/>
</collision>
<inertial>
    <mass value="0.05"/>
    <inertia
        ixx="0.0000217"
        iyy="0.0000133"
        izz="0.0000217"
        ixy="0" ixz="0" iyz="0"
    />
    <origin xyz="0 0 0.02"/>
</inertial>
</link>

<link name="D435i">
<visual>
    <geometry>
        <box size="0.04 0.04 0.04"/>
    </geometry>
    <origin xyz="0 0 0.02"/>
</visual>
<collision>
    <geometry>
        <box size="0.04 0.04 0.04"/>
    </geometry>
    <origin xyz="0 0 0.02"/>
</collision>
<inertial>
    <mass value="0.05"/>
    <inertia
        ixx="0.0000133"
        iyy="0.0000133"
        izz="0.0000133"
        ixy="0" ixz="0" iyz="0"
    />
    <origin xyz="0 0 0.02"/>
</inertial>
</link>

<joint name="wheel_right" type="continuous">
    <parent link="body"/>
    <child link="wheel_right"/>
    <origin xyz="0 -0.2 0" rpy="1.571 0 0"/>
    <axis xyz="0 0 -1"/>
</joint>

<joint name="wheel_left" type="continuous">
    <parent link="body"/>
    <child link="wheel_left"/>
    <origin xyz="0 0.2 0" rpy="-1.571 0 0"/>
    <axis xyz="0 0 1"/>
</joint>

<joint name="T265" type="fixed">
    <parent link="body"/>
    <child link="T265"/>
    <origin xyz="0.16 0 0.05"/>
</joint>

<joint name="D435i" type="fixed">
    <parent link="body"/>
    <child link="D435i"/>
    <origin xyz="0.16 0 0.09"/>
</joint>

<gazebo>
<plugin filename="libgazebo_ros_control.so" name="control"/>
</gazebo>

<transmission name="wheel_right_tran">
    <type>transmission_interface/SimpleTransmission</type>
    <joint name="wheel_right">
        <hardwareInterface>VelocityJointInterface</hardwareInterface>
    </joint>
    <actuator name="wheel_right_actr">
        <hardwareInterface>VelocityJointInterface</hardwareInterface>
        <mechanicalReduction>1</mechanicalReduction>
    </actuator>
</transmission>

<transmission name="wheel_left_tran">
    <type>transmission_interface/SimpleTransmission</type>
    <joint name="wheel_left">
        <hardwareInterface>VelocityJointInterface</hardwareInterface>
    </joint>
    <actuator name="wheel_left_actr">
        <hardwareInterface>VelocityJointInterface</hardwareInterface>
        <mechanicalReduction>1</mechanicalReduction>
    </actuator>
</transmission>

<gazebo reference="T265">
<sensor type="multicamera" name="T265">
    <update_rate>30.0</update_rate>
    <camera name="left">
        <pose>0 0.035 0 0 0 0</pose>
        <horizontal_fov>1.3962634</horizontal_fov>
        <image>
            <width>800</width>
            <height>800</height>
            <format>R8G8B8</format>
        </image>
        <clip>
            <near>0.02</near>
            <far>300</far>
        </clip>
        <noise>
            <type>gaussian</type>
            <mean>0.0</mean>
            <stddev>0.007</stddev>
        </noise>
    </camera>
    <camera name="right">
        <pose>0 -0.035 0 0 0 0</pose>
        <horizontal_fov>1.3962634</horizontal_fov>
        <image>
            <width>800</width>
            <height>800</height>
            <format>R8G8B8</format>
        </image>
        <clip>
            <near>0.02</near>
            <far>300</far>
        </clip>
        <noise>
            <type>gaussian</type>
            <mean>0.0</mean>
            <stddev>0.007</stddev>
        </noise>
    </camera>
    <plugin name="T265_controller" filename="libgazebo_ros_multicamera.so">
        <alwaysOn>true</alwaysOn>
        <updateRate>0.0</updateRate>
        <cameraName>T265</cameraName>
        <imageTopicName>image_raw</imageTopicName>
        <cameraInfoTopicName>camera_info</cameraInfoTopicName>
        <frameName>T265</frameName>
        <hackBaseline>0.07</hackBaseline>
        <distortionK1>0.0</distortionK1>
        <distortionK2>0.0</distortionK2>
        <distortionK3>0.0</distortionK3>
        <distortionT1>0.0</distortionT1>
        <distortionT2>0.0</distortionT2>
    </plugin>
</sensor>
</gazebo>

<gazebo>
<plugin name="imu_plugin" filename="libgazebo_ros_imu.so">
    <alwaysOn>true</alwaysOn>
    <bodyName>T265</bodyName>
    <topicName>T265/imu</topicName>
    <serviceName>imu_service</serviceName>
    <gaussianNoise>0.0</gaussianNoise>
    <updateRate>20.0</updateRate>
</plugin>
</gazebo>

<gazebo reference="D435i">
<sensor name="D435i" type="depth">
    <update_rate>20</update_rate>
    <camera>
        <horizontal_fov>1.047198</horizontal_fov>
        <image>
            <width>640</width>
            <height>480</height>
            <format>R8G8B8</format>
        </image>
        <clip>
            <near>0.05</near>
            <far>3</far>
        </clip>
    </camera>
    <plugin name="D435i_controller" filename="libgazebo_ros_openni_kinect.so">
        <baseline>0.2</baseline>
        <alwaysOn>true</alwaysOn>
        <updateRate>1.0</updateRate>
        <cameraName>D435i</cameraName>
        <imageTopicName>/D435i/color/image_raw</imageTopicName>
        <cameraInfoTopicName>/D435i/color/camera_info</cameraInfoTopicName>
        <depthImageTopicName>/D435i/depth/image_raw</depthImageTopicName>
        <depthImageInfoTopicName>/D435i/depth/camera_info</depthImageInfoTopicName>
        <pointCloudTopicName>/D435i/depth/points</pointCloudTopicName>
        <frameName>D435i</frameName>
        <pointCloudCutoff>0.5</pointCloudCutoff>
        <pointCloudCutoffMax>3.0</pointCloudCutoffMax>
        <distortionK1>0.00000001</distortionK1>
        <distortionK2>0.00000001</distortionK2>
        <distortionK3>0.00000001</distortionK3>
        <distortionT1>0.00000001</distortionT1>
        <distortionT2>0.00000001</distortionT2>
        <CxPrime>0</CxPrime>
        <Cx>0</Cx>
        <Cy>0</Cy>
        <focalLength>0</focalLength>
        <hackBaseline>0</hackBaseline>
    </plugin>
</sensor>
</gazebo>

</robot>
