<robot name="robot">

    <material name="body_colour">
        <color rgba="1 1 1 1"/>
    </material>

    <material name="arm_colour">
        <color rgba="0 0.8 1 1"/>
    </material>

    <material name="flipper_colour">
        <color rgba="1 0.2 0 1"/>
    </material>

    <link name="base_link">
        <visual>
            <geometry>
                <box size="1.0 0.5 0.4"/>
            </geometry>
            <material name="body_colour"/>
        </visual>
        <collision>
            <geometry>
                <box size="1.0 0.5 0.4"/>
            </geometry>
        </collision>
    </link>

    <link name="flipper_front_right">
        <visual>
            <origin xyz="0.125 -0.025 0" rpy="0 0 0" />
            <geometry>
                <box size="0.4 0.05 0.15"/>
            </geometry>
            <material name="flipper_colour"/>
        </visual>
        <collision>
            <origin xyz="0.125 -0.025 0" rpy="0 0 0" />
            <geometry>
                <box size="0.4 0.05 0.15"/>
            </geometry>
        </collision>
    </link>
    <joint name="base_link_to_flipper_front_right" type="continuous">
        <axis xyz="0 1 0"/>
        <parent link="base_link"/>
        <child link="flipper_front_right"/>
        <origin xyz="0.4 -0.25 -0.1" rpy="0 0 0"/>
    </joint>

    <link name="arm_lower">
        <visual>
            <origin xyz="0 0 0.25"/>
            <geometry>
                <cylinder length="0.5" radius="0.05"/>
            </geometry>
            <material name="arm_colour"/>
        </visual>
        <collision>
            <origin xyz="0 0 0.25"/>
            <geometry>
                <cylinder length="0.5" radius="0.05"/>
            </geometry>
        </collision>
    </link>
    <joint name="base_link_to_arm_lower" type="revolute">
        <axis xyz="0 1 0"/> 
        <limit effort="1000.0" lower="-1.5" upper="1.5" velocity="1.0"/>
        <parent link="base_link"/>
        <child link="arm_lower"/>
        <origin xyz="0.45 0 0.2"/>
    </joint>

    <link name="arm_upper">
        <visual>
            <origin xyz="0 0 0.25" rpy="0 0 0"/>
            <geometry>
                <cylinder length="0.5" radius="0.05"/>
            </geometry>
            <material name="arm_colour"/>
        </visual>
        <collision>
            <origin xyz="0 0 0.25" rpy="0 0 0"/>
            <geometry>
                <cylinder length="0.5" radius="0.05"/>
            </geometry>
        </collision>
    </link>
    <joint name="arm_lower_to_arm_upper" type="revolute">
        <axis xyz="0 1 0"/> 
        <limit effort="1000.0" lower="-1.5" upper="1.5" velocity="1.0"/>
        <parent link="arm_lower"/>
        <child link="arm_upper"/>
        <origin xyz="0 0 0.5"/>
    </joint>

</robot>
