<sdf version='1.6'>
  <model name='arbie'>
    <joint name='world_joint' type='rigid'>
      <parent>world</parent>
      <child>base_link</child>
    </joint>
    <link name='base_link'>
      <pose frame=''>0 0 0 0 -0 0</pose>
      <inertial>
        <pose frame=''>-0.016487 -0.000704 0.111607 0 -0 0</pose>
        <mass>221.932</mass>
        <inertia>
          <ixx>3.22408</ixx>
          <ixy>-0.00263481</ixy>
          <ixz>0.197353</ixz>
          <iyy>6.89301</iyy>
          <iyz>-0.00105641</iyz>
          <izz>9.13232</izz>
        </inertia>
      </inertial>
      <collision name='base_link_fixed_joint_lump__body_link_collision'>
        <pose frame=''>0.01 0 0.075 1.5708 -0 1.5708</pose>
        <geometry>
          <mesh>
            <scale>1 1 1</scale>
            <uri>model://arbie/meshes/body.stl</uri>
          </mesh>
        </geometry>
      </collision>
      <collision name='base_link_fixed_joint_lump__tracks_left_link_collision_3'>
        <pose frame=''>0.01 0 0.075 1.5708 -0 1.5708</pose>
        <geometry>
          <mesh>
            <scale>1 1 1</scale>
            <uri>model://arbie/meshes/tracks_left.stl</uri>
          </mesh>
        </geometry>
      </collision>
      <collision name='base_link_fixed_joint_lump__tracks_right_link_collision_4'>
        <pose frame=''>0.01 0 0.075 1.5708 -0 1.5708</pose>
        <geometry>
          <mesh>
            <scale>1 1 1</scale>
            <uri>model://arbie/meshes/tracks_right.stl</uri>
          </mesh>
        </geometry>
      </collision>
      <visual name='base_link_fixed_joint_lump__body_link_visual'>
        <pose frame=''>0.01 0 0.075 1.5708 -0 1.5708</pose>
        <geometry>
          <mesh>
            <scale>1 1 1</scale>
            <uri>model://arbie/meshes/body.stl</uri>
          </mesh>
        </geometry>
      </visual>
      <visual name='base_link_fixed_joint_lump__tracks_left_link_visual_3'>
        <pose frame=''>0.01 0 0.075 1.5708 -0 1.5708</pose>
        <geometry>
          <mesh>
            <scale>1 1 1</scale>
            <uri>model://arbie/meshes/tracks_left.stl</uri>
          </mesh>
        </geometry>
      </visual>
      <visual name='base_link_fixed_joint_lump__tracks_right_link_visual_4'>
        <pose frame=''>0.01 0 0.075 1.5708 -0 1.5708</pose>
        <geometry>
          <mesh>
            <scale>1 1 1</scale>
            <uri>model://arbie/meshes/tracks_right.stl</uri>
          </mesh>
        </geometry>
      </visual>
    </link>
    <link name='arm_base_link'>
      <pose frame=''>0.196272 -0.000693 0.1821 1.5708 -0 1.5708</pose>
      <inertial>
        <pose frame=''>-0.001642 0.023135 -7e-06 0 -0 0</pose>
        <mass>3.34651</mass>
        <inertia>
          <ixx>0.005075</ixx>
          <ixy>0.000176</ixy>
          <ixz>-0</ixz>
          <iyy>0.010632</iyy>
          <iyz>1e-06</iyz>
          <izz>0.009087</izz>
        </inertia>
      </inertial>
      <collision name='arm_base_link_collision'>
        <pose frame=''>0.000694 -0.107101 -0.186272 0 -0 0</pose>
        <geometry>
          <mesh>
            <scale>1 1 1</scale>
            <uri>model://arbie/meshes/arm_base.stl</uri>
          </mesh>
        </geometry>
      </collision>
      <visual name='arm_base_link_visual'>
        <pose frame=''>0.000694 -0.107101 -0.186272 0 -0 0</pose>
        <geometry>
          <mesh>
            <scale>1 1 1</scale>
            <uri>model://arbie/meshes/arm_base.stl</uri>
          </mesh>
        </geometry>
      </visual>
    </link>
    <joint name='arm_1_joint' type='revolute'>
      <child>arm_base_link</child>
      <parent>base_link</parent>
      <axis>
        <xyz>4e-06 0 1</xyz>
        <limit>
          <lower>-1e+16</lower>
          <upper>1e+16</upper>
        </limit>
        <dynamics>
          <spring_reference>0</spring_reference>
          <spring_stiffness>0</spring_stiffness>
        </dynamics>
        <use_parent_model_frame>1</use_parent_model_frame>
      </axis>
    </joint>
    <link name='arm_lower_link'>
      <pose frame=''>0.196495 0.052807 0.2491 1.5708 -0 1.5708</pose>
      <inertial>
        <pose frame=''>-0.053879 0.007244 -0.130032 0 -0 0</pose>
        <mass>9.29022</mass>
        <inertia>
          <ixx>0.285483</ixx>
          <ixy>0.000938</ixy>
          <ixz>-0.009995</ixz>
          <iyy>0.285913</iyy>
          <iyz>0.0181</iyz>
          <izz>0.011485</izz>
        </inertia>
      </inertial>
      <collision name='arm_lower_link_collision'>
        <pose frame=''>-0.052806 -0.174101 -0.186495 0 -0 0</pose>
        <geometry>
          <mesh>
            <scale>1 1 1</scale>
            <uri>model://arbie/meshes/arm_lower.stl</uri>
          </mesh>
        </geometry>
      </collision>
      <visual name='arm_lower_link_visual'>
        <pose frame=''>-0.052806 -0.174101 -0.186495 0 -0 0</pose>
        <geometry>
          <mesh>
            <scale>1 1 1</scale>
            <uri>model://arbie/meshes/arm_lower.stl</uri>
          </mesh>
        </geometry>
      </visual>
    </link>
    <joint name='arm_2_joint' type='revolute'>
      <child>arm_lower_link</child>
      <parent>arm_base_link</parent>
      <axis>
        <xyz>-4e-06 1 0</xyz>
        <limit>
          <lower>-1e+16</lower>
          <upper>1e+16</upper>
        </limit>
        <dynamics>
          <spring_reference>0</spring_reference>
          <spring_stiffness>0</spring_stiffness>
        </dynamics>
        <use_parent_model_frame>1</use_parent_model_frame>
      </axis>
    </joint>
    <link name='arm_upper_link'>
      <pose frame=''>-0.253504 0.019805 0.284102 1.5708 -0 1.5708</pose>
      <inertial>
        <pose frame=''>-0.017 0.018521 0.099807 0 -0 0</pose>
        <mass>4.01224</mass>
        <inertia>
          <ixx>0.0638396</ixx>
          <ixy>9.99966e-07</ixy>
          <ixz>-4.05291e-10</ixz>
          <iyy>0.0618849</iyy>
          <iyz>-0.00666596</iyz>
          <izz>0.00333272</izz>
        </inertia>
      </inertial>
      <collision name='arm_upper_link_collision'>
        <pose frame=''>-0.019806 -0.209101 0.263505 0 -0 0</pose>
        <geometry>
          <mesh>
            <scale>1 1 1</scale>
            <uri>model://arbie/meshes/arm_upper.stl</uri>
          </mesh>
        </geometry>
      </collision>
      <collision name='arm_upper_link_fixed_joint_lump__wrist_base_link_collision_1'>
        <pose frame=''>-0.019806 -0.209101 0.308505 0 -0 0</pose>
        <geometry>
          <mesh>
            <scale>1 1 1</scale>
            <uri>model://arbie/meshes/wrist_base.stl</uri>
          </mesh>
        </geometry>
      </collision>
      <visual name='arm_upper_link_visual'>
        <pose frame=''>-0.019806 -0.209101 0.263505 0 -0 0</pose>
        <geometry>
          <mesh>
            <scale>1 1 1</scale>
            <uri>model://arbie/meshes/arm_upper.stl</uri>
          </mesh>
        </geometry>
      </visual>
      <visual name='arm_upper_link_fixed_joint_lump__wrist_base_link_visual_1'>
        <pose frame=''>-0.019806 -0.209101 0.308505 0 -0 0</pose>
        <geometry>
          <mesh>
            <scale>1 1 1</scale>
            <uri>model://arbie/meshes/wrist_base.stl</uri>
          </mesh>
        </geometry>
      </visual>
    </link>
    <joint name='arm_3_joint' type='revolute'>
      <child>arm_upper_link</child>
      <parent>arm_lower_link</parent>
      <axis>
        <xyz>4e-06 -1 0</xyz>
        <limit>
          <lower>-1e+16</lower>
          <upper>1e+16</upper>
        </limit>
        <dynamics>
          <spring_reference>0</spring_reference>
          <spring_stiffness>0</spring_stiffness>
        </dynamics>
        <use_parent_model_frame>1</use_parent_model_frame>
      </axis>
    </joint>
    <link name='wrist_pitch_link'>
      <pose frame=''>0.069996 0.036206 0.319101 1.5708 -0 1.5708</pose>
      <inertial>
        <pose frame=''>-0.033299 0.002067 0.022821 0 -0 0</pose>
        <mass>0.0803966</mass>
        <inertia>
          <ixx>5.5e-05</ixx>
          <ixy>0</ixy>
          <ixz>0</ixz>
          <iyy>9.5e-05</iyy>
          <iyz>-7e-06</iyz>
          <izz>8e-05</izz>
        </inertia>
      </inertial>
      <collision name='wrist_pitch_link_collision'>
        <pose frame=''>-0.036206 -0.244101 -0.014995 0 -0 0</pose>
        <geometry>
          <mesh>
            <scale>1 1 1</scale>
            <uri>model://arbie/meshes/wrist_pitch.stl</uri>
          </mesh>
        </geometry>
      </collision>
      <visual name='wrist_pitch_link_visual'>
        <pose frame=''>-0.036206 -0.244101 -0.014995 0 -0 0</pose>
        <geometry>
          <mesh>
            <scale>1 1 1</scale>
            <uri>model://arbie/meshes/wrist_pitch.stl</uri>
          </mesh>
        </geometry>
      </visual>
    </link>
    <joint name='wrist_pitch_joint' type='revolute'>
      <child>wrist_pitch_link</child>
      <parent>arm_upper_link</parent>
      <axis>
        <xyz>-4e-06 1 0</xyz>
        <limit>
          <lower>-1e+16</lower>
          <upper>1e+16</upper>
        </limit>
        <dynamics>
          <spring_reference>0</spring_reference>
          <spring_stiffness>0</spring_stiffness>
        </dynamics>
        <use_parent_model_frame>1</use_parent_model_frame>
      </axis>
    </joint>
    <link name='wrist_yaw_link'>
      <pose frame=''>0.13312 0.002906 0.300651 1.5708 -0 1.5708</pose>
      <inertial>
        <pose frame=''>-0.013268 0.019276 0.016286 0 -0 0</pose>
        <mass>0.646948</mass>
        <inertia>
          <ixx>0.000275</ixx>
          <ixy>2e-06</ixy>
          <ixz>2e-06</ixz>
          <iyy>0.000342</iyy>
          <iyz>3e-06</iyz>
          <izz>0.000171</izz>
        </inertia>
      </inertial>
      <collision name='wrist_yaw_link_collision'>
        <pose frame=''>-0.002906 -0.225651 -0.078119 0 -0 0</pose>
        <geometry>
          <mesh>
            <scale>1 1 1</scale>
            <uri>model://arbie/meshes/wrist_yaw.stl</uri>
          </mesh>
        </geometry>
      </collision>
      <visual name='wrist_yaw_link_visual'>
        <pose frame=''>-0.002906 -0.225651 -0.078119 0 -0 0</pose>
        <geometry>
          <mesh>
            <scale>1 1 1</scale>
            <uri>model://arbie/meshes/wrist_yaw.stl</uri>
          </mesh>
        </geometry>
      </visual>
    </link>
    <joint name='wrist_yaw_joint' type='revolute'>
      <child>wrist_yaw_link</child>
      <parent>wrist_pitch_link</parent>
      <axis>
        <xyz>-4e-06 -0 -1</xyz>
        <limit>
          <lower>-1e+16</lower>
          <upper>1e+16</upper>
        </limit>
        <dynamics>
          <spring_reference>0</spring_reference>
          <spring_stiffness>0</spring_stiffness>
        </dynamics>
        <use_parent_model_frame>1</use_parent_model_frame>
      </axis>
    </joint>
    <link name='gripper_base_link'>
      <pose frame=''>0.17852 0.002907 0.31965 -2.35619 1.57079 -2.35619</pose>
      <inertial>
        <pose frame=''>-4.6e-05 -0.000692 0.034607 0 -0 0</pose>
        <mass>0.670674</mass>
        <inertia>
          <ixx>0.000199</ixx>
          <ixy>0</ixy>
          <ixz>0</ixz>
          <iyy>0.000353</iyy>
          <iyz>-3e-06</iyz>
          <izz>0.000284</izz>
        </inertia>
      </inertial>
      <collision name='gripper_base_link_collision'>
        <pose frame=''>-0.002906 -0.244651 -0.123519 0 -0 0</pose>
        <geometry>
          <mesh>
            <scale>1 1 1</scale>
            <uri>model://arbie/meshes/gripper_base.stl</uri>
          </mesh>
        </geometry>
      </collision>
      <visual name='gripper_base_link_visual'>
        <pose frame=''>-0.002906 -0.244651 -0.123519 0 -0 0</pose>
        <geometry>
          <mesh>
            <scale>1 1 1</scale>
            <uri>model://arbie/meshes/gripper_base.stl</uri>
          </mesh>
        </geometry>
      </visual>
    </link>
    <joint name='wrist_roll_joint' type='revolute'>
      <child>gripper_base_link</child>
      <parent>wrist_yaw_link</parent>
      <axis>
        <xyz>1 4e-06 -4e-06</xyz>
        <limit>
          <lower>-1e+16</lower>
          <upper>1e+16</upper>
        </limit>
        <dynamics>
          <spring_reference>0</spring_reference>
          <spring_stiffness>0</spring_stiffness>
        </dynamics>
        <use_parent_model_frame>1</use_parent_model_frame>
      </axis>
    </joint>
    <link name='gripper_right_driver_link'>
      <pose frame=''>0.22722 0.021907 0.30365 -1.1e-05 1.2228 -6e-06</pose>
      <inertial>
        <pose frame=''>0 -0.03094 0.004351 0 -0 0</pose>
        <mass>0.013748</mass>
        <inertia>
          <ixx>5e-06</ixx>
          <ixy>-0</ixy>
          <ixz>0</ixz>
          <iyy>2e-06</iyy>
          <iyz>-1e-06</iyz>
          <izz>4e-06</izz>
        </inertia>
      </inertial>
      <collision name='gripper_right_driver_link_collision'>
        <pose frame=''>-0.018906 -0.263651 -0.172219 0 -0 0</pose>
        <geometry>
          <mesh>
            <scale>1 1 1</scale>
            <uri>model://arbie/meshes/gripper_right_driver.stl</uri>
          </mesh>
        </geometry>
      </collision>
      <visual name='gripper_right_driver_link_visual'>
        <pose frame=''>-0.018906 -0.263651 -0.172219 0 -0 0</pose>
        <geometry>
          <mesh>
            <scale>1 1 1</scale>
            <uri>model://arbie/meshes/gripper_right_driver.stl</uri>
          </mesh>
        </geometry>
      </visual>
    </link>
    <joint name='gripper_joint' type='revolute'>
      <child>gripper_right_driver_link</child>
      <parent>gripper_base_link</parent>
      <axis>
        <xyz>-4e-06 1 -4e-06</xyz>
        <limit>
          <lower>-1e+16</lower>
          <upper>1e+16</upper>
        </limit>
        <dynamics>
          <spring_reference>0</spring_reference>
          <spring_stiffness>0</spring_stiffness>
        </dynamics>
        <use_parent_model_frame>1</use_parent_model_frame>
      </axis>
    </joint>
    <link name='gripper_right_contact_link'>
      <pose frame=''>0.260122 0.019507 0.315586 -2.35619 1.57079 -2.35619</pose>
      <inertial>
        <pose frame=''>0.004968 -0.018997 0.016467 0 -0 0</pose>
        <mass>0.0237125</mass>
        <inertia>
          <ixx>7e-06</ixx>
          <ixy>1e-06</ixy>
          <ixz>2e-06</ixz>
          <iyy>7e-06</iyy>
          <iyz>-1e-06</iyz>
          <izz>4e-06</izz>
        </inertia>
      </inertial>
      <collision name='gripper_right_contact_link_collision'>
        <pose frame=''>-0.018906 -0.261251 -0.207219 0 -0 0</pose>
        <geometry>
          <mesh>
            <scale>1 1 1</scale>
            <uri>model://arbie/meshes/gripper_right_contact.stl</uri>
          </mesh>
        </geometry>
      </collision>
      <visual name='gripper_right_contact_link_visual'>
        <pose frame=''>-0.018906 -0.261251 -0.207219 0 -0 0</pose>
        <geometry>
          <mesh>
            <scale>1 1 1</scale>
            <uri>model://arbie/meshes/gripper_right_contact.stl</uri>
          </mesh>
        </geometry>
      </visual>
    </link>
    <joint name='gripper_right_contact_dependent_joint' type='revolute'>
      <child>gripper_right_contact_link</child>
      <parent>gripper_right_driver_link</parent>
      <axis>
        <xyz>-4e-06 1 -4e-06</xyz>
        <limit>
          <lower>-1e+16</lower>
          <upper>1e+16</upper>
        </limit>
        <dynamics>
          <spring_reference>0</spring_reference>
          <spring_stiffness>0</spring_stiffness>
        </dynamics>
        <use_parent_model_frame>1</use_parent_model_frame>
      </axis>
    </joint>
    <link name='gripper_left_linkage_link'>
      <pose frame=''>0.20872 -0.003093 0.359266 -3.14158 1.22279 -3.14158</pose>
      <inertial>
        <pose frame=''>-0.005349 0.005 0.0175 0 -0 0</pose>
        <mass>0.00386409</mass>
        <inertia>
          <ixx>1e-06</ixx>
          <ixy>0</ixy>
          <ixz>0</ixz>
          <iyy>1e-06</iyy>
          <iyz>-0</iyz>
          <izz>0</izz>
        </inertia>
      </inertial>
      <collision name='gripper_left_linkage_link_collision'>
        <pose frame=''>0.03671 -0.238651 -0.153719 0 -0 0</pose>
        <geometry>
          <mesh>
            <scale>1 1 1</scale>
            <uri>model://arbie/meshes/gripper_left_linkage.stl</uri>
          </mesh>
        </geometry>
      </collision>
      <visual name='gripper_left_linkage_link_visual'>
        <pose frame=''>0.03671 -0.238651 -0.153719 0 -0 0</pose>
        <geometry>
          <mesh>
            <scale>1 1 1</scale>
            <uri>model://arbie/meshes/gripper_left_linkage.stl</uri>
          </mesh>
        </geometry>
      </visual>
    </link>
    <joint name='gripper_left_linkage_dependent_joint' type='revolute'>
      <child>gripper_left_linkage_link</child>
      <parent>gripper_base_link</parent>
      <axis>
        <xyz>-4e-06 1 -4e-06</xyz>
        <limit>
          <lower>-1e+16</lower>
          <upper>1e+16</upper>
        </limit>
        <dynamics>
          <spring_reference>0</spring_reference>
          <spring_stiffness>0</spring_stiffness>
        </dynamics>
        <use_parent_model_frame>1</use_parent_model_frame>
      </axis>
    </joint>
    <link name='gripper_left_driver_link'>
      <pose frame=''>0.22722 0.021907 0.33565 -3.14158 1.22279 -3.14158</pose>
      <inertial>
        <pose frame=''>0 -0.03094 0.004351 0 -0 0</pose>
        <mass>0.013748</mass>
        <inertia>
          <ixx>5e-06</ixx>
          <ixy>0</ixy>
          <ixz>0</ixz>
          <iyy>2e-06</iyy>
          <iyz>-1e-06</iyz>
          <izz>4e-06</izz>
        </inertia>
      </inertial>
      <collision name='gripper_left_driver_link_collision'>
        <pose frame=''>0.013094 -0.263651 -0.172219 0 -0 0</pose>
        <geometry>
          <mesh>
            <scale>1 1 1</scale>
            <uri>model://arbie/meshes/gripper_left_driver.stl</uri>
          </mesh>
        </geometry>
      </collision>
      <visual name='gripper_left_driver_link_visual'>
        <pose frame=''>0.013094 -0.263651 -0.172219 0 -0 0</pose>
        <geometry>
          <mesh>
            <scale>1 1 1</scale>
            <uri>model://arbie/meshes/gripper_left_driver.stl</uri>
          </mesh>
        </geometry>
      </visual>
    </link>
    <joint name='gripper_mimic_joint' type='revolute'>
      <child>gripper_left_driver_link</child>
      <parent>gripper_base_link</parent>
      <axis>
        <xyz>-4e-06 1 -4e-06</xyz>
        <limit>
          <lower>-1e+16</lower>
          <upper>1e+16</upper>
        </limit>
        <dynamics>
          <spring_reference>0</spring_reference>
          <spring_stiffness>0</spring_stiffness>
        </dynamics>
        <use_parent_model_frame>1</use_parent_model_frame>
      </axis>
    </joint>
    <link name='gripper_left_contact_link'>
      <pose frame=''>0.260122 0.019507 0.323714 -2.35619 1.57079 -2.35619</pose>
      <inertial>
        <pose frame=''>-0.004967 -0.018997 0.016467 0 -0 0</pose>
        <mass>0.0237125</mass>
        <inertia>
          <ixx>7e-06</ixx>
          <ixy>-1e-06</ixy>
          <ixz>-2e-06</ixz>
          <iyy>7e-06</iyy>
          <iyz>-1e-06</iyz>
          <izz>4e-06</izz>
        </inertia>
      </inertial>
      <collision name='gripper_left_contact_link_collision'>
        <pose frame=''>0.013094 -0.261251 -0.207219 0 -0 0</pose>
        <geometry>
          <mesh>
            <scale>1 1 1</scale>
            <uri>model://arbie/meshes/gripper_left_contact.stl</uri>
          </mesh>
        </geometry>
      </collision>
      <visual name='gripper_left_contact_link_visual'>
        <pose frame=''>0.013094 -0.261251 -0.207219 0 -0 0</pose>
        <geometry>
          <mesh>
            <scale>1 1 1</scale>
            <uri>model://arbie/meshes/gripper_left_contact.stl</uri>
          </mesh>
        </geometry>
      </visual>
    </link>
    <joint name='gripper_left_contact_dependent_joint' type='revolute'>
      <child>gripper_left_contact_link</child>
      <parent>gripper_left_driver_link</parent>
      <axis>
        <xyz>-4e-06 1 -4e-06</xyz>
        <limit>
          <lower>-1e+16</lower>
          <upper>1e+16</upper>
        </limit>
        <dynamics>
          <spring_reference>0</spring_reference>
          <spring_stiffness>0</spring_stiffness>
        </dynamics>
        <use_parent_model_frame>1</use_parent_model_frame>
      </axis>
    </joint>
    <link name='gripper_right_linkage_link'>
      <pose frame=''>0.20872 -0.003093 0.280034 -1.1e-05 1.2228 -6e-06</pose>
      <inertial>
        <pose frame=''>0.005349 0.005 -0.0175 0 -0 0</pose>
        <mass>0.00386409</mass>
        <inertia>
          <ixx>1e-06</ixx>
          <ixy>0</ixy>
          <ixz>0</ixz>
          <iyy>1e-06</iyy>
          <iyz>-0</iyz>
          <izz>0</izz>
        </inertia>
      </inertial>
      <collision name='gripper_right_linkage_link_collision'>
        <pose frame=''>-0.03671 -0.238651 0.153719 0 -0 0</pose>
        <geometry>
          <mesh>
            <scale>1 1 1</scale>
            <uri>model://arbie/meshes/gripper_right_linkage.stl</uri>
          </mesh>
        </geometry>
      </collision>
      <visual name='gripper_right_linkage_link_visual'>
        <pose frame=''>0.015 -0.485 -0.09 0 -0 0</pose>
        <geometry>
          <mesh>
            <scale>1 1 1</scale>
            <uri>model://arbie/meshes/gripper_right_linkage.stl</uri>
          </mesh>
        </geometry>
      </visual>
    </link>
    <joint name='gripper_right_linkage_dependent_joint' type='revolute'>
      <child>gripper_right_linkage_link</child>
      <parent>gripper_base_link</parent>
      <axis>
        <xyz>-4e-06 1 -4e-06</xyz>
        <limit>
          <lower>-1e+16</lower>
          <upper>1e+16</upper>
        </limit>
        <dynamics>
          <spring_reference>0</spring_reference>
          <spring_stiffness>0</spring_stiffness>
        </dynamics>
        <use_parent_model_frame>1</use_parent_model_frame>
      </axis>
    </joint>
    <link name='flipper_front_right_link'>
      <pose frame=''>0.229023 -0.174693 0.099728 1.5708 -0 1.5708</pose>
      <inertial>
        <pose frame=''>0.173998 0.165376 -0 0 -0 0</pose>
        <mass>27.736</mass>
        <inertia>
          <ixx>0.170702</ixx>
          <ixy>-1.11022e-16</ixy>
          <ixz>1.69806e-08</ixz>
          <iyy>0.716637</iyy>
          <iyz>0</iyz>
          <izz>0.802767</izz>
        </inertia>
      </inertial>
      <collision name='flipper_front_right_link_collision'>
        <pose frame=''>0.174694 -0.024729 -0.219022 0 -0 0</pose>
        <geometry>
          <mesh>
            <scale>1 1 1</scale>
            <uri>model://arbie/meshes/flipper_front_right.stl</uri>
          </mesh>
        </geometry>
      </collision>
      <collision name='flipper_front_right_link_fixed_joint_lump__flipper_front_left_link_collision_1'>
        <pose frame=''>0.17469 -0.024729 -0.219022 0 -0 0</pose>
        <geometry>
          <mesh>
            <scale>1 1 1</scale>
            <uri>model://arbie/meshes/flipper_front_left.stl</uri>
          </mesh>
        </geometry>
      </collision>
      <visual name='flipper_front_right_link_visual'>
        <pose frame=''>0.174694 -0.024729 -0.219022 0 -0 0</pose>
        <geometry>
          <mesh>
            <scale>1 1 1</scale>
            <uri>model://arbie/meshes/flipper_front_right.stl</uri>
          </mesh>
        </geometry>
      </visual>
      <visual name='flipper_front_right_link_fixed_joint_lump__flipper_front_left_link_visual_1'>
        <pose frame=''>0.17469 -0.024729 -0.219022 0 -0 0</pose>
        <geometry>
          <mesh>
            <scale>1 1 1</scale>
            <uri>model://arbie/meshes/flipper_front_left.stl</uri>
          </mesh>
        </geometry>
      </visual>
    </link>
    <joint name='flipper_front_joint' type='revolute'>
      <child>flipper_front_right_link</child>
      <parent>base_link</parent>
      <axis>
        <xyz>-4e-06 1 0</xyz>
        <limit>
          <lower>-1e+16</lower>
          <upper>1e+16</upper>
        </limit>
        <dynamics>
          <spring_reference>0</spring_reference>
          <spring_stiffness>0</spring_stiffness>
        </dynamics>
        <use_parent_model_frame>1</use_parent_model_frame>
      </axis>
    </joint>
    <link name='flipper_rear_right_link'>
      <pose frame=''>-0.230977 -0.174695 0.09973 1.5708 -0 1.5708</pose>
      <inertial>
        <pose frame=''>0.173998 0.165376 -0 0 -0 0</pose>
        <mass>27.736</mass>
        <inertia>
          <ixx>0.170702</ixx>
          <ixy>-2.22045e-16</ixy>
          <ixz>1.69806e-08</ixz>
          <iyy>0.716637</iyy>
          <iyz>0</iyz>
          <izz>0.802767</izz>
        </inertia>
      </inertial>
      <collision name='flipper_rear_right_link_collision'>
        <pose frame=''>0.174694 -0.024729 0.240978 0 -0 0</pose>
        <geometry>
          <mesh>
            <scale>1 1 1</scale>
            <uri>model://arbie/meshes/flipper_rear_right.stl</uri>
          </mesh>
        </geometry>
      </collision>
      <collision name='flipper_rear_right_link_fixed_joint_lump__flipper_rear_left_link_collision_1'>
        <pose frame=''>0.17469 -0.024729 0.240978 0 -0 0</pose>
        <geometry>
          <mesh>
            <scale>1 1 1</scale>
            <uri>model://arbie/meshes/flipper_rear_left.stl</uri>
          </mesh>
        </geometry>
      </collision>
      <visual name='flipper_rear_right_link_visual'>
        <pose frame=''>0.174694 -0.024729 0.240978 0 -0 0</pose>
        <geometry>
          <mesh>
            <scale>1 1 1</scale>
            <uri>model://arbie/meshes/flipper_rear_right.stl</uri>
          </mesh>
        </geometry>
      </visual>
      <visual name='flipper_rear_right_link_fixed_joint_lump__flipper_rear_left_link_visual_1'>
        <pose frame=''>0.17469 -0.024729 0.240978 0 -0 0</pose>
        <geometry>
          <mesh>
            <scale>1 1 1</scale>
            <uri>model://arbie/meshes/flipper_rear_left.stl</uri>
          </mesh>
        </geometry>
      </visual>
    </link>
    <joint name='flipper_rear_joint' type='revolute'>
      <child>flipper_rear_right_link</child>
      <parent>base_link</parent>
      <axis>
        <xyz>-4e-06 1 0</xyz>
        <limit>
          <lower>-1e+16</lower>
          <upper>1e+16</upper>
        </limit>
        <dynamics>
          <spring_reference>0</spring_reference>
          <spring_stiffness>0</spring_stiffness>
        </dynamics>
        <use_parent_model_frame>1</use_parent_model_frame>
      </axis>
    </joint>

    <!-- TODO: Get this working. At the moment, breaks gazebo.
    <plugin name='control' filename='libgazebo_ros_control.so'/>
    -->
  </model>
</sdf>
